<robot name="XSensStyleModel_template">
<!--To open this model with Gazebo replace the null masses, inertias and dimensions of the 'fake links f1 and f2'-->
    <!--LINKS-->
	<!--Link base (1)-->
	<link name="Pelvis">
        <inertial>
            <mass value="4.9968"/>
			<!--COM origin wrt pHipOrigin-->
            <origin xyz="0           0    0.049333" rpy="0 0 0" />

<inertia ixx="0.028067" iyy="0.011715" izz="0.031651" ixy="0" ixz="0" iyz="0"/>
        </inertial>

        <visual>
			<!--box origin wrt pHipOrigin-->
            <origin xyz="0           0    0.049333" rpy="0 0 0" />
            <geometry>
                <box size="0.13554     0.24008    0.098815"/>
            </geometry>
        </visual>

        <collision>
			<!--box origin wrt pHipOrigin-->
            <origin xyz="0           0    0.049333" rpy="0 0 0" />
            <geometry>
                <box size="0.13554     0.24008    0.098815"/>
            </geometry>
        </collision>

    </link>
    <!--Chain from (2) to (7)-->
	<link name="L5_f1">
        <inertial>
            <mass value="0.0001"/>
            <origin xyz="0 0 0" rpy="0 0 0" />
            <inertia ixx="0.0003" iyy="0.0003" izz="0.0003" ixy="0" ixz="0" iyz="0"/>
        </inertial>
    </link>
	<link name="L5_f2">
        <inertial>
            <mass value="0.0001"/>
            <origin xyz="0 0 0" rpy="0 0 0" />
            <inertia ixx="0.0003" iyy="0.0003" izz="0.0003" ixy="0" ixz="0" iyz="0"/>
        </inertial>
    </link>
	<link name="L5">
        <inertial>
            <mass value="6.3709"/>
			<!--COM origin wrt jL5S1-->
            <origin xyz="0           0    0.054602" rpy="0 0 0" />
            <inertia ixx="0.047176" iyy="0.03559" izz="0.069139" ixy="0" ixz="0" iyz="0"/>
        </inertial>

        <visual>
			<!--box origin origin wrt jL5S1-->
            <origin xyz="0           0    0.054602" rpy="0 0 0" />
            <geometry>
                <box size="0.13554     0.16014      0.1092"/>
            </geometry>
        </visual>

        <collision>
			<!--box origin origin wrt jL5S1-->
            <origin xyz="0           0    0.054602" rpy="0 0 0" />
            <geometry>
                <box size="0.13554     0.16014      0.1092"/>
            </geometry>
        </collision>
    </link>
	<link name="L3_f1">
        <inertial>
            <mass value="0.0001"/>
            <origin xyz="0 0 0" rpy="0 0 0" />
            <inertia ixx="0.0003" iyy="0.0003" izz="0.0003" ixy="0" ixz="0" iyz="0"/>
        </inertial>
    </link>
	<link name="L3_f2">
        <inertial>
            <mass value="0.0001"/>
            <origin xyz="0 0 0" rpy="0 0 0" />
            <inertia ixx="0.0003" iyy="0.0003" izz="0.0003" ixy="0" ixz="0" iyz="0"/>
        </inertial>
    </link>
	<link name="L3">
        <inertial>
            <mass value="6.3709"/>
			<!--COM origin wrt jL4L3-->
            <origin xyz="0           0    0.049336" rpy="0 0 0" />
            <inertia ixx="0.046013" iyy="0.034427" izz="0.069139" ixy="0" ixz="0" iyz="0"/>
        </inertial>

        <visual>
			<!--box origin origin wrt jL4L3-->
            <origin xyz="0           0    0.049336" rpy="0 0 0" />
            <geometry>
                <box size="0.13554     0.16014    0.098672"/>
            </geometry>
        </visual>

        <collision>
			<!--box origin origin wrt jL4L3-->
            <origin xyz="0           0    0.049336" rpy="0 0 0" />
            <geometry>
                <box size="0.13554     0.16014    0.098672"/>
            </geometry>
        </collision>
    </link>
	<link name="T12_f1">
        <inertial>
            <mass value="0.0001"/>
            <origin xyz="0 0 0" rpy="0 0 0" />
            <inertia ixx="0.0003" iyy="0.0003" izz="0.0003" ixy="0" ixz="0" iyz="0"/>
        </inertial>
    </link>
	<link name="T12_f2">
        <inertial>
            <mass value="0.0001"/>
            <origin xyz="0 0 0" rpy="0 0 0" />
            <inertia ixx="0.0003" iyy="0.0003" izz="0.0003" ixy="0" ixz="0" iyz="0"/>
        </inertial>
    </link>
	<link name="T12">
        <inertial>
            <mass value="6.3709"/>
			<!--COM origin wrt jL1T12-->
            <origin xyz="0           0    0.049336" rpy="0 0 0" />
            <inertia ixx="0.046013" iyy="0.034427" izz="0.069139" ixy="0" ixz="0" iyz="0"/>
        </inertial>

        <visual>
			<!--box origin origin wrt jL1T12-->
            <origin xyz="0           0    0.049336" rpy="0 0 0" />
            <geometry>
                <box size="0.13554     0.16014    0.098672"/>
            </geometry>
        </visual>

        <collision>
			<!--box origin origin wrt jL1T12-->
            <origin xyz="0           0    0.049336" rpy="0 0 0" />
            <geometry>
                <box size="0.13554     0.16014    0.098672"/>
            </geometry>
        </collision>
    </link>
	<link name="T8_f1">
        <inertial>
            <mass value="0.0001"/>
            <origin xyz="0 0 0" rpy="0 0 0" />
            <inertia ixx="0.0003" iyy="0.0003" izz="0.0003" ixy="0" ixz="0" iyz="0"/>
        </inertial>
    </link>
	<link name="T8_f2">
        <inertial>
            <mass value="0.0001"/>
            <origin xyz="0 0 0" rpy="0 0 0" />
            <inertia ixx="0.0003" iyy="0.0003" izz="0.0003" ixy="0" ixz="0" iyz="0"/>
        </inertial>
    </link>
	<link name="T8">
        <inertial>
            <mass value="2.4984"/>
			<!--COM origin wrt jT9T8-->
            <origin xyz="0           0    0.069461" rpy="0 0 0" />
            <inertia ixx="0.0047729" iyy="0.0087452" izz="0.0054818" ixy="0" ixz="0" iyz="0"/>
        </inertial>

        <visual>
			<!--box origin wrt jT9T8-->
            <origin xyz="0           0    0.069461" rpy="0 0 0" />
            <geometry>
                <box size="0.15068     0.06021     0.13892"/>
            </geometry>
        </visual>

        <collision>
			<!--box origin wrt jT9T8-->
            <origin xyz="0           0    0.069461" rpy="0 0 0" />
            <geometry>
                <box size="0.15068     0.06021     0.13892"/>
            </geometry>
        </collision>

    </link>
	<link name="Neck_f1">
        <inertial>
            <mass value="0.0001"/>
            <origin xyz="0 0 0" rpy="0 0 0" />
            <inertia ixx="0.0003" iyy="0.0003" izz="0.0003" ixy="0" ixz="0" iyz="0"/>
        </inertial>
    </link>
	<link name="Neck_f2">
        <inertial>
            <mass value="0.0001"/>
            <origin xyz="0 0 0" rpy="0 0 0" />
            <inertia ixx="0.0003" iyy="0.0003" izz="0.0003" ixy="0" ixz="0" iyz="0"/>
        </inertial>
    </link>
	<link name="Neck">
        <inertial>
            <mass value="0.74952"/>
			<!--COM origin wrt jT1C7-->
            <origin xyz="0           0    0.045917" rpy="0 0 0" />
            <inertia ixx="0.0006888" iyy="0.0006888" izz="0.00032408" ixy="0" ixz="0" iyz="0"/>
        </inertial>

        <visual>
			<!--box origin wrt jT1C7-->
            <origin xyz="0           0    0.045917" rpy="0 0 0" />
            <geometry>
		<cylinder length="0.091834" radius="0.014704"/>
            </geometry>
        </visual>

        <collision>
			<!--box origin wrt jT1C7-->
            <origin xyz="0           0    0.045917" rpy="0 0 0" />
            <geometry>
                <cylinder length="0.091834" radius="0.014704"/>
            </geometry>
        </collision>
    </link>
    <!--
	<link name="Head_f1">
        <inertial>
            <mass value="0.0001"/>
            <origin xyz="0 0 0" rpy="0 0 0" />
            <inertia ixx="0.0003" iyy="0.0003" izz="0.0003" ixy="0" ixz="0" iyz="0"/>
        </inertial>
    </link>
	<link name="Head_f2">
        <inertial>
            <mass value="0.0001"/>
            <origin xyz="0 0 0" rpy="0 0 0" />
            <inertia ixx="0.0003" iyy="0.0003" izz="0.0003" ixy="0" ixz="0" iyz="0"/>
        </inertial>
    </link>
    -->
	<link name="Head">
        <inertial>
            <mass value="2.2486"/>
			<!--COM origin wrt jC1Head-->
            <origin xyz="0           0    0.087994" rpy="0 0 0" />
            <inertia ixx="0.0069641" iyy="0.0069641" izz="0.0069641" ixy="0" ixz="0" iyz="0"/>
        </inertial>

        <visual>
			<!--boc origin wrt jC1Head-->
            <origin xyz="0           0    0.087994" rpy="0 0 0" />
            <geometry>
                <sphere radius="0.087994"/>
            </geometry>
        </visual>

        <collision>
			<!--box origin wrt jC1Head-->
            <origin xyz="0           0    0.087994" rpy="0 0 0" />
            <geometry>
                <sphere radius="0.087994"/>
            </geometry>
        </collision>

    </link>
	<!--Chain from (8) to (11)-->
	<link name="RightShoulder_f1">
        <inertial>
            <mass value="0.0001"/>
            <origin xyz="0 0 0" rpy="0 0 0" />
            <inertia ixx="0.0003" iyy="0.0003" izz="0.0003" ixy="0" ixz="0" iyz="0"/>
        </inertial>
    </link>
	<link name="RightShoulder_f2">
        <inertial>
            <mass value="0.0001"/>
            <origin xyz="0 0 0" rpy="0 0 0" />
            <inertia ixx="0.0003" iyy="0.0003" izz="0.0003" ixy="0" ixz="0" iyz="0"/>
        </inertial>
    </link>
	<link name="RightShoulder">
        <inertial>
            <mass value="1.9363"/>
			<!--COM origin wrt jRightC7Shoulder-->
            <origin xyz="0   -0.069978           0" rpy="0 0 0" />
            <inertia ixx="0.0034631" iyy="0.00060506" izz="0.0034631" ixy="0" ixz="0" iyz="0"/>
        </inertial>

        <visual>
			<!--box origin wrt jRightC7Shoulder. RPY rotated of pi/2.-->
            <origin xyz="0   -0.069978           0" rpy="1.5708 0 0" />
            <geometry>
                <cylinder length="0.13996" radius="0.025"/>
            </geometry>
        </visual>

        <collision>
			<!--box origin wrt jRightC7Shoulder. RPY rotated of pi/2.-->
            <origin xyz="0   -0.069978           0" rpy="1.5708 0 0" />
            <geometry>
                <cylinder length="0.13996" radius="0.025"/>
            </geometry>
        </collision>

    </link>
	<link name="RightUpperArm_f1">
        <inertial>
            <mass value="0.0001"/>
            <origin xyz="0 0 0" rpy="0 0 0" />
            <inertia ixx="0.0003" iyy="0.0003" izz="0.0003" ixy="0" ixz="0" iyz="0"/>
        </inertial>
    </link>
	<link name="RightUpperArm_f2">
        <inertial>
            <mass value="0.0001"/>
            <origin xyz="0 0 0" rpy="0 0 0" />
            <inertia ixx="0.0003" iyy="0.0003" izz="0.0003" ixy="0" ixz="0" iyz="0"/>
        </inertial>
    </link>
    <link name="RightUpperArm">
        <inertial>
            <mass value="1.8738"/>
			<!--COM origin wrt jRightShoulder-->
            <origin xyz="0    -0.15002           0" rpy="0 0 0" />
            <inertia ixx="0.014553" iyy="0.014553" izz="0.00099006" ixy="0" ixz="0" iyz="0"/>
        </inertial>

        <visual>
			<!--box origin wrt jRightShoulder. RPY rotated of pi/2.-->
            <origin xyz="0    -0.15002           0" rpy="1.5708 0 0" />
            <geometry>
                <cylinder length="0.30005" radius="0.032507"/>
            </geometry>
        </visual>

        <collision>
			<!--box origin wrt jRightShoulder. RPY rotated of pi/2.-->
            <origin xyz="0    -0.15002           0" rpy="1.5708 0 0" />
            <geometry>
                <cylinder length="0.30005" radius="0.032507"/>
            </geometry>
        </collision>

    </link>
	<link name="RightForeArm_f1">
        <inertial>
            <mass value="0.0001"/>
            <origin xyz="0 0 0" rpy="0 0 0" />
            <inertia ixx="0.0003" iyy="0.0003" izz="0.0003" ixy="0" ixz="0" iyz="0"/>
        </inertial>
    </link>
	<link name="RightForeArm_f2">
        <inertial>
            <mass value="0.0001"/>
            <origin xyz="0 0 0" rpy="0 0 0" />
            <inertia ixx="0.0003" iyy="0.0003" izz="0.0003" ixy="0" ixz="0" iyz="0"/>
        </inertial>
    </link>
	<link name="RightForeArm">
        <inertial>
            <mass value="1.2492"/>
			<!--COM origin wrt jRightElbow-->
            <origin xyz="0    -0.12263           0" rpy="0 0 0" />
            <inertia ixx="0.0064089" iyy="0.0064089" izz="0.00029335" ixy="0" ixz="0" iyz="0"/>
        </inertial>

        <visual>
			<!--box origin wrt jRightElbow. RPY rotated of pi/2.-->
            <origin xyz="0    -0.12263           0" rpy="1.5708 0 0" />
            <geometry>
                <cylinder length="0.24527" radius="0.021672"/>
            </geometry>
        </visual>

        <collision>
			<!--box origin wrt jRightElbow. RPY rotated of pi/2.-->
            <origin xyz="0    -0.12263           0" rpy="1.5708 0 0" />
            <geometry>
                <cylinder length="0.24527" radius="0.021672"/>
            </geometry>
        </collision>

    </link>
	<link name="RightHand_f1">
        <inertial>
            <mass value="0.0001"/>
            <origin xyz="0 0 0" rpy="0 0 0" />
            <inertia ixx="0.0003" iyy="0.0003" izz="0.0003" ixy="0" ixz="0" iyz="0"/>
        </inertial>
    </link>
	<link name="RightHand_f2">
        <inertial>
            <mass value="0.0001"/>
            <origin xyz="0 0 0" rpy="0 0 0" />
            <inertia ixx="0.0003" iyy="0.0003" izz="0.0003" ixy="0" ixz="0" iyz="0"/>
        </inertial>
    </link>
	<link name="RightHand">
        <inertial>
            <mass value="0.37476"/>
			<!--COM origin wrt jRightWrist-->
            <origin xyz="0   -0.091535           0" rpy="0 0 0" />
            <inertia ixx="0.0011053" iyy="0.00052385" izz="0.0015118" ixy="0" ixz="0" iyz="0"/>
        </inertial>

        <visual>
			<!--box origin wrt jRightWrist-->
            <origin xyz="0   -0.091535           0" rpy="0 0 0" />
            <geometry>
                <box size="0.12205     0.18307    0.043343"/>
            </geometry>
        </visual>

        <collision>
			<!--box origin wrt jRightWrist-->
            <origin xyz="0   -0.091535           0" rpy="0 0 0" />
            <geometry>
                <box size="0.12205     0.18307    0.043343"/>
            </geometry>
        </collision>

    </link>
	<!--Chain from (12) to (15)-->
	<link name="LeftShoulder_f1">
        <inertial>
            <mass value="0.0001"/>
            <origin xyz="0 0 0" rpy="0 0 0" />
            <inertia ixx="0.0003" iyy="0.0003" izz="0.0003" ixy="0" ixz="0" iyz="0"/>
        </inertial>
    </link>
	<link name="LeftShoulder_f2">
        <inertial>
            <mass value="0.0001"/>
            <origin xyz="0 0 0" rpy="0 0 0" />
            <inertia ixx="0.0003" iyy="0.0003" izz="0.0003" ixy="0" ixz="0" iyz="0"/>
        </inertial>
    </link>
	<link name="LeftShoulder">
        <inertial>
            <mass value="1.9363"/>
			<!--COM origin wrt jLeftC7Shoulder-->
            <origin xyz="0    0.069978           0" rpy="0 0 0" />
            <inertia ixx="0.0034631" iyy="0.00060506" izz="0.0034631" ixy="0" ixz="0" iyz="0"/>
        </inertial>

        <visual>
			<!--box origin wrt jLeftC7Shoulder. RPY rotated of pi/2.-->
            <origin xyz="0    0.069978           0" rpy="1.5708 0 0" />
            <geometry>
                <cylinder length="0.13996" radius="0.025"/>
            </geometry>
        </visual>

        <collision>
			<!--box origin wrt jLeftC7Shoulder. RPY rotated of pi/2.-->
            <origin xyz="0    0.069978           0" rpy="1.5708 0 0" />
            <geometry>
                <cylinder length="0.13996" radius="0.025"/>
            </geometry>
        </collision>

    </link>
	<link name="LeftUpperArm_f1">
        <inertial>
            <mass value="0.0001"/>
            <origin xyz="0 0 0" rpy="0 0 0" />
            <inertia ixx="0.0003" iyy="0.0003" izz="0.0003" ixy="0" ixz="0" iyz="0"/>
        </inertial>
    </link>
	<link name="LeftUpperArm_f2">
        <inertial>
            <mass value="0.0001"/>
            <origin xyz="0 0 0" rpy="0 0 0" />
            <inertia ixx="0.0003" iyy="0.0003" izz="0.0003" ixy="0" ixz="0" iyz="0"/>
        </inertial>
    </link>
	<link name="LeftUpperArm">
        <inertial>
            <mass value="1.8738"/>
			<!--COM origin wrt jLeftShoulder-->
            <origin xyz="0     0.15002           0" rpy="0 0 0" />
            <inertia ixx="0.014553" iyy="0.014553" izz="0.00099006" ixy="0" ixz="0" iyz="0"/>
        </inertial>

        <visual>
			<!--box origin wrt jLeftShoulder. RPY rotated of pi/2.-->
            <origin xyz="0     0.15002           0" rpy="1.5708 0 0" />
            <geometry>
                <cylinder length="0.30005" radius="0.032507"/>
            </geometry>
        </visual>

        <collision>
			<!--box origin wrt jLeftShoulder. RPY rotated of pi/2.-->
            <origin xyz="0     0.15002           0" rpy="1.5708 0 0" />
            <geometry>
                <cylinder length="0.30005" radius="0.032507"/>
            </geometry>
        </collision>

    </link>
	<link name="LeftForeArm_f1">
        <inertial>
            <mass value="0.0001"/>
            <origin xyz="0 0 0" rpy="0 0 0" />
            <inertia ixx="0.0003" iyy="0.0003" izz="0.0003" ixy="0" ixz="0" iyz="0"/>
        </inertial>
    </link>
	<link name="LeftForeArm_f2">
        <inertial>
            <mass value="0.0001"/>
            <origin xyz="0 0 0" rpy="0 0 0" />
            <inertia ixx="0.0003" iyy="0.0003" izz="0.0003" ixy="0" ixz="0" iyz="0"/>
        </inertial>
    </link>
	<link name="LeftForeArm">
        <inertial>
            <mass value="1.2492"/>
			<!--COM origin wrt jLeftElbow-->
            <origin xyz="0     0.12263           0" rpy="0 0 0" />
            <inertia ixx="0.0064089" iyy="0.0064089" izz="0.00029335" ixy="0" ixz="0" iyz="0"/>
        </inertial>

        <visual>
			<!--box origin wrt jLeftElbow. RPY rotated of pi/2.-->
            <origin xyz="0     0.12263           0" rpy="1.5708 0 0" />
            <geometry>
                <cylinder length="0.24527" radius="0.021672"/>
            </geometry>
        </visual>

        <collision>
			<!--box origin wrt jLeftElbow. RPY rotated of pi/2.-->
            <origin xyz="0     0.12263           0" rpy="1.5708 0 0" />
            <geometry>
                <cylinder length="0.24527" radius="0.021672"/>
            </geometry>
        </collision>

    </link>
	<link name="LeftHand_f1">
        <inertial>
            <mass value="0.0001"/>
            <origin xyz="0 0 0" rpy="0 0 0" />
            <inertia ixx="0.0003" iyy="0.0003" izz="0.0003" ixy="0" ixz="0" iyz="0"/>
        </inertial>
    </link>
	<link name="LeftHand_f2">
        <inertial>
            <mass value="0.0001"/>
            <origin xyz="0 0 0" rpy="0 0 0" />
            <inertia ixx="0.0003" iyy="0.0003" izz="0.0003" ixy="0" ixz="0" iyz="0"/>
        </inertial>
    </link>
	<link name="LeftHand">
        <inertial>
            <mass value="0.37476"/>
			<!--COM origin wrt jLeftWrist-->
            <origin xyz="0    0.091535           0" rpy="0 0 0" />
            <inertia ixx="0.0011053" iyy="0.00052385" izz="0.0015118" ixy="0" ixz="0" iyz="0"/>
        </inertial>

        <visual>
			<!--COM origin wrt jLeftWrist-->
            <origin xyz="0    0.091535           0" rpy="0 0 0" />
            <geometry>
                <box size="0.12205     0.18307    0.043343"/>
            </geometry>
        </visual>

        <collision>
			<!--COM origin wrt jLeftWrist-->
            <origin xyz="0    0.091535           0" rpy="0 0 0" />
            <geometry>
                <box size="0.12205     0.18307    0.043343"/>
            </geometry>
        </collision>

    </link>
	<!--Chain from (16) to (19)-->
	<link name="RightUpperLeg_f1">
        <inertial>
            <mass value="0.0001"/>
            <origin xyz="0 0 0" rpy="0 0 0" />
            <inertia ixx="0.0003" iyy="0.0003" izz="0.0003" ixy="0" ixz="0" iyz="0"/>
        </inertial>
    </link>
	<link name="RightUpperLeg_f2">
        <inertial>
            <mass value="0.0001"/>
            <origin xyz="0 0 0" rpy="0 0 0" />
            <inertia ixx="0.0003" iyy="0.0003" izz="0.0003" ixy="0" ixz="0" iyz="0"/>
        </inertial>
    </link>
    <link name="RightUpperLeg">
        <inertial>
            <mass value="7.8075"/>
			<!--COM origin wrt jRightHip-->
            <origin xyz="0           0    -0.21002" rpy="0 0 0" />
            <inertia ixx="0.12026" iyy="0.12026" izz="0.010935" ixy="0" ixz="0" iyz="0"/>
        </inertial>

        <visual>
			<!--box origin wrt jRightHip-->
            <origin xyz="0           0    -0.21002" rpy="0 0 0" />
            <geometry>
                <cylinder length="0.42004" radius="0.052927"/>
            </geometry>
        </visual>

        <collision>
			<!--box origin wrt jRightHip-->
            <origin xyz="0           0    -0.21002" rpy="0 0 0" />
            <geometry>
                <cylinder length="0.42004" radius="0.052927"/>
            </geometry>
        </collision>

    </link>
	<link name="RightLowerLeg_f1">
        <inertial>
            <mass value="0.0001"/>
            <origin xyz="0 0 0" rpy="0 0 0" />
            <inertia ixx="0.0003" iyy="0.0003" izz="0.0003" ixy="0" ixz="0" iyz="0"/>
        </inertial>
    </link>
	<link name="RightLowerLeg_f2">
        <inertial>
            <mass value="0.0001"/>
            <origin xyz="0 0 0" rpy="0 0 0" />
            <inertia ixx="0.0003" iyy="0.0003" izz="0.0003" ixy="0" ixz="0" iyz="0"/>
        </inertial>
    </link>
    <link name="RightLowerLeg">
        <inertial>
            <mass value="2.2798"/>
			<!--COM origin wrt jRightKnee-->
            <origin xyz="0           0    -0.20367" rpy="0 0 0" />
            <inertia ixx="0.032328" iyy="0.032328" izz="0.0016104" ixy="0" ixz="0" iyz="0"/>
        </inertial>

        <visual>
			<!--box origin wrt jRightKnee-->
            <origin xyz="0           0    -0.20367" rpy="0 0 0" />
            <geometry>
                <cylinder length="0.40734" radius="0.037587"/>
            </geometry>
        </visual>

        <collision>
			<!--box origin wrt jRightKnee-->
            <origin xyz="0           0    -0.20367" rpy="0 0 0" />
            <geometry>
                <cylinder length="0.40734" radius="0.037587"/>
            </geometry>
        </collision>

    </link>
	<link name="RightFoot_f1">
        <inertial>
            <mass value="0.0001"/>
            <origin xyz="0 0 0" rpy="0 0 0" />
            <inertia ixx="0.0003" iyy="0.0003" izz="0.0003" ixy="0" ixz="0" iyz="0"/>
        </inertial>
    </link>
	<link name="RightFoot_f2">
        <inertial>
            <mass value="0.0001"/>
            <origin xyz="0 0 0" rpy="0 0 0" />
            <inertia ixx="0.0003" iyy="0.0003" izz="0.0003" ixy="0" ixz="0" iyz="0"/>
        </inertial>
    </link>
    <link name="RightFoot">
        <inertial>
            <mass value="0.81198"/>
			<!--COM origin wrt jRightAnkle-->
            <origin xyz="0.05524           0   -0.052405" rpy="0 0 0" />
            <inertia ixx="0.0011257" iyy="0.0033102" izz="0.0029493" ixy="0" ixz="0" iyz="0"/>
        </inertial>

        <visual>
			<!--box origin wrt jRightAnkle-->
	    	<origin xyz="0.05524           0   -0.052405" rpy="0 0 0" />
            <geometry>
                <box size="0.19477    0.075174     0.10481"/>
            </geometry>
        </visual>

        <collision>
			<!--box origin wrt jRightAnkle-->
		    <origin xyz="0.05524           0   -0.052405" rpy="0 0 0" />
	            <geometry>
	                <box size="0.19477    0.075174     0.10481"/>
	            </geometry>
        </collision>

    </link>
	<link name="RightToe_f1">
        <inertial>
            <mass value="0.0001"/>
            <origin xyz="0 0 0" rpy="0 0 0" />
            <inertia ixx="0.0003" iyy="0.0003" izz="0.0003" ixy="0" ixz="0" iyz="0"/>
        </inertial>
    </link>
	<link name="RightToe_f2">
        <inertial>
            <mass value="0.0001"/>
            <origin xyz="0 0 0" rpy="0 0 0" />
            <inertia ixx="0.0003" iyy="0.0003" izz="0.0003" ixy="0" ixz="0" iyz="0"/>
        </inertial>
    </link>
    <link name="RightToe">
        <inertial>
            <mass value="0.09369"/>
			<!--COM origin wrt jRightBallFoot-->
            <origin xyz="0.029147           0           0" rpy="0 0 0" />
            <inertia ixx="4.579e-05" iyy="2.8201e-05" izz="7.0653e-05" ixy="0" ixz="0" iyz="0"/>
        </inertial>

        <visual>
			<!--box origin wrt jRightBallFoot-->
            <origin xyz="0.029147           0           0" rpy="0 0 0" />
            <geometry>
                <box size="0.058294    0.075174    0.014622"/>
            </geometry>
        </visual>

        <collision>
			<!--box origin wrt jRightBallFoot-->
            <origin xyz="0.029147           0           0" rpy="0 0 0" />
            <geometry>
                <box size="0.058294    0.075174    0.014622"/>
            </geometry>
        </collision>
    </link>
	<!--Chain from (20) to (23)-->
	<link name="LeftUpperLeg_f1">
        <inertial>
            <mass value="0.0001"/>
            <origin xyz="0 0 0" rpy="0 0 0" />
            <inertia ixx="0.0003" iyy="0.0003" izz="0.0003" ixy="0" ixz="0" iyz="0"/>
        </inertial>
    </link>
	<link name="LeftUpperLeg_f2">
        <inertial>
            <mass value="0.0001"/>
            <origin xyz="0 0 0" rpy="0 0 0" />
            <inertia ixx="0.0003" iyy="0.0003" izz="0.0003" ixy="0" ixz="0" iyz="0"/>
        </inertial>
    </link>
    <link name="LeftUpperLeg">
        <inertial>
            <mass value="7.8075"/>
			<!--COM origin wrt jLeftHip-->
            <origin xyz="0           0    -0.21002" rpy="0 0 0" />
            <inertia ixx="0.12026" iyy="0.12026" izz="0.010935" ixy="0" ixz="0" iyz="0"/>
        </inertial>

        <visual>
			<!--box origin wrt jLeftHip-->
            <origin xyz="0           0    -0.21002" rpy="0 0 0" />
            <geometry>
                <cylinder length="0.42004" radius="-0.052927"/>
            </geometry>
        </visual>

        <collision>
			<!--box origin wrt jLeftHip-->
            <origin xyz="0           0    -0.21002" rpy="0 0 0" />
            <geometry>
                <cylinder length="0.42004" radius="-0.052927"/>
            </geometry>
        </collision>

    </link>
	<link name="LeftLowerLeg_f1">
        <inertial>
            <mass value="0.0001"/>
            <origin xyz="0 0 0" rpy="0 0 0" />
            <inertia ixx="0.0003" iyy="0.0003" izz="0.0003" ixy="0" ixz="0" iyz="0"/>
        </inertial>
    </link>
	<link name="LeftLowerLeg_f2">
        <inertial>
            <mass value="0.0001"/>
            <origin xyz="0 0 0" rpy="0 0 0" />
            <inertia ixx="0.0003" iyy="0.0003" izz="0.0003" ixy="0" ixz="0" iyz="0"/>
        </inertial>
    </link>
	<link name="LeftLowerLeg">
        <inertial>
            <mass value="2.2798"/>
			<!--COM origin wrt jLeftKnee-->
            <origin xyz="0           0    -0.20367" rpy="0 0 0" />
            <inertia ixx="0.032328" iyy="0.032328" izz="0.0016104" ixy="0" ixz="0" iyz="0"/>
        </inertial>

        <visual>
			<!--box origin wrt jLeftKnee-->
            <origin xyz="0           0    -0.20367" rpy="0 0 0" />
            <geometry>
		<cylinder length="0.40734" radius="0.037587"/>
            </geometry>
        </visual>

        <collision>
			<!--box origin wrt jLeftKnee-->
            <origin xyz="0           0    -0.20367" rpy="0 0 0" />
            <geometry>
		<cylinder length="0.40734" radius="0.037587"/>
            </geometry>
        </collision>

    </link>
	<link name="LeftFoot_f1">
        <inertial>
            <mass value="0.0001"/>
            <origin xyz="0 0 0" rpy="0 0 0" />
            <inertia ixx="0.0003" iyy="0.0003" izz="0.0003" ixy="0" ixz="0" iyz="0"/>
        </inertial>
    </link>
	<link name="LeftFoot_f2">
        <inertial>
            <mass value="0.0001"/>
            <origin xyz="0 0 0" rpy="0 0 0" />
            <inertia ixx="0.0003" iyy="0.0003" izz="0.0003" ixy="0" ixz="0" iyz="0"/>
        </inertial>
    </link>
    <link name="LeftFoot">
        <inertial>
            <mass value="0.81198"/>
			<!--COM origin wrt jLeftAnkle-->
            <origin xyz="0.05524           0   -0.052405" rpy="0 0 0" />
            <inertia ixx="0.0011257" iyy="0.0033102" izz="0.0029493" ixy="0" ixz="0" iyz="0"/>
        </inertial>

        <visual>
			<!--box origin wrt jLeftAnkle-->
	   	 	<origin xyz="0.05524           0   -0.052405" rpy="0 0 0" />
            <geometry>
                <box size="0.19477    0.075174     0.10481"/>
            </geometry>
        </visual>

        <collision>
			<!--box origin wrt jLeftAnkle-->
		    <origin xyz="0.05524           0   -0.052405" rpy="0 0 0" />
	            <geometry>
	                <box size="0.19477    0.075174     0.10481"/>
	            </geometry>
        </collision>

    </link>
	<link name="LeftToe_f1">
        <inertial>
            <mass value="0.0001"/>
            <origin xyz="0 0 0" rpy="0 0 0" />
            <inertia ixx="0.0003" iyy="0.0003" izz="0.0003" ixy="0" ixz="0" iyz="0"/>
        </inertial>
    </link>
	<link name="LeftToe_f2">
        <inertial>
            <mass value="0.0001"/>
            <origin xyz="0 0 0" rpy="0 0 0" />
            <inertia ixx="0.0003" iyy="0.0003" izz="0.0003" ixy="0" ixz="0" iyz="0"/>
        </inertial>
    </link>
	<link name="LeftToe">
        <inertial>
            <mass value="0.09369"/>
			<!--COM origin wrt jLeftBallFoot-->
            <origin xyz="0.029147           0           0" rpy="0 0 0" />
            <inertia ixx="4.579e-05" iyy="2.8201e-05" izz="7.0653e-05" ixy="0" ixz="0" iyz="0"/>
        </inertial>

        <visual>
			<!--box origin wrt jLeftBallFoot-->
            <origin xyz="0.029147           0           0" rpy="0 0 0" />
            <geometry>
                <box size="0.058294    0.075174    0.014622"/>
            </geometry>
        </visual>

        <collision>
			<!--box origin wrt jLeftBallFoot-->
            <origin xyz="0.029147           0           0" rpy="0 0 0" />
            <geometry>
                <box size="0.058294    0.075174    0.014622"/>
            </geometry>
        </collision>
    </link>


	<!--JOINTS-->
	<!--Chain from (2) to (7)-->
	<joint name="jL5S1_rotx" type="revolute">
        <origin xyz="1.5e-05           0    0.098741" rpy="0 0 0"/>
        <parent link="Pelvis"/>
        <child link="L5_f1"/>
        <dynamics damping="0.1" friction="0.0"/>
        <limit effort="30" velocity="1.0" lower="-3.141592" upper="3.141592" />
        <axis xyz="1 0 0" />
    </joint>
	<joint name="jL5S1_roty" type="revolute">
        <origin xyz="0 0 0" rpy="0 0 0"/>
        <parent link="L5_f1"/>
        <child link="L5_f2"/>
        <dynamics damping="0.1" friction="0.0"/>
        <limit effort="30" velocity="1.0" lower="-3.141592" upper="3.141592" />
        <axis xyz="0 1 0" />
    </joint>
    <joint name="jL5S1_rotz" type="revolute">
        <origin xyz="0 0 0" rpy="0 0 0"/>
        <parent link="L5_f2"/>
        <child link="L5"/>
        <dynamics damping="0.1" friction="0.0"/>
        <limit effort="30" velocity="1.0" lower="-3.141592" upper="3.141592" />
        <axis xyz="0 0 1" />
    </joint>
	<joint name="jL4L3_rotx" type="revolute">
        <origin xyz="-2.7e-05           0      0.1092" rpy="0 0 0"/>
        <parent link="L5"/>
        <child link="L3_f1"/>
        <dynamics damping="0.1" friction="0.0"/>
        <limit effort="30" velocity="1.0" lower="-3.141592" upper="3.141592" />
        <axis xyz="1 0 0" />
    </joint>
	<joint name="jL4L3_roty" type="revolute">
        <origin xyz="0 0 0" rpy="0 0 0"/>
        <parent link="L3_f1"/>
        <child link="L3_f2"/>
        <dynamics damping="0.1" friction="0.0"/>
        <limit effort="30" velocity="1.0" lower="-3.141592" upper="3.141592" />
        <axis xyz="0 1 0" />
    </joint>
    <joint name="jL4L3_rotz" type="revolute">
        <origin xyz="0 0 0" rpy="0 0 0"/>
        <parent link="L3_f2"/>
        <child link="L3"/>
        <dynamics damping="0.1" friction="0.0"/>
        <limit effort="30" velocity="1.0" lower="-3.141592" upper="3.141592" />
        <axis xyz="0 0 1" />
    </joint>
	<joint name="jL1T12_rotx" type="revolute">
        <origin xyz="0           0    0.098672" rpy="0 0 0"/>
        <parent link="L3"/>
        <child link="T12_f1"/>
        <dynamics damping="0.1" friction="0.0"/>
        <limit effort="30" velocity="1.0" lower="-3.141592" upper="3.141592" />
        <axis xyz="1 0 0" />
    </joint>
	<joint name="jL1T12_roty" type="revolute">
        <origin xyz="0 0 0" rpy="0 0 0"/>
        <parent link="T12_f1"/>
        <child link="T12_f2"/>
        <dynamics damping="0.1" friction="0.0"/>
        <limit effort="30" velocity="1.0" lower="-3.141592" upper="3.141592" />
        <axis xyz="0 1 0" />
    </joint>
    <joint name="jL1T12_rotz" type="revolute">
        <origin xyz="0 0 0" rpy="0 0 0"/>
        <parent link="T12_f2"/>
        <child link="T12"/>
        <dynamics damping="0.1" friction="0.0"/>
        <limit effort="30" velocity="1.0" lower="-3.141592" upper="3.141592" />
        <axis xyz="0 0 1" />
    </joint>
	<joint name="jT9T8_rotx" type="revolute">
        <origin xyz="0           0    0.098672" rpy="0 0 0"/>
        <parent link="T12"/>
        <child link="T8_f1"/>
        <dynamics damping="0.1" friction="0.0"/>
        <limit effort="30" velocity="1.0" lower="-3.141592" upper="3.141592" />
        <axis xyz="1 0 0" />
    </joint>
	<joint name="jT9T8_roty" type="revolute">
        <origin xyz="0 0 0" rpy="0 0 0"/>
        <parent link="T8_f1"/>
        <child link="T8_f2"/>
        <dynamics damping="0.1" friction="0.0"/>
        <limit effort="30" velocity="1.0" lower="-3.141592" upper="3.141592" />
        <axis xyz="0 1 0" />
    </joint>
    <joint name="jT9T8_rotz" type="revolute">
        <origin xyz="0 0 0" rpy="0 0 0"/>
        <parent link="T8_f2"/>
        <child link="T8"/>
        <dynamics damping="0.1" friction="0.0"/>
        <limit effort="30" velocity="1.0" lower="-3.141592" upper="3.141592" />
        <axis xyz="0 0 1" />
    </joint>
	<joint name="jT1C7_rotx" type="revolute">
        <origin xyz="0           0     0.13892" rpy="0 0 0"/>
        <parent link="T8"/>
        <child link="Neck_f1"/>
        <dynamics damping="0.1" friction="0.0"/>
        <limit effort="30" velocity="1.0" lower="-3.141592" upper="3.141592" />
        <axis xyz="1 0 0" />
    </joint>
	<joint name="jT1C7_roty" type="revolute">
        <origin xyz="0 0 0" rpy="0 0 0"/>
        <parent link="Neck_f1"/>
        <child link="Neck_f2"/>
        <dynamics damping="0.1" friction="0.0"/>
        <limit effort="30" velocity="1.0" lower="-3.141592" upper="3.141592" />
        <axis xyz="0 1 0" />
    </joint>
    <joint name="jT1C7_rotz" type="revolute">
        <origin xyz="0 0 0" rpy="0 0 0"/>
        <parent link="Neck_f2"/>
        <child link="Neck"/>
        <dynamics damping="0.1" friction="0.0"/>
        <limit effort="30" velocity="1.0" lower="-3.141592" upper="3.141592" />
        <axis xyz="0 0 1" />
    </joint>
	<joint name="jC1Head_rotx" type="revolute">
        <origin xyz="-6.5e-05           0    0.091834" rpy="1.57079632679 0.7853 0"/>
        <parent link="Neck"/>
        <child link="Head"/>
        <dynamics damping="0.1" friction="0.0"/>
        <limit effort="30" velocity="1.0" lower="-3.141592" upper="3.141592" />
        <axis xyz="1 0 0" />
    </joint>
<!--
<joint name="jC1Head_roty" type="revolute">
        <origin xyz="0 0 0" rpy="0 0 0"/>
        <parent link="Head_f1"/>
        <child link="Head_f2"/>
        <dynamics damping="0.1" friction="0.0"/>
        <limit effort="30" velocity="1.0" lower="-3.141592" upper="3.141592" />
        <axis xyz="0 1 0" />
    </joint>
    <joint name="jC1Head_rotz" type="revolute">
        <origin xyz="0 0 0" rpy="0 0 0"/>
        <parent link="Head_f2"/>
        <child link="Head"/>
        <dynamics damping="0.1" friction="0.0"/>
        <limit effort="30" velocity="1.0" lower="-3.141592" upper="3.141592" />
        <axis xyz="0 0 1" />
    </joint>
    -->
	<!--Chain from (8) to (11)-->
	<joint name="jRightC7Shoulder_rotx" type="revolute">
        <origin xyz="0   -0.030105    0.077497" rpy="0 0 0"/>
        <parent link="T8"/>
        <child link="RightShoulder_f1"/>
        <dynamics damping="0.1" friction="0.0"/>
        <limit effort="30" velocity="1.0" lower="-3.141592" upper="3.141592" />
        <axis xyz="1 0 0" />
    </joint>
	<joint name="jRightC7Shoulder_roty" type="revolute">
        <origin xyz="0 0 0" rpy="0 0 0"/>
        <parent link="RightShoulder_f1"/>
        <child link="RightShoulder_f2"/>
        <dynamics damping="0.1" friction="0.0"/>
        <limit effort="30" velocity="1.0" lower="-3.141592" upper="3.141592" />
        <axis xyz="0 1 0" />
    </joint>
    <joint name="jRightC7Shoulder_rotz" type="revolute">
        <origin xyz="0 0 0" rpy="0 0 0"/>
        <parent link="RightShoulder_f2"/>
        <child link="RightShoulder"/>
        <dynamics damping="0.1" friction="0.0"/>
        <limit effort="30" velocity="1.0" lower="-3.141592" upper="3.141592" />
        <axis xyz="0 0 1" />
    </joint>
	<joint name="jRightShoulder_rotx" type="revolute">
        <origin xyz="0    -0.13996           0" rpy="0 0 0"/>
        <parent link="RightShoulder"/>
        <child link="RightUpperArm_f1"/>
        <dynamics damping="0.1" friction="0.0"/>
        <limit effort="30" velocity="1.0" lower="-3.141592" upper="3.141592" />
        <axis xyz="1 0 0" />
    </joint>
	<joint name="jRightShoulder_roty" type="revolute">
        <origin xyz="0 0 0" rpy="0 0 0"/>
        <parent link="RightUpperArm_f1"/>
        <child link="RightUpperArm_f2"/>
        <dynamics damping="0.1" friction="0.0"/>
        <limit effort="30" velocity="1.0" lower="-3.141592" upper="3.141592" />
        <axis xyz="0 1 0" />
    </joint>
    <joint name="jRightShoulder_rotz" type="revolute">
        <origin xyz="0 0 0" rpy="0 0 0"/>
        <parent link="RightUpperArm_f2"/>
        <child link="RightUpperArm"/>
        <dynamics damping="0.1" friction="0.0"/>
        <limit effort="30" velocity="1.0" lower="-3.141592" upper="3.141592" />
        <axis xyz="0 0 1" />
    </joint>
	<joint name="jRightElbow_rotx" type="revolute">
        <origin xyz="0    -0.30005           0" rpy="0 0 0"/>
        <parent link="RightUpperArm"/>
        <child link="RightForeArm_f1"/>
        <dynamics damping="0.1" friction="0.0"/>
        <limit effort="30" velocity="1.0" lower="-3.141592" upper="3.141592" />
        <axis xyz="1 0 0" />
    </joint>
	<joint name="jRightElbow_roty" type="revolute">
        <origin xyz="0 0 0" rpy="0 0 0"/>
        <parent link="RightForeArm_f1"/>
        <child link="RightForeArm_f2"/>
        <dynamics damping="0.1" friction="0.0"/>
        <limit effort="30" velocity="1.0" lower="-3.141592" upper="3.141592" />
        <axis xyz="0 1 0" />
    </joint>
    <joint name="jRightElbow_rotz" type="revolute">
        <origin xyz="0 0 0" rpy="0 0 0"/>
        <parent link="RightForeArm_f2"/>
        <child link="RightForeArm"/>
        <dynamics damping="0.1" friction="0.0"/>
        <limit effort="30" velocity="1.0" lower="-3.141592" upper="3.141592" />
        <axis xyz="0 0 1" />
    </joint>
	<joint name="jRightWrist_rotx" type="revolute">
        <origin xyz="1e-06    -0.24527           0" rpy="0 0 0"/>
        <parent link="RightForeArm"/>
        <child link="RightHand_f1"/>
        <dynamics damping="0.1" friction="0.0"/>
        <limit effort="30" velocity="1.0" lower="-3.141592" upper="3.141592" />
        <axis xyz="1 0 0" />
    </joint>
	<joint name="jRightWrist_roty" type="revolute">
        <origin xyz="0 0 0" rpy="0 0 0"/>
        <parent link="RightHand_f1"/>
        <child link="RightHand_f2"/>
        <dynamics damping="0.1" friction="0.0"/>
        <limit effort="30" velocity="1.0" lower="-3.141592" upper="3.141592" />
        <axis xyz="0 1 0" />
    </joint>
    <joint name="jRightWrist_rotz" type="revolute">
        <origin xyz="0 0 0" rpy="0 0 0"/>
        <parent link="RightHand_f2"/>
        <child link="RightHand"/>
        <dynamics damping="0.1" friction="0.0"/>
        <limit effort="30" velocity="1.0" lower="-3.141592" upper="3.141592" />
        <axis xyz="0 0 1" />
    </joint>
	<!--Chain from (12) to (15)-->
	<joint name="jLeftC7Shoulder_rotx" type="revolute">
        <origin xyz="0    0.030105    0.077497" rpy="0 0 0"/>
        <parent link="T8"/>
        <child link="LeftShoulder_f1"/>
        <dynamics damping="0.1" friction="0.0"/>
        <limit effort="30" velocity="1.0" lower="-3.141592" upper="3.141592" />
        <axis xyz="1 0 0" />
    </joint>
	<joint name="jLeftC7Shoulder_roty" type="revolute">
        <origin xyz="0 0 0" rpy="0 0 0"/>
        <parent link="LeftShoulder_f1"/>
        <child link="LeftShoulder_f2"/>
        <dynamics damping="0.1" friction="0.0"/>
        <limit effort="30" velocity="1.0" lower="-3.141592" upper="3.141592" />
        <axis xyz="0 1 0" />
    </joint>
    <joint name="jLeftC7Shoulder_rotz" type="revolute">
        <origin xyz="0 0 0" rpy="0 0 0"/>
        <parent link="LeftShoulder_f2"/>
        <child link="LeftShoulder"/>
        <dynamics damping="0.1" friction="0.0"/>
        <limit effort="30" velocity="1.0" lower="-3.141592" upper="3.141592" />
        <axis xyz="0 0 1" />
    </joint>
	<joint name="jLeftShoulder_rotx" type="revolute">
        <origin xyz="0     0.13996           0" rpy="0 0 0"/>
        <parent link="LeftShoulder"/>
        <child link="LeftUpperArm_f1"/>
        <dynamics damping="0.1" friction="0.0"/>
        <limit effort="30" velocity="1.0" lower="-3.141592" upper="3.141592" />
        <axis xyz="1 0 0" />
    </joint>
	<joint name="jLeftShoulder_roty" type="revolute">
        <origin xyz="0 0 0" rpy="0 0 0"/>
        <parent link="LeftUpperArm_f1"/>
        <child link="LeftUpperArm_f2"/>
        <dynamics damping="0.1" friction="0.0"/>
        <limit effort="30" velocity="1.0" lower="-3.141592" upper="3.141592" />
        <axis xyz="0 1 0" />
    </joint>
    <joint name="jLeftShoulder_rotz" type="revolute">
        <origin xyz="0 0 0" rpy="0 0 0"/>
        <parent link="LeftUpperArm_f2"/>
        <child link="LeftUpperArm"/>
        <dynamics damping="0.1" friction="0.0"/>
        <limit effort="30" velocity="1.0" lower="-3.141592" upper="3.141592" />
        <axis xyz="0 0 1" />
    </joint>
    <joint name="jLeftElbow_rotx" type="revolute">
        <origin xyz="0     0.30005           0" rpy="0 0 0"/>
        <parent link="LeftUpperArm"/>
        <child link="LeftForeArm_f1"/>
        <dynamics damping="0.1" friction="0.0"/>
        <limit effort="30" velocity="1.0" lower="-3.141592" upper="3.141592" />
        <axis xyz="1 0 0" />
    </joint>
	<joint name="jLeftElbow_roty" type="revolute">
        <origin xyz="0 0 0" rpy="0 0 0"/>
        <parent link="LeftForeArm_f1"/>
        <child link="LeftForeArm_f2"/>
        <dynamics damping="0.1" friction="0.0"/>
        <limit effort="30" velocity="1.0" lower="-3.141592" upper="3.141592" />
        <axis xyz="0 1 0" />
    </joint>
    <joint name="jLeftElbow_rotz" type="revolute">
        <origin xyz="0 0 0" rpy="0 0 0"/>
        <parent link="LeftForeArm_f2"/>
        <child link="LeftForeArm"/>
        <dynamics damping="0.1" friction="0.0"/>
        <limit effort="30" velocity="1.0" lower="-3.141592" upper="3.141592" />
        <axis xyz="0 0 1" />
    </joint>
	<joint name="jLeftWrist_rotx" type="revolute">
        <origin xyz="1e-06     0.24527           0" rpy="0 0 0"/>
        <parent link="LeftForeArm"/>
        <child link="LeftHand_f1"/>
        <dynamics damping="0.1" friction="0.0"/>
        <limit effort="30" velocity="1.0" lower="-3.141592" upper="3.141592" />
        <axis xyz="1 0 0" />
    </joint>
	<joint name="jLeftWrist_roty" type="revolute">
        <origin xyz="0 0 0" rpy="0 0 0"/>
        <parent link="LeftHand_f1"/>
        <child link="LeftHand_f2"/>
        <dynamics damping="0.1" friction="0.0"/>
        <limit effort="30" velocity="1.0" lower="-3.141592" upper="3.141592" />
        <axis xyz="0 1 0" />
    </joint>
    <joint name="jLeftWrist_rotz" type="revolute">
        <origin xyz="0 0 0" rpy="0 0 0"/>
        <parent link="LeftHand_f2"/>
        <child link="LeftHand"/>
        <dynamics damping="0.1" friction="0.0"/>
        <limit effort="30" velocity="1.0" lower="-3.141592" upper="3.141592" />
        <axis xyz="0 0 1" />
    </joint>
	<!--Chain from (16) to (19)-->
	<joint name="jRightHip_rotx" type="revolute">
        <origin xyz="-8e-06   -0.080069    -7.4e-05" rpy="0 0 0"/>
        <parent link="Pelvis"/>
        <child link="RightUpperLeg_f1"/>
        <dynamics damping="0.1" friction="0.0"/>
        <limit effort="30" velocity="1.0" lower="-3.141592" upper="3.141592" />
        <axis xyz="1 0 0" />
    </joint>
	<joint name="jRightHip_roty" type="revolute">
        <origin xyz="0 0 0" rpy="0 0 0"/>
        <parent link="RightUpperLeg_f1"/>
        <child link="RightUpperLeg_f2"/>
        <dynamics damping="0.1" friction="0.0"/>
        <limit effort="30" velocity="1.0" lower="-3.141592" upper="3.141592" />
        <axis xyz="0 1 0" />
    </joint>
    <joint name="jRightHip_rotz" type="revolute">
        <origin xyz="0 0 0" rpy="0 0 0"/>
        <parent link="RightUpperLeg_f2"/>
        <child link="RightUpperLeg"/>
        <dynamics damping="0.1" friction="0.0"/>
        <limit effort="30" velocity="1.0" lower="-3.141592" upper="3.141592" />
        <axis xyz="0 0 1" />
    </joint>
	<joint name="jRightKnee_rotx" type="revolute">
        <origin xyz="8e-06           0    -0.42004" rpy="0 0 0"/>
        <parent link="RightUpperLeg"/>
        <child link="RightLowerLeg_f1"/>
        <dynamics damping="0.1" friction="0.0"/>
        <limit effort="30" velocity="1.0" lower="-3.141592" upper="3.141592" />
        <axis xyz="1 0 0" />
    </joint>
	<joint name="jRightKnee_roty" type="revolute">
        <origin xyz="0 0 0" rpy="0 0 0"/>
        <parent link="RightLowerLeg_f1"/>
        <child link="RightLowerLeg_f2"/>
        <dynamics damping="0.1" friction="0.0"/>
        <limit effort="30" velocity="1.0" lower="-3.141592" upper="3.141592" />
        <axis xyz="0 1 0" />
    </joint>
    <joint name="jRightKnee_rotz" type="revolute">
        <origin xyz="0 0 0" rpy="0 0 0"/>
        <parent link="RightLowerLeg_f2"/>
        <child link="RightLowerLeg"/>
        <dynamics damping="0.1" friction="0.0"/>
        <limit effort="30" velocity="1.0" lower="-3.141592" upper="3.141592" />
        <axis xyz="0 0 1" />
    </joint>
	<joint name="jRightAnkle_rotx" type="revolute">
        <origin xyz="0.00046           0    -0.40734" rpy="0 0 0"/>
        <parent link="RightLowerLeg"/>
        <child link="RightFoot_f1"/>
        <dynamics damping="0.1" friction="0.0"/>
        <limit effort="30" velocity="1.0" lower="-3.141592" upper="3.141592" />
        <axis xyz="1 0 0" />
    </joint>
	<joint name="jRightAnkle_roty" type="revolute">
        <origin xyz="0 0 0" rpy="0 0 0"/>
        <parent link="RightFoot_f1"/>
        <child link="RightFoot_f2"/>
        <dynamics damping="0.1" friction="0.0"/>
        <limit effort="30" velocity="1.0" lower="-3.141592" upper="3.141592" />
        <axis xyz="0 1 0" />
    </joint>
    <joint name="jRightAnkle_rotz" type="revolute">
        <origin xyz="0 0 0" rpy="0 0 0"/>
        <parent link="RightFoot_f2"/>
        <child link="RightFoot"/>
        <dynamics damping="0.1" friction="0.0"/>
        <limit effort="30" velocity="1.0" lower="-3.141592" upper="3.141592" />
        <axis xyz="0 0 1" />
    </joint>
	<joint name="jRightBallFoot_rotx" type="revolute">
        <origin xyz="0.15263           0   -0.088953" rpy="0 0 0"/>
        <parent link="RightFoot"/>
        <child link="RightToe_f1"/>
        <dynamics damping="0.1" friction="0.0"/>
        <limit effort="30" velocity="1.0" lower="-3.141592" upper="3.141592" />
        <axis xyz="1 0 0" />
    </joint>
	<joint name="jRightBallFoot_roty" type="revolute">
        <origin xyz="0 0 0" rpy="0 0 0"/>
        <parent link="RightToe_f1"/>
        <child link="RightToe_f2"/>
        <dynamics damping="0.1" friction="0.0"/>
        <limit effort="30" velocity="1.0" lower="-3.141592" upper="3.141592" />
        <axis xyz="0 1 0" />
    </joint>
    <joint name="jRightBallFoot_rotz" type="revolute">
        <origin xyz="0 0 0" rpy="0 0 0"/>
        <parent link="RightToe_f2"/>
        <child link="RightToe"/>
        <dynamics damping="0.1" friction="0.0"/>
        <limit effort="30" velocity="1.0" lower="-3.141592" upper="3.141592" />
        <axis xyz="0 0 1" />
    </joint>
	<!--Chain from (20) to (23)-->
	<joint name="jLeftHip_rotx" type="revolute">
        <origin xyz="-8e-06    0.080069    -7.4e-05" rpy="0 0 0"/>
        <parent link="Pelvis"/>
        <child link="LeftUpperLeg_f1"/>
        <dynamics damping="0.1" friction="0.0"/>
        <limit effort="30" velocity="1.0" lower="-3.141592" upper="3.141592" />
        <axis xyz="1 0 0" />
    </joint>
	<joint name="jLeftHip_roty" type="revolute">
        <origin xyz="0 0 0" rpy="0 0 0"/>
        <parent link="LeftUpperLeg_f1"/>
        <child link="LeftUpperLeg_f2"/>
        <dynamics damping="0.1" friction="0.0"/>
        <limit effort="30" velocity="1.0" lower="-3.141592" upper="3.141592" />
        <axis xyz="0 1 0" />
    </joint>
    <joint name="jLeftHip_rotz" type="revolute">
        <origin xyz="0 0 0" rpy="0 0 0"/>
        <parent link="LeftUpperLeg_f2"/>
        <child link="LeftUpperLeg"/>
        <dynamics damping="0.1" friction="0.0"/>
        <limit effort="30" velocity="1.0" lower="-3.141592" upper="3.141592" />
        <axis xyz="0 0 1" />
    </joint>
	<joint name="jLeftKnee_rotx" type="revolute">
        <origin xyz="8e-06           0    -0.42004" rpy="0 0 0"/>
        <parent link="LeftUpperLeg"/>
        <child link="LeftLowerLeg_f1"/>
        <dynamics damping="0.1" friction="0.0"/>
        <limit effort="30" velocity="1.0" lower="-3.141592" upper="3.141592" />
        <axis xyz="1 0 0" />
    </joint>
	<joint name="jLeftKnee_roty" type="revolute">
        <origin xyz="0 0 0" rpy="0 0 0"/>
        <parent link="LeftLowerLeg_f1"/>
        <child link="LeftLowerLeg_f2"/>
        <dynamics damping="0.1" friction="0.0"/>
        <limit effort="30" velocity="1.0" lower="-3.141592" upper="3.141592" />
        <axis xyz="0 1 0" />
    </joint>
    <joint name="jLeftKnee_rotz" type="revolute">
        <origin xyz="0 0 0" rpy="0 0 0"/>
        <parent link="LeftLowerLeg_f2"/>
        <child link="LeftLowerLeg"/>
        <dynamics damping="0.1" friction="0.0"/>
        <limit effort="30" velocity="1.0" lower="-3.141592" upper="3.141592" />
        <axis xyz="0 0 1" />
    </joint>
	<joint name="jLeftAnkle_rotx" type="revolute">
        <origin xyz="0.00046           0    -0.40734" rpy="0 0 0"/>
        <parent link="LeftLowerLeg"/>
        <child link="LeftFoot_f1"/>
        <dynamics damping="0.1" friction="0.0"/>
        <limit effort="30" velocity="1.0" lower="-3.141592" upper="3.141592" />
        <axis xyz="1 0 0" />
    </joint>
	<joint name="jLeftAnkle_roty" type="revolute">
        <origin xyz="0 0 0" rpy="0 0 0"/>
        <parent link="LeftFoot_f1"/>
        <child link="LeftFoot_f2"/>
        <dynamics damping="0.1" friction="0.0"/>
        <limit effort="30" velocity="1.0" lower="-3.141592" upper="3.141592" />
        <axis xyz="0 1 0" />
    </joint>
    <joint name="jLeftAnkle_rotz" type="revolute">
        <origin xyz="0 0 0" rpy="0 0 0"/>
        <parent link="LeftFoot_f2"/>
        <child link="LeftFoot"/>
        <dynamics damping="0.1" friction="0.0"/>
        <limit effort="30" velocity="1.0" lower="-3.141592" upper="3.141592" />
        <axis xyz="0 0 1" />
    </joint>
	<joint name="jLeftBallFoot_rotx" type="revolute">
        <origin xyz="0.15263           0   -0.088953" rpy="0 0 0"/>
        <parent link="LeftFoot"/>
        <child link="LeftToe_f1"/>
        <dynamics damping="0.1" friction="0.0"/>
        <limit effort="30" velocity="1.0" lower="-3.141592" upper="3.141592" />
        <axis xyz="1 0 0" />
    </joint>
	<joint name="jLeftBallFoot_roty" type="revolute">
        <origin xyz="0 0 0" rpy="0 0 0"/>
        <parent link="LeftToe_f1"/>
        <child link="LeftToe_f2"/>
        <dynamics damping="0.1" friction="0.0"/>
        <limit effort="30" velocity="1.0" lower="-3.141592" upper="3.141592" />
        <axis xyz="0 1 0" />
    </joint>
    <joint name="jLeftBallFoot_rotz" type="revolute">
        <origin xyz="0 0 0" rpy="0 0 0"/>
        <parent link="LeftToe_f2"/>
        <child link="LeftToe"/>
        <dynamics damping="0.1" friction="0.0"/>
        <limit effort="30" velocity="1.0" lower="-3.141592" upper="3.141592" />
        <axis xyz="0 0 1" />
    </joint>

	<!-- Sensor  1-->
<sensor name="Pelvis_gyro" type="gyroscope">
<parent link="Pelvis"/>
<origin xyz="-0.055881  0.00020678    0.095148" rpy="0.094617      1.0086     -3.0304"/>
</sensor>
<sensor name="Pelvis_accelerometer" type="accelerometer">
<parent link="Pelvis"/>
<origin xyz="-0.055881  0.00020678    0.095148" rpy="0.094617      1.0086     -3.0304"/>
</sensor>
<!-- Sensor  2-->
<sensor name="T8_gyro" type="gyroscope">
<parent link="T8"/>
<origin xyz="0.14068  6.2838e-06    0.077433" rpy="-0.077161      1.1064    -0.17687"/>
</sensor>
<sensor name="T8_accelerometer" type="accelerometer">
<parent link="T8"/>
<origin xyz="0.14068  6.2838e-06    0.077433" rpy="-0.077161      1.1064    -0.17687"/>
</sensor>
<!-- Sensor  3-->
<sensor name="Head_gyro" type="gyroscope">
<parent link="Head"/>
<origin xyz="-0.06975 -2.1628e-05    0.076683" rpy="2.3836  -0.0032688     -1.7942"/>
</sensor>
<sensor name="Head_accelerometer" type="accelerometer">
<parent link="Head"/>
<origin xyz="-0.06975 -2.1628e-05    0.076683" rpy="2.3836  -0.0032688     -1.7942"/>
</sensor>
<!-- Sensor  4-->
<sensor name="RightShoulder_gyro" type="gyroscope">
<parent link="RightShoulder"/>
<origin xyz="-0.020002   -0.049977   -0.059953" rpy="1.0711    -0.16714    -0.95844"/>
</sensor>
<sensor name="RightShoulder_accelerometer" type="accelerometer">
<parent link="RightShoulder"/>
<origin xyz="-0.020002   -0.049977   -0.059953" rpy="1.0711    -0.16714    -0.95844"/>
</sensor>
<!-- Sensor  5-->
<sensor name="RightUpperArm_gyro" type="gyroscope">
<parent link="RightUpperArm"/>
<origin xyz="-0.020047   -0.099952    0.019983" rpy="-0.10514    0.025819     -1.5224"/>
</sensor>
<sensor name="RightUpperArm_accelerometer" type="accelerometer">
<parent link="RightUpperArm"/>
<origin xyz="-0.020047   -0.099952    0.019983" rpy="-0.10514    0.025819     -1.5224"/>
</sensor>
<!-- Sensor  6-->
<sensor name="RightForeArm_gyro" type="gyroscope">
<parent link="RightForeArm"/>
<origin xyz="0.0018328    -0.20024    0.019978" rpy="-0.41688   -0.021387     -1.2563"/>
</sensor>
<sensor name="RightForeArm_accelerometer" type="accelerometer">
<parent link="RightForeArm"/>
<origin xyz="0.0018328    -0.20024    0.019978" rpy="-0.41688   -0.021387     -1.2563"/>
</sensor>
<!-- Sensor  7-->
<sensor name="RightHand_gyro" type="gyroscope">
<parent link="RightHand"/>
<origin xyz="-7.5053e-06   -0.054958    0.020014" rpy="-0.37028    0.088894     -1.5331"/>
</sensor>
<sensor name="RightHand_accelerometer" type="accelerometer">
<parent link="RightHand"/>
<origin xyz="-7.5053e-06   -0.054958    0.020014" rpy="-0.37028    0.088894     -1.5331"/>
</sensor>
<!-- Sensor  8-->
<sensor name="LeftShoulder_gyro" type="gyroscope">
<parent link="LeftShoulder"/>
<origin xyz="-0.019992    0.049973    -0.05994" rpy="-1.0318    -0.19235      1.1962"/>
</sensor>
<sensor name="LeftShoulder_accelerometer" type="accelerometer">
<parent link="LeftShoulder"/>
<origin xyz="-0.019992    0.049973    -0.05994" rpy="-1.0318    -0.19235      1.1962"/>
</sensor>
<!-- Sensor  9-->
<sensor name="LeftUpperArm_gyro" type="gyroscope">
<parent link="LeftUpperArm"/>
<origin xyz="-0.020025    0.099939    0.019989" rpy="0.064789   -0.084026      1.4526"/>
</sensor>
<sensor name="LeftUpperArm_accelerometer" type="accelerometer">
<parent link="LeftUpperArm"/>
<origin xyz="-0.020025    0.099939    0.019989" rpy="0.064789   -0.084026      1.4526"/>
</sensor>
<!-- Sensor  10-->
<sensor name="LeftForeArm_gyro" type="gyroscope">
<parent link="LeftForeArm"/>
<origin xyz="0.0017837     0.20024    0.020006" rpy="0.72472      0.1279      1.0326"/>
</sensor>
<sensor name="LeftForeArm_accelerometer" type="accelerometer">
<parent link="LeftForeArm"/>
<origin xyz="0.0017837     0.20024    0.020006" rpy="0.72472      0.1279      1.0326"/>
</sensor>
<!-- Sensor  11-->
<sensor name="LeftHand_gyro" type="gyroscope">
<parent link="LeftHand"/>
<origin xyz="-3.1578e-05    0.054994    0.019979" rpy="-0.88757   0.0059868      1.7618"/>
</sensor>
<sensor name="LeftHand_accelerometer" type="accelerometer">
<parent link="LeftHand"/>
<origin xyz="-3.1578e-05    0.054994    0.019979" rpy="-0.88757   0.0059868      1.7618"/>
</sensor>
<!-- Sensor  12-->
<sensor name="RightUpperLeg_gyro" type="gyroscope">
<parent link="RightUpperLeg"/>
<origin xyz="0.013338   -0.044248    -0.25239" rpy="-3.0702      1.3416      1.8771"/>
</sensor>
<sensor name="RightUpperLeg_accelerometer" type="accelerometer">
<parent link="RightUpperLeg"/>
<origin xyz="0.013338   -0.044248    -0.25239" rpy="-3.0702      1.3416      1.8771"/>
</sensor>
<!-- Sensor  13-->
<sensor name="RightLowerLeg_gyro" type="gyroscope">
<parent link="RightLowerLeg"/>
<origin xyz="0.031063   0.0066293    -0.13321" rpy="-3.0874      1.4644     -2.7215"/>
</sensor>
<sensor name="RightLowerLeg_accelerometer" type="accelerometer">
<parent link="RightLowerLeg"/>
<origin xyz="0.031063   0.0066293    -0.13321" rpy="-3.0874      1.4644     -2.7215"/>
</sensor>
<!-- Sensor  14-->
<sensor name="RightFoot_gyro" type="gyroscope">
<parent link="RightFoot"/>
<origin xyz="0.089471   0.0011861   -0.012554" rpy="-0.07906     0.83912    -0.38361"/>
</sensor>
<sensor name="RightFoot_accelerometer" type="accelerometer">
<parent link="RightFoot"/>
<origin xyz="0.089471   0.0011861   -0.012554" rpy="-0.07906     0.83912    -0.38361"/>
</sensor>
<!-- Sensor  15-->
<sensor name="LeftUpperLeg_gyro" type="gyroscope">
<parent link="LeftUpperLeg"/>
<origin xyz="0.01207    0.043037    -0.25269" rpy="-3.11      1.3262    -0.93453"/>
</sensor>
<sensor name="LeftUpperLeg_accelerometer" type="accelerometer">
<parent link="LeftUpperLeg"/>
<origin xyz="0.01207    0.043037    -0.25269" rpy="-3.11      1.3262    -0.93453"/>
</sensor>
<!-- Sensor  16-->
<sensor name="LeftLowerLeg_gyro" type="gyroscope">
<parent link="LeftLowerLeg"/>
<origin xyz="0.030962  -0.0070902    -0.13319" rpy="-2.05      1.5347     -2.3088"/>
</sensor>
<sensor name="LeftLowerLeg_accelerometer" type="accelerometer">
<parent link="LeftLowerLeg"/>
<origin xyz="0.030962  -0.0070902    -0.13319" rpy="-2.05      1.5347     -2.3088"/>
</sensor>
<!-- Sensor  17-->
<sensor name="LeftFoot_gyro" type="gyroscope">
<parent link="LeftFoot"/>
<origin xyz="0.089484  -0.0013526   -0.012584" rpy="-0.35797     0.75899     0.20577"/>
</sensor>
<sensor name="LeftFoot_accelerometer" type="accelerometer">
<parent link="LeftFoot"/>
<origin xyz="0.089484  -0.0013526   -0.012584" rpy="-0.35797     0.75899     0.20577"/>
</sensor>


</robot>
