<robot name="XSensStyleModel_template">
<!--To open this model with Gazebo replace the null masses, inertias and dimensions of the 'fake links f1 and f2'-->
    <!--LINKS-->
	<!--Link base (1)-->
	<link name="Pelvis">
        <inertial>
            <mass value="4.88"/>
			<!--COM origin wrt pHipOrigin-->
            <origin xyz="0           0    0.050194" rpy="0 0 0" />
            <inertia ixx="0.029296" iyy="0.011839" izz="0.033081" ixy="0" ixz="0" iyz="0"/>
        </inertial>

        <visual>
			<!--box origin wrt pHipOrigin-->
            <origin xyz="0           0    0.050194" rpy="0 0 0" />
            <geometry>
                <box size="0.1386     0.24927    0.099515"/>
            </geometry>
        </visual>

        <collision>
			<!--box origin wrt pHipOrigin-->
            <origin xyz="0           0    0.050194" rpy="0 0 0" />
            <geometry>
                <box size="0.1386     0.24927    0.099515"/>
            </geometry>
        </collision>

    </link>
    <!--Chain from (2) to (7)-->
	<link name="L5_f1">
        <inertial>
            <mass value="0"/>
            <origin xyz="0 0 0" rpy="0 0 0" />
            <inertia ixx="0" iyy="0" izz="0" ixy="0" ixz="0" iyz="0"/>
        </inertial>
    </link>
	<link name="L5_f2">
        <inertial>
            <mass value="0"/>
            <origin xyz="0 0 0" rpy="0 0 0" />
            <inertia ixx="0" iyy="0" izz="0" ixy="0" ixz="0" iyz="0"/>
        </inertial>
    </link>
	<link name="L5">
        <inertial>
            <mass value="6.222"/>
			<!--COM origin wrt jL5S1-->
            <origin xyz="0           0     0.04987" rpy="0 0 0" />
            <inertia ixx="0.019063" iyy="0.015119" izz="0.0002671" ixy="0" ixz="0" iyz="0"/>
        </inertial>

        <visual>
			<!--box origin origin wrt jL5S1-->
            <origin xyz="0           0     0.04987" rpy="0 0 0" />
            <geometry>
                <box size="0.1386     0.16376    0.099741"/>
            </geometry>
        </visual>

        <collision>
			<!--box origin origin wrt jL5S1-->
            <origin xyz="0           0     0.04987" rpy="0 0 0" />
            <geometry>
                <box size="0.1386     0.16376    0.099741"/>
            </geometry>
        </collision>
    </link>
	<link name="L3_f1">
        <inertial>
            <mass value="0"/>
            <origin xyz="0 0 0" rpy="0 0 0" />
            <inertia ixx="0" iyy="0" izz="0" ixy="0" ixz="0" iyz="0"/>
        </inertial>
    </link>
	<link name="L3_f2">
        <inertial>
            <mass value="0"/>
            <origin xyz="0 0 0" rpy="0 0 0" />
            <inertia ixx="0" iyy="0" izz="0" ixy="0" ixz="0" iyz="0"/>
        </inertial>
    </link>
	<link name="L3">
        <inertial>
            <mass value="6.222"/>
			<!--COM origin wrt jL4L3-->
            <origin xyz="0           0    0.045056" rpy="0 0 0" />
            <inertia ixx="0.018115" iyy="0.014171" izz="0.023865" ixy="0" ixz="0" iyz="0"/>
        </inertial>

        <visual>
			<!--box origin origin wrt jL4L3-->
            <origin xyz="0           0    0.045056" rpy="0 0 0" />
            <geometry>
                <box size="0.1386     0.16376    0.090113"/>
            </geometry>
        </visual>

        <collision>
			<!--box origin origin wrt jL4L3-->
            <origin xyz="0           0    0.045056" rpy="0 0 0" />
            <geometry>
                <box size="0.1386     0.16376    0.090113"/>
            </geometry>
        </collision>
    </link>
	<link name="T12_f1">
        <inertial>
            <mass value="0"/>
            <origin xyz="0 0 0" rpy="0 0 0" />
            <inertia ixx="0" iyy="0" izz="0" ixy="0" ixz="0" iyz="0"/>
        </inertial>
    </link>
	<link name="T12_f2">
        <inertial>
            <mass value="0"/>
            <origin xyz="0 0 0" rpy="0 0 0" />
            <inertia ixx="0" iyy="0" izz="0" ixy="0" ixz="0" iyz="0"/>
        </inertial>
    </link>
	<link name="T12">
        <inertial>
            <mass value="6.222"/>
			<!--COM origin wrt jL1T12-->
            <origin xyz="0           0    0.045056" rpy="0 0 0" />
            <inertia ixx="0.018115" iyy="0.014171" izz="0.023865" ixy="0" ixz="0" iyz="0"/>
        </inertial>

        <visual>
			<!--box origin origin wrt jL1T12-->
            <origin xyz="0           0    0.045056" rpy="0 0 0" />
            <geometry>
                <box size="0.1386     0.16376    0.090113"/>
            </geometry>
        </visual>

        <collision>
			<!--box origin origin wrt jL1T12-->
            <origin xyz="0           0    0.045056" rpy="0 0 0" />
            <geometry>
                <box size="0.1386     0.16376    0.090113"/>
            </geometry>
        </collision>
    </link>
	<link name="T8_f1">
        <inertial>
            <mass value="0"/>
            <origin xyz="0 0 0" rpy="0 0 0" />
            <inertia ixx="0" iyy="0" izz="0" ixy="0" ixz="0" iyz="0"/>
        </inertial>
    </link>
	<link name="T8_f2">
        <inertial>
            <mass value="0"/>
            <origin xyz="0 0 0" rpy="0 0 0" />
            <inertia ixx="0" iyy="0" izz="0" ixy="0" ixz="0" iyz="0"/>
        </inertial>
    </link>
	<link name="T8">
        <inertial>
            <mass value="2.44"/>
			<!--COM origin wrt jT9T8-->
            <origin xyz="0           0    0.062925" rpy="0 0 0" />
            <inertia ixx="0.0038182" iyy="0.007132" izz="0.0045093" ixy="0" ixz="0" iyz="0"/>
        </inertial>

        <visual>
			<!--box origin wrt jT9T8-->
            <origin xyz="0           0    0.062925" rpy="0 0 0" />
            <geometry>
                <box size="0.1387    0.054218     0.12585"/>
            </geometry>
        </visual>

        <collision>
			<!--box origin wrt jT9T8-->
            <origin xyz="0           0    0.062925" rpy="0 0 0" />
            <geometry>
                <box size="0.1387    0.054218     0.12585"/>
            </geometry>
        </collision>

    </link>
	<link name="Neck_f1">
        <inertial>
            <mass value="0"/>
            <origin xyz="0 0 0" rpy="0 0 0" />
            <inertia ixx="0" iyy="0" izz="0" ixy="0" ixz="0" iyz="0"/>
        </inertial>
    </link>
	<link name="Neck_f2">
        <inertial>
            <mass value="0"/>
            <origin xyz="0 0 0" rpy="0 0 0" />
            <inertia ixx="0" iyy="0" izz="0" ixy="0" ixz="0" iyz="0"/>
        </inertial>
    </link>
	<link name="Neck">
        <inertial>
            <mass value="0.732"/>
			<!--COM origin wrt jT1C7-->
            <origin xyz="0           0    0.041973" rpy="0 0 0" />
            <inertia ixx="0.00056618" iyy="0.00056618" izz="0.00027264" ixy="0" ixz="0" iyz="0"/>
        </inertial>

        <visual>
			<!--box origin wrt jT1C7-->
            <origin xyz="0           0    0.041973" rpy="0 0 0" />
            <geometry>
		<cylinder length="0.083946" radius="0.013647"/>
            </geometry>
        </visual>

        <collision>
			<!--box origin wrt jT1C7-->
            <origin xyz="0           0    0.041973" rpy="0 0 0" />
            <geometry>
                <cylinder length="0.083946" radius="0.013647"/>
            </geometry>
        </collision>
    </link>
	<link name="Head_f1">
        <inertial>
            <mass value="0"/>
            <origin xyz="0 0 0" rpy="0 0 0" />
            <inertia ixx="0" iyy="0" izz="0" ixy="0" ixz="0" iyz="0"/>
        </inertial>
    </link>
	<link name="Head_f2">
        <inertial>
            <mass value="0"/>
            <origin xyz="0 0 0" rpy="0 0 0" />
            <inertia ixx="0" iyy="0" izz="0" ixy="0" ixz="0" iyz="0"/>
        </inertial>
    </link>
	<link name="Head">
        <inertial>
            <mass value="2.196"/>
			<!--COM origin wrt jC1Head-->
            <origin xyz="0           0    0.079896" rpy="0 0 0" />
            <inertia ixx="0.0056072" iyy="0.0056072" izz="0.0056072" ixy="0" ixz="0" iyz="0"/>
        </inertial>

        <visual>
			<!--boc origin wrt jC1Head-->
            <origin xyz="0           0    0.079896" rpy="0 0 0" />
            <geometry>
                <sphere radius="0.079896"/>
            </geometry>
        </visual>

        <collision>
			<!--box origin wrt jC1Head-->
            <origin xyz="0           0    0.079896" rpy="0 0 0" />
            <geometry>
                <sphere radius="0.079896"/>
            </geometry>
        </collision>

    </link>
	<!--Chain from (8) to (11)-->
	<link name="RightShoulder_f1">
        <inertial>
            <mass value="0"/>
            <origin xyz="0 0 0" rpy="0 0 0" />
            <inertia ixx="0" iyy="0" izz="0" ixy="0" ixz="0" iyz="0"/>
        </inertial>
    </link>
	<link name="RightShoulder_f2">
        <inertial>
            <mass value="0"/>
            <origin xyz="0 0 0" rpy="0 0 0" />
            <inertia ixx="0" iyy="0" izz="0" ixy="0" ixz="0" iyz="0"/>
        </inertial>
    </link>
	<link name="RightShoulder">
        <inertial>
            <mass value="1.891"/>
			<!--COM origin wrt jRightC7Shoulder-->
            <origin xyz="0   -0.064947           0" rpy="0 0 0" />
            <inertia ixx="0.0029192" iyy="0.00052075" izz="0.0029192" ixy="0" ixz="0" iyz="0"/>
        </inertial>

        <visual>
			<!--box origin wrt jRightC7Shoulder. RPY rotated of pi/2.-->
            <origin xyz="0   -0.064947           0" rpy="1.5708 0 0" />
            <geometry>
                <cylinder length="0.12989" radius="0.023468"/>
            </geometry>
        </visual>

        <collision>
			<!--box origin wrt jRightC7Shoulder. RPY rotated of pi/2.-->
            <origin xyz="0   -0.064947           0" rpy="1.5708 0 0" />
            <geometry>
                <cylinder length="0.12989" radius="0.023468"/>
            </geometry>
        </collision>

    </link>
	<link name="RightUpperArm_f1">
        <inertial>
            <mass value="0"/>
            <origin xyz="0 0 0" rpy="0 0 0" />
            <inertia ixx="0" iyy="0" izz="0" ixy="0" ixz="0" iyz="0"/>
        </inertial>
    </link>
	<link name="RightUpperArm_f2">
        <inertial>
            <mass value="0"/>
            <origin xyz="0 0 0" rpy="0 0 0" />
            <inertia ixx="0" iyy="0" izz="0" ixy="0" ixz="0" iyz="0"/>
        </inertial>
    </link>
    <link name="RightUpperArm">
        <inertial>
            <mass value="1.83"/>
			<!--COM origin wrt jRightShoulder-->
            <origin xyz="0    -0.13498           0" rpy="0 0 0" />
            <inertia ixx="0.01151" iyy="0.00079302" izz="0.01151" ixy="0" ixz="0" iyz="0"/>
        </inertial>

        <visual>
			<!--box origin wrt jRightShoulder. RPY rotated of pi/2.-->
            <origin xyz="0    -0.13498           0" rpy="1.5708 0 0" />
            <geometry>
                <cylinder length="0.26995" radius="0.02944"/>
            </geometry>
        </visual>

        <collision>
			<!--box origin wrt jRightShoulder. RPY rotated of pi/2.-->
            <origin xyz="0    -0.13498           0" rpy="1.5708 0 0" />
            <geometry>
                <cylinder length="0.26995" radius="0.02944"/>
            </geometry>
        </collision>

    </link>
	<link name="RightForeArm_f1">
        <inertial>
            <mass value="0"/>
            <origin xyz="0 0 0" rpy="0 0 0" />
            <inertia ixx="0" iyy="0" izz="0" ixy="0" ixz="0" iyz="0"/>
        </inertial>
    </link>
	<link name="RightForeArm_f2">
        <inertial>
            <mass value="0"/>
            <origin xyz="0 0 0" rpy="0 0 0" />
            <inertia ixx="0" iyy="0" izz="0" ixy="0" ixz="0" iyz="0"/>
        </inertial>
    </link>
	<link name="RightForeArm">
        <inertial>
            <mass value="1.22"/>
			<!--COM origin wrt jRightElbow-->
            <origin xyz="0    -0.11119           0" rpy="0 0 0" />
            <inertia ixx="0.0051448" iyy="0.00023497" izz="0.0051448" ixy="0" ixz="0" iyz="0"/>
        </inertial>

        <visual>
			<!--box origin wrt jRightElbow. RPY rotated of pi/2.-->
            <origin xyz="0    -0.11119           0" rpy="1.5708 0 0" />
            <geometry>
                <cylinder length="0.22237" radius="0.019626"/>
            </geometry>
        </visual>

        <collision>
			<!--box origin wrt jRightElbow. RPY rotated of pi/2.-->
            <origin xyz="0    -0.11119           0" rpy="1.5708 0 0" />
            <geometry>
                <cylinder length="0.22237" radius="0.019626"/>
            </geometry>
        </collision>

    </link>
	<link name="RightHand_f1">
        <inertial>
            <mass value="0"/>
            <origin xyz="0 0 0" rpy="0 0 0" />
            <inertia ixx="0" iyy="0" izz="0" ixy="0" ixz="0" iyz="0"/>
        </inertial>
    </link>
	<link name="RightHand_f2">
        <inertial>
            <mass value="0"/>
            <origin xyz="0 0 0" rpy="0 0 0" />
            <inertia ixx="0" iyy="0" izz="0" ixy="0" ixz="0" iyz="0"/>
        </inertial>
    </link>
	<link name="RightHand">
        <inertial>
            <mass value="0.366"/>
			<!--COM origin wrt jRightWrist-->
            <origin xyz="0   -0.083494           0" rpy="0 0 0" />
            <inertia ixx="0.0008975" iyy="0.00042499" izz="0.0012285" ixy="0" ixz="0" iyz="0"/>
        </inertial>

        <visual>
			<!--box origin wrt jRightWrist-->
            <origin xyz="0   -0.083494           0" rpy="0 0 0" />
            <geometry>
                <box size="0.11133     0.16699    0.039253"/>
            </geometry>
        </visual>

        <collision>
			<!--box origin wrt jRightWrist-->
            <origin xyz="0   -0.083494           0" rpy="0 0 0" />
            <geometry>
                <box size="0.11133     0.16699    0.039253"/>
            </geometry>
        </collision>

    </link>
	<!--Chain from (12) to (15)-->
	<link name="LeftShoulder_f1">
        <inertial>
            <mass value="0"/>
            <origin xyz="0 0 0" rpy="0 0 0" />
            <inertia ixx="0" iyy="0" izz="0" ixy="0" ixz="0" iyz="0"/>
        </inertial>
    </link>
	<link name="LeftShoulder_f2">
        <inertial>
            <mass value="0"/>
            <origin xyz="0 0 0" rpy="0 0 0" />
            <inertia ixx="0" iyy="0" izz="0" ixy="0" ixz="0" iyz="0"/>
        </inertial>
    </link>
	<link name="LeftShoulder">
        <inertial>
            <mass value="1.891"/>
			<!--COM origin wrt jLeftC7Shoulder-->
            <origin xyz="0    0.064947           0" rpy="0 0 0" />
            <inertia ixx="0.0029192" iyy="0.00052075" izz="0.0029192" ixy="0" ixz="0" iyz="0"/>
        </inertial>

        <visual>
			<!--box origin wrt jLeftC7Shoulder. RPY rotated of pi/2.-->
            <origin xyz="0    0.064947           0" rpy="1.5708 0 0" />
            <geometry>
                <cylinder length="0.12989" radius="0.023468"/>
            </geometry>
        </visual>

        <collision>
			<!--box origin wrt jLeftC7Shoulder. RPY rotated of pi/2.-->
            <origin xyz="0    0.064947           0" rpy="1.5708 0 0" />
            <geometry>
                <cylinder length="0.12989" radius="0.023468"/>
            </geometry>
        </collision>

    </link>
	<link name="LeftUpperArm_f1">
        <inertial>
            <mass value="0"/>
            <origin xyz="0 0 0" rpy="0 0 0" />
            <inertia ixx="0" iyy="0" izz="0" ixy="0" ixz="0" iyz="0"/>
        </inertial>
    </link>
	<link name="LeftUpperArm_f2">
        <inertial>
            <mass value="0"/>
            <origin xyz="0 0 0" rpy="0 0 0" />
            <inertia ixx="0" iyy="0" izz="0" ixy="0" ixz="0" iyz="0"/>
        </inertial>
    </link>
	<link name="LeftUpperArm">
        <inertial>
            <mass value="1.83"/>
			<!--COM origin wrt jLeftShoulder-->
            <origin xyz="0     0.13498           0" rpy="0 0 0" />
            <inertia ixx="0.01151" iyy="0.00079302" izz="0.01151" ixy="0" ixz="0" iyz="0"/>
        </inertial>

        <visual>
			<!--box origin wrt jLeftShoulder. RPY rotated of pi/2.-->
            <origin xyz="0     0.13498           0" rpy="1.5708 0 0" />
            <geometry>
                <cylinder length="0.26995" radius="0.02944"/>
            </geometry>
        </visual>

        <collision>
			<!--box origin wrt jLeftShoulder. RPY rotated of pi/2.-->
            <origin xyz="0     0.13498           0" rpy="1.5708 0 0" />
            <geometry>
                <cylinder length="0.26995" radius="0.02944"/>
            </geometry>
        </collision>

    </link>
	<link name="LeftForeArm_f1">
        <inertial>
            <mass value="0"/>
            <origin xyz="0 0 0" rpy="0 0 0" />
            <inertia ixx="0" iyy="0" izz="0" ixy="0" ixz="0" iyz="0"/>
        </inertial>
    </link>
	<link name="LeftForeArm_f2">
        <inertial>
            <mass value="0"/>
            <origin xyz="0 0 0" rpy="0 0 0" />
            <inertia ixx="0" iyy="0" izz="0" ixy="0" ixz="0" iyz="0"/>
        </inertial>
    </link>
	<link name="LeftForeArm">
        <inertial>
            <mass value="1.22"/>
			<!--COM origin wrt jLeftElbow-->
            <origin xyz="0     0.11119           0" rpy="0 0 0" />
            <inertia ixx="0.0051448" iyy="0.00023497" izz="0.0051448" ixy="0" ixz="0" iyz="0"/>
        </inertial>

        <visual>
			<!--box origin wrt jLeftElbow. RPY rotated of pi/2.-->
            <origin xyz="0     0.11119           0" rpy="1.5708 0 0" />
            <geometry>
                <cylinder length="0.22237" radius="0.019626"/>
            </geometry>
        </visual>

        <collision>
			<!--box origin wrt jLeftElbow. RPY rotated of pi/2.-->
            <origin xyz="0     0.11119           0" rpy="1.5708 0 0" />
            <geometry>
                <cylinder length="0.22237" radius="0.019626"/>
            </geometry>
        </collision>

    </link>
	<link name="LeftHand_f1">
        <inertial>
            <mass value="0"/>
            <origin xyz="0 0 0" rpy="0 0 0" />
            <inertia ixx="0" iyy="0" izz="0" ixy="0" ixz="0" iyz="0"/>
        </inertial>
    </link>
	<link name="LeftHand_f2">
        <inertial>
            <mass value="0"/>
            <origin xyz="0 0 0" rpy="0 0 0" />
            <inertia ixx="0" iyy="0" izz="0" ixy="0" ixz="0" iyz="0"/>
        </inertial>
    </link>
	<link name="LeftHand">
        <inertial>
            <mass value="0.366"/>
			<!--COM origin wrt jLeftWrist-->
            <origin xyz="0    0.083494           0" rpy="0 0 0" />
            <inertia ixx="0.0008975" iyy="0.00042499" izz="0.0012285" ixy="0" ixz="0" iyz="0"/>
        </inertial>

        <visual>
			<!--COM origin wrt jLeftWrist-->
            <origin xyz="0    0.083494           0" rpy="0 0 0" />
            <geometry>
                <box size="0.11133     0.16699    0.039253"/>
            </geometry>
        </visual>

        <collision>
			<!--COM origin wrt jLeftWrist-->
            <origin xyz="0    0.083494           0" rpy="0 0 0" />
            <geometry>
                <box size="0.11133     0.16699    0.039253"/>
            </geometry>
        </collision>

    </link>
	<!--Chain from (16) to (19)-->
	<link name="RightUpperLeg_f1">
        <inertial>
            <mass value="0"/>
            <origin xyz="0 0 0" rpy="0 0 0" />
            <inertia ixx="0" iyy="0" izz="0" ixy="0" ixz="0" iyz="0"/>
        </inertial>
    </link>
	<link name="RightUpperLeg_f2">
        <inertial>
            <mass value="0"/>
            <origin xyz="0 0 0" rpy="0 0 0" />
            <inertia ixx="0" iyy="0" izz="0" ixy="0" ixz="0" iyz="0"/>
        </inertial>
    </link>
    <link name="RightUpperLeg">
        <inertial>
            <mass value="7.625"/>
			<!--COM origin wrt jRightHip-->
            <origin xyz="0           0    -0.22557" rpy="0 0 0" />
            <inertia ixx="0.13545" iyy="0.13545" izz="0.012254" ixy="0" ixz="0" iyz="0"/>
        </inertial>

        <visual>
			<!--box origin wrt jRightHip-->
            <origin xyz="0           0    -0.22557" rpy="0 0 0" />
            <geometry>
                <cylinder length="0.45113" radius="0.056694"/>
            </geometry>
        </visual>

        <collision>
			<!--box origin wrt jRightHip-->
            <origin xyz="0           0    -0.22557" rpy="0 0 0" />
            <geometry>
                <cylinder length="0.45113" radius="0.056694"/>
            </geometry>
        </collision>

    </link>
	<link name="RightLowerLeg_f1">
        <inertial>
            <mass value="0"/>
            <origin xyz="0 0 0" rpy="0 0 0" />
            <inertia ixx="0" iyy="0" izz="0" ixy="0" ixz="0" iyz="0"/>
        </inertial>
    </link>
	<link name="RightLowerLeg_f2">
        <inertial>
            <mass value="0"/>
            <origin xyz="0 0 0" rpy="0 0 0" />
            <inertia ixx="0" iyy="0" izz="0" ixy="0" ixz="0" iyz="0"/>
        </inertial>
    </link>
    <link name="RightLowerLeg">
        <inertial>
            <mass value="2.2265"/>
			<!--COM origin wrt jRightKnee-->
            <origin xyz="0           0    -0.20314" rpy="0 0 0" />
            <inertia ixx="0.031404" iyy="0.031404" izz="0.001557" ixy="0" ixz="0" iyz="0"/>
        </inertial>

        <visual>
			<!--box origin wrt jRightKnee-->
            <origin xyz="0           0    -0.20314" rpy="0 0 0" />
            <geometry>
                <cylinder length="0.40628" radius="0.037398"/>
            </geometry>
        </visual>

        <collision>
			<!--box origin wrt jRightKnee-->
            <origin xyz="0           0    -0.20314" rpy="0 0 0" />
            <geometry>
                <cylinder length="0.40628" radius="0.037398"/>
            </geometry>
        </collision>

    </link>
	<link name="RightFoot_f1">
        <inertial>
            <mass value="0"/>
            <origin xyz="0 0 0" rpy="0 0 0" />
            <inertia ixx="0" iyy="0" izz="0" ixy="0" ixz="0" iyz="0"/>
        </inertial>
    </link>
	<link name="RightFoot_f2">
        <inertial>
            <mass value="0"/>
            <origin xyz="0 0 0" rpy="0 0 0" />
            <inertia ixx="0" iyy="0" izz="0" ixy="0" ixz="0" iyz="0"/>
        </inertial>
    </link>
    <link name="RightFoot">
        <inertial>
            <mass value="0.793"/>
			<!--COM origin wrt jRightAnkle-->
            <origin xyz="0.050643           0   -0.061735" rpy="0 0 0" />
            <inertia ixx="0.0013771" iyy="0.00317" izz="0.0025323" ixy="0" ixz="0" iyz="0"/>
        </inertial>

        <visual>
			<!--box origin wrt jRightAnkle-->
	    	<origin xyz="0.050643           0   -0.061735" rpy="0 0 0" />
            <geometry>
                <box size="0.1809    0.074795     0.12347"/>
            </geometry>
        </visual>

        <collision>
			<!--box origin wrt jRightAnkle-->
		    <origin xyz="0.050643           0   -0.061735" rpy="0 0 0" />
	            <geometry>
	                <box size="0.1809    0.074795     0.12347"/>
	            </geometry>
        </collision>

    </link>
	<link name="RightToe_f1">
        <inertial>
            <mass value="0"/>
            <origin xyz="0 0 0" rpy="0 0 0" />
            <inertia ixx="0" iyy="0" izz="0" ixy="0" ixz="0" iyz="0"/>
        </inertial>
    </link>
	<link name="RightToe_f2">
        <inertial>
            <mass value="0"/>
            <origin xyz="0 0 0" rpy="0 0 0" />
            <inertia ixx="0" iyy="0" izz="0" ixy="0" ixz="0" iyz="0"/>
        </inertial>
    </link>
    <link name="RightToe">
        <inertial>
            <mass value="0.0915"/>
			<!--COM origin wrt jRightBallFoot-->
            <origin xyz="0.029551           0           0" rpy="0 0 0" />
            <inertia ixx="4.419e-05" iyy="2.8167e-05" izz="6.929e-05" ixy="0" ixz="0" iyz="0"/>
        </inertial>

        <visual>
			<!--box origin wrt jRightBallFoot-->
            <origin xyz="0.029551           0           0" rpy="0 0 0" />
            <geometry>
                <box size="0.059101    0.074795    0.014183"/>
            </geometry>
        </visual>

        <collision>
			<!--box origin wrt jRightBallFoot-->
            <origin xyz="0.029551           0           0" rpy="0 0 0" />
            <geometry>
                <box size="0.059101    0.074795    0.014183"/>
            </geometry>
        </collision>
    </link>
	<!--Chain from (20) to (23)-->
	<link name="LeftUpperLeg_f1">
        <inertial>
            <mass value="0"/>
            <origin xyz="0 0 0" rpy="0 0 0" />
            <inertia ixx="0" iyy="0" izz="0" ixy="0" ixz="0" iyz="0"/>
        </inertial>
    </link>
	<link name="LeftUpperLeg_f2">
        <inertial>
            <mass value="0"/>
            <origin xyz="0 0 0" rpy="0 0 0" />
            <inertia ixx="0" iyy="0" izz="0" ixy="0" ixz="0" iyz="0"/>
        </inertial>
    </link>
    <link name="LeftUpperLeg">
        <inertial>
            <mass value="7.625"/>
			<!--COM origin wrt jLeftHip-->
            <origin xyz="0           0    -0.22557" rpy="0 0 0" />
            <inertia ixx="0.13545" iyy="0.13545" izz="0.012254" ixy="0" ixz="0" iyz="0"/>
        </inertial>

        <visual>
			<!--box origin wrt jLeftHip-->
            <origin xyz="0           0    -0.22557" rpy="0 0 0" />
            <geometry>
                <cylinder length="0.45113" radius="-0.056694"/>
            </geometry>
        </visual>

        <collision>
			<!--box origin wrt jLeftHip-->
            <origin xyz="0           0    -0.22557" rpy="0 0 0" />
            <geometry>
                <cylinder length="0.45113" radius="-0.056694"/>
            </geometry>
        </collision>

    </link>
	<link name="LeftLowerLeg_f1">
        <inertial>
            <mass value="0"/>
            <origin xyz="0 0 0" rpy="0 0 0" />
            <inertia ixx="0" iyy="0" izz="0" ixy="0" ixz="0" iyz="0"/>
        </inertial>
    </link>
	<link name="LeftLowerLeg_f2">
        <inertial>
            <mass value="0"/>
            <origin xyz="0 0 0" rpy="0 0 0" />
            <inertia ixx="0" iyy="0" izz="0" ixy="0" ixz="0" iyz="0"/>
        </inertial>
    </link>
	<link name="LeftLowerLeg">
        <inertial>
            <mass value="2.2265"/>
			<!--COM origin wrt jLeftKnee-->
            <origin xyz="0           0    -0.20314" rpy="0 0 0" />
            <inertia ixx="0.031404" iyy="0.031404" izz="0.001557" ixy="0" ixz="0" iyz="0"/>
        </inertial>

        <visual>
			<!--box origin wrt jLeftKnee-->
            <origin xyz="0           0    -0.20314" rpy="0 0 0" />
            <geometry>
		<cylinder length="0.40628" radius="0.037398"/>
            </geometry>
        </visual>

        <collision>
			<!--box origin wrt jLeftKnee-->
            <origin xyz="0           0    -0.20314" rpy="0 0 0" />
            <geometry>
		<cylinder length="0.40628" radius="0.037398"/>
            </geometry>
        </collision>

    </link>
	<link name="LeftFoot_f1">
        <inertial>
            <mass value="0"/>
            <origin xyz="0 0 0" rpy="0 0 0" />
            <inertia ixx="0" iyy="0" izz="0" ixy="0" ixz="0" iyz="0"/>
        </inertial>
    </link>
	<link name="LeftFoot_f2">
        <inertial>
            <mass value="0"/>
            <origin xyz="0 0 0" rpy="0 0 0" />
            <inertia ixx="0" iyy="0" izz="0" ixy="0" ixz="0" iyz="0"/>
        </inertial>
    </link>
    <link name="LeftFoot">
        <inertial>
            <mass value="0.793"/>
			<!--COM origin wrt jLeftAnkle-->
            <origin xyz="0.050643           0   -0.061735" rpy="0 0 0" />
            <inertia ixx="0.0013771" iyy="0.00317" izz="0.0025323" ixy="0" ixz="0" iyz="0"/>
        </inertial>

        <visual>
			<!--box origin wrt jLeftAnkle-->
	   	 	<origin xyz="0.050643           0   -0.061735" rpy="0 0 0" />
            <geometry>
                <box size="0.1809    0.074795     0.12347"/>
            </geometry>
        </visual>

        <collision>
			<!--box origin wrt jLeftAnkle-->
		    <origin xyz="0.050643           0   -0.061735" rpy="0 0 0" />
	            <geometry>
	                <box size="0.1809    0.074795     0.12347"/>
	            </geometry>
        </collision>

    </link>
	<link name="LeftToe_f1">
        <inertial>
            <mass value="0"/>
            <origin xyz="0 0 0" rpy="0 0 0" />
            <inertia ixx="0" iyy="0" izz="0" ixy="0" ixz="0" iyz="0"/>
        </inertial>
    </link>
	<link name="LeftToe_f2">
        <inertial>
            <mass value="0"/>
            <origin xyz="0 0 0" rpy="0 0 0" />
            <inertia ixx="0" iyy="0" izz="0" ixy="0" ixz="0" iyz="0"/>
        </inertial>
    </link>
	<link name="LeftToe">
        <inertial>
            <mass value="0.0915"/>
			<!--COM origin wrt jLeftBallFoot-->
            <origin xyz="0.029551           0           0" rpy="0 0 0" />
            <inertia ixx="4.419e-05" iyy="2.8167e-05" izz="6.929e-05" ixy="0" ixz="0" iyz="0"/>
        </inertial>

        <visual>
			<!--box origin wrt jLeftBallFoot-->
            <origin xyz="0.029551           0           0" rpy="0 0 0" />
            <geometry>
                <box size="0.059101    0.074795    0.014183"/>
            </geometry>
        </visual>

        <collision>
			<!--box origin wrt jLeftBallFoot-->
            <origin xyz="0.029551           0           0" rpy="0 0 0" />
            <geometry>
                <box size="0.059101    0.074795    0.014183"/>
            </geometry>
        </collision>
    </link>


	<!--JOINTS-->
	<!--Chain from (2) to (7)-->
	<joint name="jL5S1_rotx" type="revolute">
        <origin xyz="-8.9e-05           0    0.099951" rpy="0 0 0"/>
        <parent link="Pelvis"/>
        <child link="L5_f1"/>
        <dynamics damping="0.1" friction="0.0"/>
        <limit effort="30" velocity="1.0" lower="-10.0" upper="10.0" />
        <axis xyz="1 0 0" />
    </joint>
	<joint name="jL5S1_roty" type="revolute">
        <origin xyz="0 0 0" rpy="0 0 0"/>
        <parent link="L5_f1"/>
        <child link="L5_f2"/>
        <dynamics damping="0.1" friction="0.0"/>
        <limit effort="30" velocity="1.0" lower="-10.0" upper="10.0" />
        <axis xyz="0 1 0" />
    </joint>
    <joint name="jL5S1_rotz" type="revolute">
        <origin xyz="0 0 0" rpy="0 0 0"/>
        <parent link="L5_f2"/>
        <child link="L5"/>
        <dynamics damping="0.1" friction="0.0"/>
        <limit effort="30" velocity="1.0" lower="-10.0" upper="10.0" />
        <axis xyz="0 0 1" />
    </joint>
	<joint name="jL4L3_rotx" type="revolute">
        <origin xyz="0.000162           0    0.099741" rpy="0 0 0"/>
        <parent link="L5"/>
        <child link="L3_f1"/>
        <dynamics damping="0.1" friction="0.0"/>
        <limit effort="30" velocity="1.0" lower="-10.0" upper="10.0" />
        <axis xyz="1 0 0" />
    </joint>
	<joint name="jL4L3_roty" type="revolute">
        <origin xyz="0 0 0" rpy="0 0 0"/>
        <parent link="L3_f1"/>
        <child link="L3_f2"/>
        <dynamics damping="0.1" friction="0.0"/>
        <limit effort="30" velocity="1.0" lower="-10.0" upper="10.0" />
        <axis xyz="0 1 0" />
    </joint>
    <joint name="jL4L3_rotz" type="revolute">
        <origin xyz="0 0 0" rpy="0 0 0"/>
        <parent link="L3_f2"/>
        <child link="L3"/>
        <dynamics damping="0.1" friction="0.0"/>
        <limit effort="30" velocity="1.0" lower="-10.0" upper="10.0" />
        <axis xyz="0 0 1" />
    </joint>
	<joint name="jL1T12_rotx" type="revolute">
        <origin xyz="0           0    0.090113" rpy="0 0 0"/>
        <parent link="L3"/>
        <child link="T12_f1"/>
        <dynamics damping="0.1" friction="0.0"/>
        <limit effort="30" velocity="1.0" lower="-10.0" upper="10.0" />
        <axis xyz="1 0 0" />
    </joint>
	<joint name="jL1T12_roty" type="revolute">
        <origin xyz="0 0 0" rpy="0 0 0"/>
        <parent link="T12_f1"/>
        <child link="T12_f2"/>
        <dynamics damping="0.1" friction="0.0"/>
        <limit effort="30" velocity="1.0" lower="-10.0" upper="10.0" />
        <axis xyz="0 1 0" />
    </joint>
    <joint name="jL1T12_rotz" type="revolute">
        <origin xyz="0 0 0" rpy="0 0 0"/>
        <parent link="T12_f2"/>
        <child link="T12"/>
        <dynamics damping="0.1" friction="0.0"/>
        <limit effort="30" velocity="1.0" lower="-10.0" upper="10.0" />
        <axis xyz="0 0 1" />
    </joint>
	<joint name="jT9T8_rotx" type="revolute">
        <origin xyz="0           0    0.090113" rpy="0 0 0"/>
        <parent link="T12"/>
        <child link="T8_f1"/>
        <dynamics damping="0.1" friction="0.0"/>
        <limit effort="30" velocity="1.0" lower="-10.0" upper="10.0" />
        <axis xyz="1 0 0" />
    </joint>
	<joint name="jT9T8_roty" type="revolute">
        <origin xyz="0 0 0" rpy="0 0 0"/>
        <parent link="T8_f1"/>
        <child link="T8_f2"/>
        <dynamics damping="0.1" friction="0.0"/>
        <limit effort="30" velocity="1.0" lower="-10.0" upper="10.0" />
        <axis xyz="0 1 0" />
    </joint>
    <joint name="jT9T8_rotz" type="revolute">
        <origin xyz="0 0 0" rpy="0 0 0"/>
        <parent link="T8_f2"/>
        <child link="T8"/>
        <dynamics damping="0.1" friction="0.0"/>
        <limit effort="30" velocity="1.0" lower="-10.0" upper="10.0" />
        <axis xyz="0 0 1" />
    </joint>
	<joint name="jT1C7_rotx" type="revolute">
        <origin xyz="0           0     0.12585" rpy="0 0 0"/>
        <parent link="T8"/>
        <child link="Neck_f1"/>
        <dynamics damping="0.1" friction="0.0"/>
        <limit effort="30" velocity="1.0" lower="-10.0" upper="10.0" />
        <axis xyz="1 0 0" />
    </joint>
	<joint name="jT1C7_roty" type="revolute">
        <origin xyz="0 0 0" rpy="0 0 0"/>
        <parent link="Neck_f1"/>
        <child link="Neck_f2"/>
        <dynamics damping="0.1" friction="0.0"/>
        <limit effort="30" velocity="1.0" lower="-10.0" upper="10.0" />
        <axis xyz="0 1 0" />
    </joint>
    <joint name="jT1C7_rotz" type="revolute">
        <origin xyz="0 0 0" rpy="0 0 0"/>
        <parent link="Neck_f2"/>
        <child link="Neck"/>
        <dynamics damping="0.1" friction="0.0"/>
        <limit effort="30" velocity="1.0" lower="-10.0" upper="10.0" />
        <axis xyz="0 0 1" />
    </joint>
	<joint name="jC1Head_rotx" type="revolute">
        <origin xyz="0.000384           0    0.083946" rpy="0 0 0"/>
        <parent link="Neck"/>
        <child link="Head_f1"/>
        <dynamics damping="0.1" friction="0.0"/>
        <limit effort="30" velocity="1.0" lower="-10.0" upper="10.0" />
        <axis xyz="1 0 0" />
    </joint>
	<joint name="jC1Head_roty" type="revolute">
        <origin xyz="0 0 0" rpy="0 0 0"/>
        <parent link="Head_f1"/>
        <child link="Head_f2"/>
        <dynamics damping="0.1" friction="0.0"/>
        <limit effort="30" velocity="1.0" lower="-10.0" upper="10.0" />
        <axis xyz="0 1 0" />
    </joint>
    <joint name="jC1Head_rotz" type="revolute">
        <origin xyz="0 0 0" rpy="0 0 0"/>
        <parent link="Head_f2"/>
        <child link="Head"/>
        <dynamics damping="0.1" friction="0.0"/>
        <limit effort="30" velocity="1.0" lower="-10.0" upper="10.0" />
        <axis xyz="0 0 1" />
    </joint>
	<!--Chain from (8) to (11)-->
	<joint name="jRightC7Shoulder_rotx" type="revolute">
        <origin xyz="0   -0.027109    0.070322" rpy="0 0 0"/>
        <parent link="T8"/>
        <child link="RightShoulder_f1"/>
        <dynamics damping="0.1" friction="0.0"/>
        <limit effort="30" velocity="1.0" lower="-10.0" upper="10.0" />
        <axis xyz="1 0 0" />
    </joint>
	<joint name="jRightC7Shoulder_roty" type="revolute">
        <origin xyz="0 0 0" rpy="0 0 0"/>
        <parent link="RightShoulder_f1"/>
        <child link="RightShoulder_f2"/>
        <dynamics damping="0.1" friction="0.0"/>
        <limit effort="30" velocity="1.0" lower="-10.0" upper="10.0" />
        <axis xyz="0 1 0" />
    </joint>
    <joint name="jRightC7Shoulder_rotz" type="revolute">
        <origin xyz="0 0 0" rpy="0 0 0"/>
        <parent link="RightShoulder_f2"/>
        <child link="RightShoulder"/>
        <dynamics damping="0.1" friction="0.0"/>
        <limit effort="30" velocity="1.0" lower="-10.0" upper="10.0" />
        <axis xyz="0 0 1" />
    </joint>
	<joint name="jRightShoulder_rotx" type="revolute">
        <origin xyz="0    -0.12989           0" rpy="0 0 0"/>
        <parent link="RightShoulder"/>
        <child link="RightUpperArm_f1"/>
        <dynamics damping="0.1" friction="0.0"/>
        <limit effort="30" velocity="1.0" lower="-10.0" upper="10.0" />
        <axis xyz="1 0 0" />
    </joint>
	<joint name="jRightShoulder_roty" type="revolute">
        <origin xyz="0 0 0" rpy="0 0 0"/>
        <parent link="RightUpperArm_f1"/>
        <child link="RightUpperArm_f2"/>
        <dynamics damping="0.1" friction="0.0"/>
        <limit effort="30" velocity="1.0" lower="-10.0" upper="10.0" />
        <axis xyz="0 1 0" />
    </joint>
    <joint name="jRightShoulder_rotz" type="revolute">
        <origin xyz="0 0 0" rpy="0 0 0"/>
        <parent link="RightUpperArm_f2"/>
        <child link="RightUpperArm"/>
        <dynamics damping="0.1" friction="0.0"/>
        <limit effort="30" velocity="1.0" lower="-10.0" upper="10.0" />
        <axis xyz="0 0 1" />
    </joint>
	<joint name="jRightElbow_rotx" type="revolute">
        <origin xyz="0    -0.26995           0" rpy="0 0 0"/>
        <parent link="RightUpperArm"/>
        <child link="RightForeArm_f1"/>
        <dynamics damping="0.1" friction="0.0"/>
        <limit effort="30" velocity="1.0" lower="-10.0" upper="10.0" />
        <axis xyz="1 0 0" />
    </joint>
	<joint name="jRightElbow_roty" type="revolute">
        <origin xyz="0 0 0" rpy="0 0 0"/>
        <parent link="RightForeArm_f1"/>
        <child link="RightForeArm_f2"/>
        <dynamics damping="0.1" friction="0.0"/>
        <limit effort="30" velocity="1.0" lower="-10.0" upper="10.0" />
        <axis xyz="0 1 0" />
    </joint>
    <joint name="jRightElbow_rotz" type="revolute">
        <origin xyz="0 0 0" rpy="0 0 0"/>
        <parent link="RightForeArm_f2"/>
        <child link="RightForeArm"/>
        <dynamics damping="0.1" friction="0.0"/>
        <limit effort="30" velocity="1.0" lower="-10.0" upper="10.0" />
        <axis xyz="0 0 1" />
    </joint>
	<joint name="jRightWrist_rotx" type="revolute">
        <origin xyz="7.3e-05    -0.22237           0" rpy="0 0 0"/>
        <parent link="RightForeArm"/>
        <child link="RightHand_f1"/>
        <dynamics damping="0.1" friction="0.0"/>
        <limit effort="30" velocity="1.0" lower="-10.0" upper="10.0" />
        <axis xyz="1 0 0" />
    </joint>
	<joint name="jRightWrist_roty" type="revolute">
        <origin xyz="0 0 0" rpy="0 0 0"/>
        <parent link="RightHand_f1"/>
        <child link="RightHand_f2"/>
        <dynamics damping="0.1" friction="0.0"/>
        <limit effort="30" velocity="1.0" lower="-10.0" upper="10.0" />
        <axis xyz="0 1 0" />
    </joint>
    <joint name="jRightWrist_rotz" type="revolute">
        <origin xyz="0 0 0" rpy="0 0 0"/>
        <parent link="RightHand_f2"/>
        <child link="RightHand"/>
        <dynamics damping="0.1" friction="0.0"/>
        <limit effort="30" velocity="1.0" lower="-10.0" upper="10.0" />
        <axis xyz="0 0 1" />
    </joint>
	<!--Chain from (12) to (15)-->
	<joint name="jLeftC7Shoulder_rotx" type="revolute">
        <origin xyz="0    0.027109    0.070322" rpy="0 0 0"/>
        <parent link="T8"/>
        <child link="LeftShoulder_f1"/>
        <dynamics damping="0.1" friction="0.0"/>
        <limit effort="30" velocity="1.0" lower="-10.0" upper="10.0" />
        <axis xyz="1 0 0" />
    </joint>
	<joint name="jLeftC7Shoulder_roty" type="revolute">
        <origin xyz="0 0 0" rpy="0 0 0"/>
        <parent link="LeftShoulder_f1"/>
        <child link="LeftShoulder_f2"/>
        <dynamics damping="0.1" friction="0.0"/>
        <limit effort="30" velocity="1.0" lower="-10.0" upper="10.0" />
        <axis xyz="0 1 0" />
    </joint>
    <joint name="jLeftC7Shoulder_rotz" type="revolute">
        <origin xyz="0 0 0" rpy="0 0 0"/>
        <parent link="LeftShoulder_f2"/>
        <child link="LeftShoulder"/>
        <dynamics damping="0.1" friction="0.0"/>
        <limit effort="30" velocity="1.0" lower="-10.0" upper="10.0" />
        <axis xyz="0 0 1" />
    </joint>
	<joint name="jLeftShoulder_rotx" type="revolute">
        <origin xyz="0     0.12989           0" rpy="0 0 0"/>
        <parent link="LeftShoulder"/>
        <child link="LeftUpperArm_f1"/>
        <dynamics damping="0.1" friction="0.0"/>
        <limit effort="30" velocity="1.0" lower="-10.0" upper="10.0" />
        <axis xyz="1 0 0" />
    </joint>
	<joint name="jLeftShoulder_roty" type="revolute">
        <origin xyz="0 0 0" rpy="0 0 0"/>
        <parent link="LeftUpperArm_f1"/>
        <child link="LeftUpperArm_f2"/>
        <dynamics damping="0.1" friction="0.0"/>
        <limit effort="30" velocity="1.0" lower="-10.0" upper="10.0" />
        <axis xyz="0 1 0" />
    </joint>
    <joint name="jLeftShoulder_rotz" type="revolute">
        <origin xyz="0 0 0" rpy="0 0 0"/>
        <parent link="LeftUpperArm_f2"/>
        <child link="LeftUpperArm"/>
        <dynamics damping="0.1" friction="0.0"/>
        <limit effort="30" velocity="1.0" lower="-10.0" upper="10.0" />
        <axis xyz="0 0 1" />
    </joint>
    <joint name="jLeftElbow_rotx" type="revolute">
        <origin xyz="0     0.26995           0" rpy="0 0 0"/>
        <parent link="LeftUpperArm"/>
        <child link="LeftForeArm_f1"/>
        <dynamics damping="0.1" friction="0.0"/>
        <limit effort="30" velocity="1.0" lower="-10.0" upper="10.0" />
        <axis xyz="1 0 0" />
    </joint>
	<joint name="jLeftElbow_roty" type="revolute">
        <origin xyz="0 0 0" rpy="0 0 0"/>
        <parent link="LeftForeArm_f1"/>
        <child link="LeftForeArm_f2"/>
        <dynamics damping="0.1" friction="0.0"/>
        <limit effort="30" velocity="1.0" lower="-10.0" upper="10.0" />
        <axis xyz="0 1 0" />
    </joint>
    <joint name="jLeftElbow_rotz" type="revolute">
        <origin xyz="0 0 0" rpy="0 0 0"/>
        <parent link="LeftForeArm_f2"/>
        <child link="LeftForeArm"/>
        <dynamics damping="0.1" friction="0.0"/>
        <limit effort="30" velocity="1.0" lower="-10.0" upper="10.0" />
        <axis xyz="0 0 1" />
    </joint>
	<joint name="jLeftWrist_rotx" type="revolute">
        <origin xyz="7.3e-05     0.22237           0" rpy="0 0 0"/>
        <parent link="LeftForeArm"/>
        <child link="LeftHand_f1"/>
        <dynamics damping="0.1" friction="0.0"/>
        <limit effort="30" velocity="1.0" lower="-10.0" upper="10.0" />
        <axis xyz="1 0 0" />
    </joint>
	<joint name="jLeftWrist_roty" type="revolute">
        <origin xyz="0 0 0" rpy="0 0 0"/>
        <parent link="LeftHand_f1"/>
        <child link="LeftHand_f2"/>
        <dynamics damping="0.1" friction="0.0"/>
        <limit effort="30" velocity="1.0" lower="-10.0" upper="10.0" />
        <axis xyz="0 1 0" />
    </joint>
    <joint name="jLeftWrist_rotz" type="revolute">
        <origin xyz="0 0 0" rpy="0 0 0"/>
        <parent link="LeftHand_f2"/>
        <child link="LeftHand"/>
        <dynamics damping="0.1" friction="0.0"/>
        <limit effort="30" velocity="1.0" lower="-10.0" upper="10.0" />
        <axis xyz="0 0 1" />
    </joint>
	<!--Chain from (16) to (19)-->
	<joint name="jRightHip_rotx" type="revolute">
        <origin xyz="4.4e-05   -0.081879    0.000436" rpy="0 0 0"/>
        <parent link="Pelvis"/>
        <child link="RightUpperLeg_f1"/>
        <dynamics damping="0.1" friction="0.0"/>
        <limit effort="30" velocity="1.0" lower="-10.0" upper="10.0" />
        <axis xyz="1 0 0" />
    </joint>
	<joint name="jRightHip_roty" type="revolute">
        <origin xyz="0 0 0" rpy="0 0 0"/>
        <parent link="RightUpperLeg_f1"/>
        <child link="RightUpperLeg_f2"/>
        <dynamics damping="0.1" friction="0.0"/>
        <limit effort="30" velocity="1.0" lower="-10.0" upper="10.0" />
        <axis xyz="0 1 0" />
    </joint>
    <joint name="jRightHip_rotz" type="revolute">
        <origin xyz="0 0 0" rpy="0 0 0"/>
        <parent link="RightUpperLeg_f2"/>
        <child link="RightUpperLeg"/>
        <dynamics damping="0.1" friction="0.0"/>
        <limit effort="30" velocity="1.0" lower="-10.0" upper="10.0" />
        <axis xyz="0 0 1" />
    </joint>
	<joint name="jRightKnee_rotx" type="revolute">
        <origin xyz="6.7e-05           0    -0.45113" rpy="0 0 0"/>
        <parent link="RightUpperLeg"/>
        <child link="RightLowerLeg_f1"/>
        <dynamics damping="0.1" friction="0.0"/>
        <limit effort="30" velocity="1.0" lower="-10.0" upper="10.0" />
        <axis xyz="1 0 0" />
    </joint>
	<joint name="jRightKnee_roty" type="revolute">
        <origin xyz="0 0 0" rpy="0 0 0"/>
        <parent link="RightLowerLeg_f1"/>
        <child link="RightLowerLeg_f2"/>
        <dynamics damping="0.1" friction="0.0"/>
        <limit effort="30" velocity="1.0" lower="-10.0" upper="10.0" />
        <axis xyz="0 1 0" />
    </joint>
    <joint name="jRightKnee_rotz" type="revolute">
        <origin xyz="0 0 0" rpy="0 0 0"/>
        <parent link="RightLowerLeg_f2"/>
        <child link="RightLowerLeg"/>
        <dynamics damping="0.1" friction="0.0"/>
        <limit effort="30" velocity="1.0" lower="-10.0" upper="10.0" />
        <axis xyz="0 0 1" />
    </joint>
	<joint name="jRightAnkle_rotx" type="revolute">
        <origin xyz="0.000289           0    -0.40628" rpy="0 0 0"/>
        <parent link="RightLowerLeg"/>
        <child link="RightFoot_f1"/>
        <dynamics damping="0.1" friction="0.0"/>
        <limit effort="30" velocity="1.0" lower="-10.0" upper="10.0" />
        <axis xyz="1 0 0" />
    </joint>
	<joint name="jRightAnkle_roty" type="revolute">
        <origin xyz="0 0 0" rpy="0 0 0"/>
        <parent link="RightFoot_f1"/>
        <child link="RightFoot_f2"/>
        <dynamics damping="0.1" friction="0.0"/>
        <limit effort="30" velocity="1.0" lower="-10.0" upper="10.0" />
        <axis xyz="0 1 0" />
    </joint>
    <joint name="jRightAnkle_rotz" type="revolute">
        <origin xyz="0 0 0" rpy="0 0 0"/>
        <parent link="RightFoot_f2"/>
        <child link="RightFoot"/>
        <dynamics damping="0.1" friction="0.0"/>
        <limit effort="30" velocity="1.0" lower="-10.0" upper="10.0" />
        <axis xyz="0 0 1" />
    </joint>
	<joint name="jRightBallFoot_rotx" type="revolute">
        <origin xyz="0.14109           0    -0.10944" rpy="0 0 0"/>
        <parent link="RightFoot"/>
        <child link="RightToe_f1"/>
        <dynamics damping="0.1" friction="0.0"/>
        <limit effort="30" velocity="1.0" lower="-10.0" upper="10.0" />
        <axis xyz="1 0 0" />
    </joint>
	<joint name="jRightBallFoot_roty" type="revolute">
        <origin xyz="0 0 0" rpy="0 0 0"/>
        <parent link="RightToe_f1"/>
        <child link="RightToe_f2"/>
        <dynamics damping="0.1" friction="0.0"/>
        <limit effort="30" velocity="1.0" lower="-10.0" upper="10.0" />
        <axis xyz="0 1 0" />
    </joint>
    <joint name="jRightBallFoot_rotz" type="revolute">
        <origin xyz="0 0 0" rpy="0 0 0"/>
        <parent link="RightToe_f2"/>
        <child link="RightToe"/>
        <dynamics damping="0.1" friction="0.0"/>
        <limit effort="30" velocity="1.0" lower="-10.0" upper="10.0" />
        <axis xyz="0 0 1" />
    </joint>
	<!--Chain from (20) to (23)-->
	<joint name="jLeftHip_rotx" type="revolute">
        <origin xyz="4.4e-05    0.081879    0.000436" rpy="0 0 0"/>
        <parent link="Pelvis"/>
        <child link="LeftUpperLeg_f1"/>
        <dynamics damping="0.1" friction="0.0"/>
        <limit effort="30" velocity="1.0" lower="-10.0" upper="10.0" />
        <axis xyz="1 0 0" />
    </joint>
	<joint name="jLeftHip_roty" type="revolute">
        <origin xyz="0 0 0" rpy="0 0 0"/>
        <parent link="LeftUpperLeg_f1"/>
        <child link="LeftUpperLeg_f2"/>
        <dynamics damping="0.1" friction="0.0"/>
        <limit effort="30" velocity="1.0" lower="-10.0" upper="10.0" />
        <axis xyz="0 1 0" />
    </joint>
    <joint name="jLeftHip_rotz" type="revolute">
        <origin xyz="0 0 0" rpy="0 0 0"/>
        <parent link="LeftUpperLeg_f2"/>
        <child link="LeftUpperLeg"/>
        <dynamics damping="0.1" friction="0.0"/>
        <limit effort="30" velocity="1.0" lower="-10.0" upper="10.0" />
        <axis xyz="0 0 1" />
    </joint>
	<joint name="jLeftKnee_rotx" type="revolute">
        <origin xyz="6.7e-05           0    -0.45113" rpy="0 0 0"/>
        <parent link="LeftUpperLeg"/>
        <child link="LeftLowerLeg_f1"/>
        <dynamics damping="0.1" friction="0.0"/>
        <limit effort="30" velocity="1.0" lower="-10.0" upper="10.0" />
        <axis xyz="1 0 0" />
    </joint>
	<joint name="jLeftKnee_roty" type="revolute">
        <origin xyz="0 0 0" rpy="0 0 0"/>
        <parent link="LeftLowerLeg_f1"/>
        <child link="LeftLowerLeg_f2"/>
        <dynamics damping="0.1" friction="0.0"/>
        <limit effort="30" velocity="1.0" lower="-10.0" upper="10.0" />
        <axis xyz="0 1 0" />
    </joint>
    <joint name="jLeftKnee_rotz" type="revolute">
        <origin xyz="0 0 0" rpy="0 0 0"/>
        <parent link="LeftLowerLeg_f2"/>
        <child link="LeftLowerLeg"/>
        <dynamics damping="0.1" friction="0.0"/>
        <limit effort="30" velocity="1.0" lower="-10.0" upper="10.0" />
        <axis xyz="0 0 1" />
    </joint>
	<joint name="jLeftAnkle_rotx" type="revolute">
        <origin xyz="0.000289           0    -0.40628" rpy="0 0 0"/>
        <parent link="LeftLowerLeg"/>
        <child link="LeftFoot_f1"/>
        <dynamics damping="0.1" friction="0.0"/>
        <limit effort="30" velocity="1.0" lower="-10.0" upper="10.0" />
        <axis xyz="1 0 0" />
    </joint>
	<joint name="jLeftAnkle_roty" type="revolute">
        <origin xyz="0 0 0" rpy="0 0 0"/>
        <parent link="LeftFoot_f1"/>
        <child link="LeftFoot_f2"/>
        <dynamics damping="0.1" friction="0.0"/>
        <limit effort="30" velocity="1.0" lower="-10.0" upper="10.0" />
        <axis xyz="0 1 0" />
    </joint>
    <joint name="jLeftAnkle_rotz" type="revolute">
        <origin xyz="0 0 0" rpy="0 0 0"/>
        <parent link="LeftFoot_f2"/>
        <child link="LeftFoot"/>
        <dynamics damping="0.1" friction="0.0"/>
        <limit effort="30" velocity="1.0" lower="-10.0" upper="10.0" />
        <axis xyz="0 0 1" />
    </joint>
	<joint name="jLeftBallFoot_rotx" type="revolute">
        <origin xyz="0.14109           0    -0.10944" rpy="0 0 0"/>
        <parent link="LeftFoot"/>
        <child link="LeftToe_f1"/>
        <dynamics damping="0.1" friction="0.0"/>
        <limit effort="30" velocity="1.0" lower="-10.0" upper="10.0" />
        <axis xyz="1 0 0" />
    </joint>
	<joint name="jLeftBallFoot_roty" type="revolute">
        <origin xyz="0 0 0" rpy="0 0 0"/>
        <parent link="LeftToe_f1"/>
        <child link="LeftToe_f2"/>
        <dynamics damping="0.1" friction="0.0"/>
        <limit effort="30" velocity="1.0" lower="-10.0" upper="10.0" />
        <axis xyz="0 1 0" />
    </joint>
    <joint name="jLeftBallFoot_rotz" type="revolute">
        <origin xyz="0 0 0" rpy="0 0 0"/>
        <parent link="LeftToe_f2"/>
        <child link="LeftToe"/>
        <dynamics damping="0.1" friction="0.0"/>
        <limit effort="30" velocity="1.0" lower="-10.0" upper="10.0" />
        <axis xyz="0 0 1" />
    </joint>

<robot name="XSensStyleModel_template">
<!--To open this model with Gazebo replace the null masses, inertias and dimensions of the 'fake links f1 and f2'-->
    <!--LINKS-->
	<!--Link base (1)-->
	<link name="Pelvis">
        <inertial>
            <mass value="4.88"/>
			<!--COM origin wrt pHipOrigin-->
            <origin xyz="0           0    0.050194" rpy="0 0 0" />
            <inertia ixx="0.029296" iyy="0.011839" izz="0.033081" ixy="0" ixz="0" iyz="0"/>
        </inertial>

        <visual>
			<!--box origin wrt pHipOrigin-->
            <origin xyz="0           0    0.050194" rpy="0 0 0" />
            <geometry>
                <box size="0.1386     0.24927    0.099515"/>
            </geometry>
        </visual>

        <collision>
			<!--box origin wrt pHipOrigin-->
            <origin xyz="0           0    0.050194" rpy="0 0 0" />
            <geometry>
                <box size="0.1386     0.24927    0.099515"/>
            </geometry>
        </collision>

    </link>
    <!--Chain from (2) to (7)-->
	<link name="L5_f1">
        <inertial>
            <mass value="0"/>
            <origin xyz="0 0 0" rpy="0 0 0" />
            <inertia ixx="0" iyy="0" izz="0" ixy="0" ixz="0" iyz="0"/>
        </inertial>
    </link>
	<link name="L5">
        <inertial>
            <mass value="6.222"/>
			<!--COM origin wrt jL5S1-->
            <origin xyz="0           0     0.04987" rpy="0 0 0" />
            <inertia ixx="0.019063" iyy="0.015119" izz="0.0002671" ixy="0" ixz="0" iyz="0"/>
        </inertial>

        <visual>
			<!--box origin origin wrt jL5S1-->
            <origin xyz="0           0     0.04987" rpy="0 0 0" />
            <geometry>
                <box size="0.1386     0.16376    0.099741"/>
            </geometry>
        </visual>

        <collision>
			<!--box origin origin wrt jL5S1-->
            <origin xyz="0           0     0.04987" rpy="0 0 0" />
            <geometry>
                <box size="0.1386     0.16376    0.099741"/>
            </geometry>
        </collision>
    </link>
	<link name="L3_f1">
        <inertial>
            <mass value="0"/>
            <origin xyz="0 0 0" rpy="0 0 0" />
            <inertia ixx="0" iyy="0" izz="0" ixy="0" ixz="0" iyz="0"/>
        </inertial>
    </link>
	<link name="L3">
        <inertial>
            <mass value="6.222"/>
			<!--COM origin wrt jL4L3-->
            <origin xyz="0           0    0.045056" rpy="0 0 0" />
            <inertia ixx="0.018115" iyy="0.014171" izz="0.023865" ixy="0" ixz="0" iyz="0"/>
        </inertial>

        <visual>
			<!--box origin origin wrt jL4L3-->
            <origin xyz="0           0    0.045056" rpy="0 0 0" />
            <geometry>
                <box size="0.1386     0.16376    0.090113"/>
            </geometry>
        </visual>

        <collision>
			<!--box origin origin wrt jL4L3-->
            <origin xyz="0           0    0.045056" rpy="0 0 0" />
            <geometry>
                <box size="0.1386     0.16376    0.090113"/>
            </geometry>
        </collision>
    </link>
	<link name="T12_f1">
        <inertial>
            <mass value="0"/>
            <origin xyz="0 0 0" rpy="0 0 0" />
            <inertia ixx="0" iyy="0" izz="0" ixy="0" ixz="0" iyz="0"/>
        </inertial>
    </link>
	<link name="T12">
        <inertial>
            <mass value="6.222"/>
			<!--COM origin wrt jL1T12-->
            <origin xyz="0           0    0.045056" rpy="0 0 0" />
            <inertia ixx="0.018115" iyy="0.014171" izz="0.023865" ixy="0" ixz="0" iyz="0"/>
        </inertial>

        <visual>
			<!--box origin origin wrt jL1T12-->
            <origin xyz="0           0    0.045056" rpy="0 0 0" />
            <geometry>
                <box size="0.1386     0.16376    0.090113"/>
            </geometry>
        </visual>

        <collision>
			<!--box origin origin wrt jL1T12-->
            <origin xyz="0           0    0.045056" rpy="0 0 0" />
            <geometry>
                <box size="0.1386     0.16376    0.090113"/>
            </geometry>
        </collision>
    </link>
	<link name="T8_f1">
        <inertial>
            <mass value="0"/>
            <origin xyz="0 0 0" rpy="0 0 0" />
            <inertia ixx="0" iyy="0" izz="0" ixy="0" ixz="0" iyz="0"/>
        </inertial>
    </link>
	<link name="T8_f2">
        <inertial>
            <mass value="0"/>
            <origin xyz="0 0 0" rpy="0 0 0" />
            <inertia ixx="0" iyy="0" izz="0" ixy="0" ixz="0" iyz="0"/>
        </inertial>
    </link>
	<link name="T8">
        <inertial>
            <mass value="2.44"/>
			<!--COM origin wrt jT9T8-->
            <origin xyz="0           0    0.062925" rpy="0 0 0" />
            <inertia ixx="0.0038182" iyy="0.007132" izz="0.0045093" ixy="0" ixz="0" iyz="0"/>
        </inertial>

        <visual>
			<!--box origin wrt jT9T8-->
            <origin xyz="0           0    0.062925" rpy="0 0 0" />
            <geometry>
                <box size="0.1387    0.054218     0.12585"/>
            </geometry>
        </visual>

        <collision>
			<!--box origin wrt jT9T8-->
            <origin xyz="0           0    0.062925" rpy="0 0 0" />
            <geometry>
                <box size="0.1387    0.054218     0.12585"/>
            </geometry>
        </collision>

    </link>
	<link name="Neck_f1">
        <inertial>
            <mass value="0"/>
            <origin xyz="0 0 0" rpy="0 0 0" />
            <inertia ixx="0" iyy="0" izz="0" ixy="0" ixz="0" iyz="0"/>
        </inertial>
    </link>
	<link name="Neck_f2">
        <inertial>
            <mass value="0"/>
            <origin xyz="0 0 0" rpy="0 0 0" />
            <inertia ixx="0" iyy="0" izz="0" ixy="0" ixz="0" iyz="0"/>
        </inertial>
    </link>
	<link name="Neck">
        <inertial>
            <mass value="0.732"/>
			<!--COM origin wrt jT1C7-->
            <origin xyz="0           0    0.041973" rpy="0 0 0" />
            <inertia ixx="0.00056618" iyy="0.00056618" izz="0.00027264" ixy="0" ixz="0" iyz="0"/>
        </inertial>

        <visual>
			<!--box origin wrt jT1C7-->
            <origin xyz="0           0    0.041973" rpy="0 0 0" />
            <geometry>
		<cylinder length="0.083946" radius="0.013647"/>
            </geometry>
        </visual>

        <collision>
			<!--box origin wrt jT1C7-->
            <origin xyz="0           0    0.041973" rpy="0 0 0" />
            <geometry>
                <cylinder length="0.083946" radius="0.013647"/>
            </geometry>
        </collision>
    </link>
	<link name="Head_f1">
        <inertial>
            <mass value="0"/>
            <origin xyz="0 0 0" rpy="0 0 0" />
            <inertia ixx="0" iyy="0" izz="0" ixy="0" ixz="0" iyz="0"/>
        </inertial>
    </link>
	<link name="Head">
        <inertial>
            <mass value="2.196"/>
			<!--COM origin wrt jC1Head-->
            <origin xyz="0           0    0.079896" rpy="0 0 0" />
            <inertia ixx="0.0056072" iyy="0.0056072" izz="0.0056072" ixy="0" ixz="0" iyz="0"/>
        </inertial>

        <visual>
			<!--boc origin wrt jC1Head-->
            <origin xyz="0           0    0.079896" rpy="0 0 0" />
            <geometry>
                <sphere radius="0.079896"/>
            </geometry>
        </visual>

        <collision>
			<!--box origin wrt jC1Head-->
            <origin xyz="0           0    0.079896" rpy="0 0 0" />
            <geometry>
                <sphere radius="0.079896"/>
            </geometry>
        </collision>

    </link>
	<!--Chain from (8) to (11)-->
	<link name="RightShoulder">
        <inertial>
            <mass value="1.891"/>
			<!--COM origin wrt jRightC7Shoulder-->
            <origin xyz="0   -0.064947           0" rpy="0 0 0" />
            <inertia ixx="0.0029192" iyy="0.00052075" izz="0.0029192" ixy="0" ixz="0" iyz="0"/>
        </inertial>

        <visual>
			<!--box origin wrt jRightC7Shoulder. RPY rotated of pi/2.-->
            <origin xyz="0   -0.064947           0" rpy="1.5708 0 0" />
            <geometry>
                <cylinder length="0.12989" radius="0.023468"/>
            </geometry>
        </visual>

        <collision>
			<!--box origin wrt jRightC7Shoulder. RPY rotated of pi/2.-->
            <origin xyz="0   -0.064947           0" rpy="1.5708 0 0" />
            <geometry>
                <cylinder length="0.12989" radius="0.023468"/>
            </geometry>
        </collision>

    </link>
	<link name="RightUpperArm_f1">
        <inertial>
            <mass value="0"/>
            <origin xyz="0 0 0" rpy="0 0 0" />
            <inertia ixx="0" iyy="0" izz="0" ixy="0" ixz="0" iyz="0"/>
        </inertial>
    </link>
	<link name="RightUpperArm_f2">
        <inertial>
            <mass value="0"/>
            <origin xyz="0 0 0" rpy="0 0 0" />
            <inertia ixx="0" iyy="0" izz="0" ixy="0" ixz="0" iyz="0"/>
        </inertial>
    </link>
    <link name="RightUpperArm">
        <inertial>
            <mass value="1.83"/>
			<!--COM origin wrt jRightShoulder-->
            <origin xyz="0    -0.13498           0" rpy="0 0 0" />
            <inertia ixx="0.01151" iyy="0.00079302" izz="0.01151" ixy="0" ixz="0" iyz="0"/>
        </inertial>

        <visual>
			<!--box origin wrt jRightShoulder. RPY rotated of pi/2.-->
            <origin xyz="0    -0.13498           0" rpy="1.5708 0 0" />
            <geometry>
                <cylinder length="0.26995" radius="0.02944"/>
            </geometry>
        </visual>

        <collision>
			<!--box origin wrt jRightShoulder. RPY rotated of pi/2.-->
            <origin xyz="0    -0.13498           0" rpy="1.5708 0 0" />
            <geometry>
                <cylinder length="0.26995" radius="0.02944"/>
            </geometry>
        </collision>

    </link>
	<link name="RightForeArm_f1">
        <inertial>
            <mass value="0"/>
            <origin xyz="0 0 0" rpy="0 0 0" />
            <inertia ixx="0" iyy="0" izz="0" ixy="0" ixz="0" iyz="0"/>
        </inertial>
    </link>
	<link name="RightForeArm">
        <inertial>
            <mass value="1.22"/>
			<!--COM origin wrt jRightElbow-->
            <origin xyz="0    -0.11119           0" rpy="0 0 0" />
            <inertia ixx="0.0051448" iyy="0.00023497" izz="0.0051448" ixy="0" ixz="0" iyz="0"/>
        </inertial>

        <visual>
			<!--box origin wrt jRightElbow. RPY rotated of pi/2.-->
            <origin xyz="0    -0.11119           0" rpy="1.5708 0 0" />
            <geometry>
                <cylinder length="0.22237" radius="0.019626"/>
            </geometry>
        </visual>

        <collision>
			<!--box origin wrt jRightElbow. RPY rotated of pi/2.-->
            <origin xyz="0    -0.11119           0" rpy="1.5708 0 0" />
            <geometry>
                <cylinder length="0.22237" radius="0.019626"/>
            </geometry>
        </collision>

    </link>
	<link name="RightHand_f1">
        <inertial>
            <mass value="0"/>
            <origin xyz="0 0 0" rpy="0 0 0" />
            <inertia ixx="0" iyy="0" izz="0" ixy="0" ixz="0" iyz="0"/>
        </inertial>
    </link>
	<link name="RightHand">
        <inertial>
            <mass value="0.366"/>
			<!--COM origin wrt jRightWrist-->
            <origin xyz="0   -0.083494           0" rpy="0 0 0" />
            <inertia ixx="0.0008975" iyy="0.00042499" izz="0.0012285" ixy="0" ixz="0" iyz="0"/>
        </inertial>

        <visual>
			<!--box origin wrt jRightWrist-->
            <origin xyz="0   -0.083494           0" rpy="0 0 0" />
            <geometry>
                <box size="0.11133     0.16699    0.039253"/>
            </geometry>
        </visual>

        <collision>
			<!--box origin wrt jRightWrist-->
            <origin xyz="0   -0.083494           0" rpy="0 0 0" />
            <geometry>
                <box size="0.11133     0.16699    0.039253"/>
            </geometry>
        </collision>

    </link>
	<!--Chain from (12) to (15)-->
	<link name="LeftShoulder">
        <inertial>
            <mass value="1.891"/>
			<!--COM origin wrt jLeftC7Shoulder-->
            <origin xyz="0    0.064947           0" rpy="0 0 0" />
            <inertia ixx="0.0029192" iyy="0.00052075" izz="0.0029192" ixy="0" ixz="0" iyz="0"/>
        </inertial>

        <visual>
			<!--box origin wrt jLeftC7Shoulder. RPY rotated of pi/2.-->
            <origin xyz="0    0.064947           0" rpy="1.5708 0 0" />
            <geometry>
                <cylinder length="0.12989" radius="0.023468"/>
            </geometry>
        </visual>

        <collision>
			<!--box origin wrt jLeftC7Shoulder. RPY rotated of pi/2.-->
            <origin xyz="0    0.064947           0" rpy="1.5708 0 0" />
            <geometry>
                <cylinder length="0.12989" radius="0.023468"/>
            </geometry>
        </collision>

    </link>
	<link name="LeftUpperArm_f1">
        <inertial>
            <mass value="0"/>
            <origin xyz="0 0 0" rpy="0 0 0" />
            <inertia ixx="0" iyy="0" izz="0" ixy="0" ixz="0" iyz="0"/>
        </inertial>
    </link>
	<link name="LeftUpperArm_f2">
        <inertial>
            <mass value="0"/>
            <origin xyz="0 0 0" rpy="0 0 0" />
            <inertia ixx="0" iyy="0" izz="0" ixy="0" ixz="0" iyz="0"/>
        </inertial>
    </link>
	<link name="LeftUpperArm">
        <inertial>
            <mass value="1.83"/>
			<!--COM origin wrt jLeftShoulder-->
            <origin xyz="0     0.13498           0" rpy="0 0 0" />
            <inertia ixx="0.01151" iyy="0.00079302" izz="0.01151" ixy="0" ixz="0" iyz="0"/>
        </inertial>

        <visual>
			<!--box origin wrt jLeftShoulder. RPY rotated of pi/2.-->
            <origin xyz="0     0.13498           0" rpy="1.5708 0 0" />
            <geometry>
                <cylinder length="0.26995" radius="0.02944"/>
            </geometry>
        </visual>

        <collision>
			<!--box origin wrt jLeftShoulder. RPY rotated of pi/2.-->
            <origin xyz="0     0.13498           0" rpy="1.5708 0 0" />
            <geometry>
                <cylinder length="0.26995" radius="0.02944"/>
            </geometry>
        </collision>

    </link>
	<link name="LeftForeArm_f1">
        <inertial>
            <mass value="0"/>
            <origin xyz="0 0 0" rpy="0 0 0" />
            <inertia ixx="0" iyy="0" izz="0" ixy="0" ixz="0" iyz="0"/>
        </inertial>
    </link>
	<link name="LeftForeArm">
        <inertial>
            <mass value="1.22"/>
			<!--COM origin wrt jLeftElbow-->
            <origin xyz="0     0.11119           0" rpy="0 0 0" />
            <inertia ixx="0.0051448" iyy="0.00023497" izz="0.0051448" ixy="0" ixz="0" iyz="0"/>
        </inertial>

        <visual>
			<!--box origin wrt jLeftElbow. RPY rotated of pi/2.-->
            <origin xyz="0     0.11119           0" rpy="1.5708 0 0" />
            <geometry>
                <cylinder length="0.22237" radius="0.019626"/>
            </geometry>
        </visual>

        <collision>
			<!--box origin wrt jLeftElbow. RPY rotated of pi/2.-->
            <origin xyz="0     0.11119           0" rpy="1.5708 0 0" />
            <geometry>
                <cylinder length="0.22237" radius="0.019626"/>
            </geometry>
        </collision>

    </link>
	<link name="LeftHand_f1">
        <inertial>
            <mass value="0"/>
            <origin xyz="0 0 0" rpy="0 0 0" />
            <inertia ixx="0" iyy="0" izz="0" ixy="0" ixz="0" iyz="0"/>
        </inertial>
    </link>
	<link name="LeftHand">
        <inertial>
            <mass value="0.366"/>
			<!--COM origin wrt jLeftWrist-->
            <origin xyz="0    0.083494           0" rpy="0 0 0" />
            <inertia ixx="0.0008975" iyy="0.00042499" izz="0.0012285" ixy="0" ixz="0" iyz="0"/>
        </inertial>

        <visual>
			<!--COM origin wrt jLeftWrist-->
            <origin xyz="0    0.083494           0" rpy="0 0 0" />
            <geometry>
                <box size="0.11133     0.16699    0.039253"/>
            </geometry>
        </visual>

        <collision>
			<!--COM origin wrt jLeftWrist-->
            <origin xyz="0    0.083494           0" rpy="0 0 0" />
            <geometry>
                <box size="0.11133     0.16699    0.039253"/>
            </geometry>
        </collision>

    </link>
	<!--Chain from (16) to (19)-->
	<link name="RightUpperLeg_f1">
        <inertial>
            <mass value="0"/>
            <origin xyz="0 0 0" rpy="0 0 0" />
            <inertia ixx="0" iyy="0" izz="0" ixy="0" ixz="0" iyz="0"/>
        </inertial>
    </link>
	<link name="RightUpperLeg_f2">
        <inertial>
            <mass value="0"/>
            <origin xyz="0 0 0" rpy="0 0 0" />
            <inertia ixx="0" iyy="0" izz="0" ixy="0" ixz="0" iyz="0"/>
        </inertial>
    </link>
    <link name="RightUpperLeg">
        <inertial>
            <mass value="7.625"/>
			<!--COM origin wrt jRightHip-->
            <origin xyz="0           0    -0.22557" rpy="0 0 0" />
            <inertia ixx="0.13545" iyy="0.13545" izz="0.012254" ixy="0" ixz="0" iyz="0"/>
        </inertial>

        <visual>
			<!--box origin wrt jRightHip-->
            <origin xyz="0           0    -0.22557" rpy="0 0 0" />
            <geometry>
                <cylinder length="0.45113" radius="0.056694"/>
            </geometry>
        </visual>

        <collision>
			<!--box origin wrt jRightHip-->
            <origin xyz="0           0    -0.22557" rpy="0 0 0" />
            <geometry>
                <cylinder length="0.45113" radius="0.056694"/>
            </geometry>
        </collision>

    </link>
	<link name="RightLowerLeg_f1">
        <inertial>
            <mass value="0"/>
            <origin xyz="0 0 0" rpy="0 0 0" />
            <inertia ixx="0" iyy="0" izz="0" ixy="0" ixz="0" iyz="0"/>
        </inertial>
    </link>
    <link name="RightLowerLeg">
        <inertial>
            <mass value="2.2265"/>
			<!--COM origin wrt jRightKnee-->
            <origin xyz="0           0    -0.20314" rpy="0 0 0" />
            <inertia ixx="0.031404" iyy="0.031404" izz="0.001557" ixy="0" ixz="0" iyz="0"/>
        </inertial>

        <visual>
			<!--box origin wrt jRightKnee-->
            <origin xyz="0           0    -0.20314" rpy="0 0 0" />
            <geometry>
                <cylinder length="0.40628" radius="0.037398"/>
            </geometry>
        </visual>

        <collision>
			<!--box origin wrt jRightKnee-->
            <origin xyz="0           0    -0.20314" rpy="0 0 0" />
            <geometry>
                <cylinder length="0.40628" radius="0.037398"/>
            </geometry>
        </collision>

    </link>
	<link name="RightFoot_f1">
        <inertial>
            <mass value="0"/>
            <origin xyz="0 0 0" rpy="0 0 0" />
            <inertia ixx="0" iyy="0" izz="0" ixy="0" ixz="0" iyz="0"/>
        </inertial>
    </link>
	<link name="RightFoot_f2">
        <inertial>
            <mass value="0"/>
            <origin xyz="0 0 0" rpy="0 0 0" />
            <inertia ixx="0" iyy="0" izz="0" ixy="0" ixz="0" iyz="0"/>
        </inertial>
    </link>
    <link name="RightFoot">
        <inertial>
            <mass value="0.793"/>
			<!--COM origin wrt jRightAnkle-->
            <origin xyz="0.050643           0   -0.061735" rpy="0 0 0" />
            <inertia ixx="0.0013771" iyy="0.00317" izz="0.0025323" ixy="0" ixz="0" iyz="0"/>
        </inertial>

        <visual>
			<!--box origin wrt jRightAnkle-->
	    	<origin xyz="0.050643           0   -0.061735" rpy="0 0 0" />
            <geometry>
                <box size="0.1809    0.074795     0.12347"/>
            </geometry>
        </visual>

        <collision>
			<!--box origin wrt jRightAnkle-->
		    <origin xyz="0.050643           0   -0.061735" rpy="0 0 0" />
	            <geometry>
	                <box size="0.1809    0.074795     0.12347"/>
	            </geometry>
        </collision>

    </link>
    <link name="RightToe">
        <inertial>
            <mass value="0.0915"/>
			<!--COM origin wrt jRightBallFoot-->
            <origin xyz="0.029551           0           0" rpy="0 0 0" />
            <inertia ixx="4.419e-05" iyy="2.8167e-05" izz="6.929e-05" ixy="0" ixz="0" iyz="0"/>
        </inertial>

        <visual>
			<!--box origin wrt jRightBallFoot-->
            <origin xyz="0.029551           0           0" rpy="0 0 0" />
            <geometry>
                <box size="0.059101    0.074795    0.014183"/>
            </geometry>
        </visual>

        <collision>
			<!--box origin wrt jRightBallFoot-->
            <origin xyz="0.029551           0           0" rpy="0 0 0" />
            <geometry>
                <box size="0.059101    0.074795    0.014183"/>
            </geometry>
        </collision>
    </link>
	<!--Chain from (20) to (23)-->
	<link name="LeftUpperLeg_f1">
        <inertial>
            <mass value="0"/>
            <origin xyz="0 0 0" rpy="0 0 0" />
            <inertia ixx="0" iyy="0" izz="0" ixy="0" ixz="0" iyz="0"/>
        </inertial>
    </link>
	<link name="LeftUpperLeg_f2">
        <inertial>
            <mass value="0"/>
            <origin xyz="0 0 0" rpy="0 0 0" />
            <inertia ixx="0" iyy="0" izz="0" ixy="0" ixz="0" iyz="0"/>
        </inertial>
    </link>
    <link name="LeftUpperLeg">
        <inertial>
            <mass value="7.625"/>
			<!--COM origin wrt jLeftHip-->
            <origin xyz="0           0    -0.22557" rpy="0 0 0" />
            <inertia ixx="0.13545" iyy="0.13545" izz="0.012254" ixy="0" ixz="0" iyz="0"/>
        </inertial>

        <visual>
			<!--box origin wrt jLeftHip-->
            <origin xyz="0           0    -0.22557" rpy="0 0 0" />
            <geometry>
                <cylinder length="0.45113" radius="-0.056694"/>
            </geometry>
        </visual>

        <collision>
			<!--box origin wrt jLeftHip-->
            <origin xyz="0           0    -0.22557" rpy="0 0 0" />
            <geometry>
                <cylinder length="0.45113" radius="-0.056694"/>
            </geometry>
        </collision>

    </link>
	<link name="LeftLowerLeg_f1">
        <inertial>
            <mass value="0"/>
            <origin xyz="0 0 0" rpy="0 0 0" />
            <inertia ixx="0" iyy="0" izz="0" ixy="0" ixz="0" iyz="0"/>
        </inertial>
    </link>
	<link name="LeftLowerLeg">
        <inertial>
            <mass value="2.2265"/>
			<!--COM origin wrt jLeftKnee-->
            <origin xyz="0           0    -0.20314" rpy="0 0 0" />
            <inertia ixx="0.031404" iyy="0.031404" izz="0.001557" ixy="0" ixz="0" iyz="0"/>
        </inertial>

        <visual>
			<!--box origin wrt jLeftKnee-->
            <origin xyz="0           0    -0.20314" rpy="0 0 0" />
            <geometry>
		<cylinder length="0.40628" radius="0.037398"/>
            </geometry>
        </visual>

        <collision>
			<!--box origin wrt jLeftKnee-->
            <origin xyz="0           0    -0.20314" rpy="0 0 0" />
            <geometry>
		<cylinder length="0.40628" radius="0.037398"/>
            </geometry>
        </collision>

    </link>
	<link name="LeftFoot_f1">
        <inertial>
            <mass value="0"/>
            <origin xyz="0 0 0" rpy="0 0 0" />
            <inertia ixx="0" iyy="0" izz="0" ixy="0" ixz="0" iyz="0"/>
        </inertial>
    </link>
	<link name="LeftFoot_f2">
        <inertial>
            <mass value="0"/>
            <origin xyz="0 0 0" rpy="0 0 0" />
            <inertia ixx="0" iyy="0" izz="0" ixy="0" ixz="0" iyz="0"/>
        </inertial>
    </link>
    <link name="LeftFoot">
        <inertial>
            <mass value="0.793"/>
			<!--COM origin wrt jLeftAnkle-->
            <origin xyz="0.050643           0   -0.061735" rpy="0 0 0" />
            <inertia ixx="0.0013771" iyy="0.00317" izz="0.0025323" ixy="0" ixz="0" iyz="0"/>
        </inertial>

        <visual>
			<!--box origin wrt jLeftAnkle-->
	   	 	<origin xyz="0.050643           0   -0.061735" rpy="0 0 0" />
            <geometry>
                <box size="0.1809    0.074795     0.12347"/>
            </geometry>
        </visual>

        <collision>
			<!--box origin wrt jLeftAnkle-->
		    <origin xyz="0.050643           0   -0.061735" rpy="0 0 0" />
	            <geometry>
	                <box size="0.1809    0.074795     0.12347"/>
	            </geometry>
        </collision>

    </link>
	<link name="LeftToe">
        <inertial>
            <mass value="0.0915"/>
			<!--COM origin wrt jLeftBallFoot-->
            <origin xyz="0.029551           0           0" rpy="0 0 0" />
            <inertia ixx="4.419e-05" iyy="2.8167e-05" izz="6.929e-05" ixy="0" ixz="0" iyz="0"/>
        </inertial>

        <visual>
			<!--box origin wrt jLeftBallFoot-->
            <origin xyz="0.029551           0           0" rpy="0 0 0" />
            <geometry>
                <box size="0.059101    0.074795    0.014183"/>
            </geometry>
        </visual>

        <collision>
			<!--box origin wrt jLeftBallFoot-->
            <origin xyz="0.029551           0           0" rpy="0 0 0" />
            <geometry>
                <box size="0.059101    0.074795    0.014183"/>
            </geometry>
        </collision>
    </link>


	<!--JOINTS-->
	<!--Chain from (2) to (7)-->
	<joint name="jL5S1_rotx" type="revolute">
        <origin xyz="-8.9e-05           0    0.099951" rpy="0 0 0"/>
        <parent link="Pelvis"/>
        <child link="L5_f1"/>
        <dynamics damping="0.1" friction="0.0"/>
        <limit effort="30" velocity="1.0" lower="-0.610865" upper="0.610865" />
        <axis xyz="1 0 0" />
    </joint>
	<joint name="jL5S1_roty" type="revolute">
        <origin xyz="0 0 0" rpy="0 0 0"/>
        <parent link="L5_f1"/>
        <child link="L5"/>
        <dynamics damping="0.1" friction="0.0"/>
        <limit effort="30" velocity="1.0" lower="-0.523599" upper="1.309" />
        <axis xyz="0 1 0" />
    </joint>
	<joint name="jL4L3_rotx" type="revolute">
        <origin xyz="0.000162           0    0.099741" rpy="0 0 0"/>
        <parent link="L5"/>
        <child link="L3_f1"/>
        <dynamics damping="0.1" friction="0.0"/>
        <limit effort="30" velocity="1.0" lower="-0.610865" upper="0.610865" />
        <axis xyz="1 0 0" />
    </joint>
	<joint name="jL4L3_roty" type="revolute">
        <origin xyz="0 0 0" rpy="0 0 0"/>
        <parent link="L3_f1"/>
        <child link="L3"/>
        <dynamics damping="0.1" friction="0.0"/>
        <limit effort="30" velocity="1.0" lower="-0.523599" upper="1.309" />
        <axis xyz="0 1 0" />
    </joint>
	<joint name="jL1T12_rotx" type="revolute">
        <origin xyz="0           0    0.090113" rpy="0 0 0"/>
        <parent link="L3"/>
        <child link="T12_f1"/>
        <dynamics damping="0.1" friction="0.0"/>
        <limit effort="30" velocity="1.0" lower="-0.610865" upper="0.610865" />
        <axis xyz="1 0 0" />
    </joint>
	<joint name="jL1T12_roty" type="revolute">
        <origin xyz="0 0 0" rpy="0 0 0"/>
        <parent link="T12_f1"/>
        <child link="T12"/>
        <dynamics damping="0.1" friction="0.0"/>
        <limit effort="30" velocity="1.0" lower="-0.523599" upper="1.309" />
        <axis xyz="0 1 0" />
    </joint>
	<joint name="jT9T8_rotx" type="revolute">
        <origin xyz="0           0    0.090113" rpy="0 0 0"/>
        <parent link="T12"/>
        <child link="T8_f1"/>
        <dynamics damping="0.1" friction="0.0"/>
        <limit effort="30" velocity="1.0" lower="-0.349066" upper="0.349066" />
        <axis xyz="1 0 0" />
    </joint>
	<joint name="jT9T8_roty" type="revolute">
        <origin xyz="0 0 0" rpy="0 0 0"/>
        <parent link="T8_f1"/>
        <child link="T8_f2"/>
        <dynamics damping="0.1" friction="0.0"/>
        <limit effort="30" velocity="1.0" lower="-0.261799" upper="0.698132" />
        <axis xyz="0 1 0" />
    </joint>
    <joint name="jT9T8_rotz" type="revolute">
        <origin xyz="0 0 0" rpy="0 0 0"/>
        <parent link="T8_f2"/>
        <child link="T8"/>
        <dynamics damping="0.1" friction="0.0"/>
        <limit effort="30" velocity="1.0" lower="-0.610865" upper="0.610865" />
        <axis xyz="0 0 1" />
    </joint>
	<joint name="jT1C7_rotx" type="revolute">
        <origin xyz="0           0     0.12585" rpy="0 0 0"/>
        <parent link="T8"/>
        <child link="Neck_f1"/>
        <dynamics damping="0.1" friction="0.0"/>
        <limit effort="30" velocity="1.0" lower="-0.610865" upper="0.610865" />
        <axis xyz="1 0 0" />
    </joint>
	<joint name="jT1C7_roty" type="revolute">
        <origin xyz="0 0 0" rpy="0 0 0"/>
        <parent link="Neck_f1"/>
        <child link="Neck_f2"/>
        <dynamics damping="0.1" friction="0.0"/>
        <limit effort="30" velocity="1.0" lower="-0.959931" upper="1.5708" />
        <axis xyz="0 1 0" />
    </joint>
    <joint name="jT1C7_rotz" type="revolute">
        <origin xyz="0 0 0" rpy="0 0 0"/>
        <parent link="Neck_f2"/>
        <child link="Neck"/>
        <dynamics damping="0.1" friction="0.0"/>
        <limit effort="30" velocity="1.0" lower="-1.22173" upper="1.22173" />
        <axis xyz="0 0 1" />
    </joint>
	<joint name="jC1Head_rotx" type="revolute">
        <origin xyz="0.000384           0    0.083946" rpy="0 0 0"/>
        <parent link="Neck"/>
        <child link="Head_f1"/>
        <dynamics damping="0.1" friction="0.0"/>
        <limit effort="30" velocity="1.0" lower="-0.610865" upper="0.610865" />
        <axis xyz="1 0 0" />
    </joint>
	<joint name="jC1Head_roty" type="revolute">
        <origin xyz="0 0 0" rpy="0 0 0"/>
        <parent link="Head_f1"/>
        <child link="Head"/>
        <dynamics damping="0.1" friction="0.0"/>
        <limit effort="30" velocity="1.0" lower="-0.436332" upper="0.174533" />
        <axis xyz="0 1 0" />
    </joint>
	<!--Chain from (8) to (11)-->
	<joint name="jRightC7Shoulder_rotx" type="revolute">
        <origin xyz="0   -0.027109    0.070322" rpy="0 0 0"/>
        <parent link="T8"/>
        <child link="RightShoulder"/>
        <dynamics damping="0.1" friction="0.0"/>
        <limit effort="30" velocity="1.0" lower="-0.0872665" upper="0.785398" />
        <axis xyz="1 0 0" />
    </joint>
	<joint name="jRightShoulder_rotx" type="revolute">
        <origin xyz="0    -0.12989           0" rpy="0 0 0"/>
        <parent link="RightShoulder"/>
        <child link="RightUpperArm_f1"/>
        <dynamics damping="0.1" friction="0.0"/>
        <limit effort="30" velocity="1.0" lower="-2.35619" upper="1.5708" />
        <axis xyz="1 0 0" />
    </joint>
	<joint name="jRightShoulder_roty" type="revolute">
        <origin xyz="0 0 0" rpy="0 0 0"/>
        <parent link="RightUpperArm_f1"/>
        <child link="RightUpperArm_f2"/>
        <dynamics damping="0.1" friction="0.0"/>
        <limit effort="30" velocity="1.0" lower="-1.5708" upper="1.5708" />
        <axis xyz="0 1 0" />
    </joint>
    <joint name="jRightShoulder_rotz" type="revolute">
        <origin xyz="0 0 0" rpy="0 0 0"/>
        <parent link="RightUpperArm_f2"/>
        <child link="RightUpperArm"/>
        <dynamics damping="0.1" friction="0.0"/>
        <limit effort="30" velocity="1.0" lower="-0.785398" upper="3.14159" />
        <axis xyz="0 0 1" />
    </joint>
	<joint name="jRightElbow_roty" type="revolute">
        <origin xyz="0    -0.26995           0" rpy="0 0 0"/>
        <parent link="RightUpperArm"/>
        <child link="RightForeArm_f1"/>
        <dynamics damping="0.1" friction="0.0"/>
        <limit effort="30" velocity="1.0" lower="-1.5708" upper="1.48353" />
        <axis xyz="0 1 0" />
    </joint>
	<joint name="jRightElbow_rotz" type="revolute">
        <origin xyz="0 0 0" rpy="0 0 0"/>
        <parent link="RightForeArm_f1"/>
        <child link="RightForeArm"/>
        <dynamics damping="0.1" friction="0.0"/>
        <limit effort="30" velocity="1.0" lower="0" upper="2.53073" />
        <axis xyz="0 0 1" />
    </joint>
	<joint name="jRightWrist_rotx" type="revolute">
        <origin xyz="7.3e-05    -0.22237           0" rpy="0 0 0"/>
        <parent link="RightForeArm"/>
        <child link="RightHand_f1"/>
        <dynamics damping="0.1" friction="0.0"/>
        <limit effort="30" velocity="1.0" lower="-0.872665" upper="1.0472" />
        <axis xyz="1 0 0" />
    </joint>
	<joint name="jRightWrist_rotz" type="revolute">
        <origin xyz="0 0 0" rpy="0 0 0"/>
        <parent link="RightHand_f1"/>
        <child link="RightHand"/>
        <dynamics damping="0.1" friction="0.0"/>
        <limit effort="30" velocity="1.0" lower="-0.523599" upper="0.349066" />
        <axis xyz="0 0 1" />
    </joint>
	<!--Chain from (12) to (15)-->
	<joint name="jLeftC7Shoulder_rotx" type="revolute">
        <origin xyz="0    0.027109    0.070322" rpy="0 0 0"/>
        <parent link="T8"/>
        <child link="LeftShoulder"/>
        <dynamics damping="0.1" friction="0.0"/>
        <limit effort="30" velocity="1.0" lower="-0.0872665" upper="0.785398" />
        <axis xyz="1 0 0" />
    </joint>
	<joint name="jLeftShoulder_rotx" type="revolute">
        <origin xyz="0     0.12989           0" rpy="0 0 0"/>
        <parent link="LeftShoulder"/>
        <child link="LeftUpperArm_f1"/>
        <dynamics damping="0.1" friction="0.0"/>
        <limit effort="30" velocity="1.0" lower="-1.5708" upper="2.35619" />
        <axis xyz="1 0 0" />
    </joint>
	<joint name="jLeftShoulder_roty" type="revolute">
        <origin xyz="0 0 0" rpy="0 0 0"/>
        <parent link="LeftUpperArm_f1"/>
        <child link="LeftUpperArm_f2"/>
        <dynamics damping="0.1" friction="0.0"/>
        <limit effort="30" velocity="1.0" lower="-1.5708" upper="1.5708" />
        <axis xyz="0 1 0" />
    </joint>
    <joint name="jLeftShoulder_rotz" type="revolute">
        <origin xyz="0 0 0" rpy="0 0 0"/>
        <parent link="LeftUpperArm_f2"/>
        <child link="LeftUpperArm"/>
        <dynamics damping="0.1" friction="0.0"/>
        <limit effort="30" velocity="1.0" lower="-3.14159" upper="0.785398" />
        <axis xyz="0 0 1" />
    </joint>
    <joint name="jLeftElbow_roty" type="revolute">
        <origin xyz="0     0.26995           0" rpy="0 0 0"/>
        <parent link="LeftUpperArm"/>
        <child link="LeftForeArm_f1"/>
        <dynamics damping="0.1" friction="0.0"/>
        <limit effort="30" velocity="1.0" lower="-1.5708" upper="1.48353" />
        <axis xyz="0 1 0" />
    </joint>
    <joint name="jLeftElbow_rotz" type="revolute">
        <origin xyz="0 0 0" rpy="0 0 0"/>
        <parent link="LeftForeArm_f1"/>
        <child link="LeftForeArm"/>
        <dynamics damping="0.1" friction="0.0"/>
        <limit effort="30" velocity="1.0" lower="-2.53073" upper="0" />
        <axis xyz="0 0 1" />
    </joint>
	<joint name="jLeftWrist_rotx" type="revolute">
        <origin xyz="7.3e-05     0.22237           0" rpy="0 0 0"/>
        <parent link="LeftForeArm"/>
        <child link="LeftHand_f1"/>
        <dynamics damping="0.1" friction="0.0"/>
        <limit effort="30" velocity="1.0" lower="-1.0472" upper="0.872665" />
        <axis xyz="1 0 0" />
    </joint>
	<joint name="jLeftWrist_rotz" type="revolute">
        <origin xyz="0 0 0" rpy="0 0 0"/>
        <parent link="LeftHand_f1"/>
        <child link="LeftHand"/>
        <dynamics damping="0.1" friction="0.0"/>
        <limit effort="30" velocity="1.0" lower="-0.349066" upper="0.523599" />
        <axis xyz="0 0 1" />
    </joint>
	<!--Chain from (16) to (19)-->
	<joint name="jRightHip_rotx" type="revolute">
        <origin xyz="4.4e-05   -0.081879    0.000436" rpy="0 0 0"/>
        <parent link="Pelvis"/>
        <child link="RightUpperLeg_f1"/>
        <dynamics damping="0.1" friction="0.0"/>
        <limit effort="30" velocity="1.0" lower="-0.523599" upper="0.785398" />
        <axis xyz="1 0 0" />
    </joint>
	<joint name="jRightHip_roty" type="revolute">
        <origin xyz="0 0 0" rpy="0 0 0"/>
        <parent link="RightUpperLeg_f1"/>
        <child link="RightUpperLeg_f2"/>
        <dynamics damping="0.1" friction="0.0"/>
        <limit effort="30" velocity="1.0" lower="-0.261799" upper="2.0944" />
        <axis xyz="0 1 0" />
    </joint>
    <joint name="jRightHip_rotz" type="revolute">
        <origin xyz="0 0 0" rpy="0 0 0"/>
        <parent link="RightUpperLeg_f2"/>
        <child link="RightUpperLeg"/>
        <dynamics damping="0.1" friction="0.0"/>
        <limit effort="30" velocity="1.0" lower="-0.785398" upper="0.785398" />
        <axis xyz="0 0 1" />
    </joint>
	<joint name="jRightKnee_roty" type="revolute">
        <origin xyz="6.7e-05           0    -0.45113" rpy="0 0 0"/>
        <parent link="RightUpperLeg"/>
        <child link="RightLowerLeg_f1"/>
        <dynamics damping="0.1" friction="0.0"/>
        <limit effort="30" velocity="1.0" lower="0" upper="2.35619" />
        <axis xyz="0 1 0" />
    </joint>
	<joint name="jRightKnee_rotz" type="revolute">
        <origin xyz="0 0 0" rpy="0 0 0"/>
        <parent link="RightLowerLeg_f1"/>
        <child link="RightLowerLeg"/>
        <dynamics damping="0.1" friction="0.0"/>
        <limit effort="30" velocity="1.0" lower="-0.698132" upper="0.523599" />
        <axis xyz="0 0 1" />
    </joint>
	<joint name="jRightAnkle_rotx" type="revolute">
        <origin xyz="0.000289           0    -0.40628" rpy="0 0 0"/>
        <parent link="RightLowerLeg"/>
        <child link="RightFoot_f1"/>
        <dynamics damping="0.1" friction="0.0"/>
        <limit effort="30" velocity="1.0" lower="-0.610865" upper="0.785398" />
        <axis xyz="1 0 0" />
    </joint>
	<joint name="jRightAnkle_roty" type="revolute">
        <origin xyz="0 0 0" rpy="0 0 0"/>
        <parent link="RightFoot_f1"/>
        <child link="RightFoot_f2"/>
        <dynamics damping="0.1" friction="0.0"/>
        <limit effort="30" velocity="1.0" lower="-0.523599" upper="0.872665" />
        <axis xyz="0 1 0" />
    </joint>
    <joint name="jRightAnkle_rotz" type="revolute">
        <origin xyz="0 0 0" rpy="0 0 0"/>
        <parent link="RightFoot_f2"/>
        <child link="RightFoot"/>
        <dynamics damping="0.1" friction="0.0"/>
        <limit effort="30" velocity="1.0" lower="-0.436332" upper="0.872665" />
        <axis xyz="0 0 1" />
    </joint>
	<joint name="jRightBallFoot_roty" type="revolute">
        <origin xyz="0.14109           0    -0.10944" rpy="0 0 0"/>
        <parent link="RightFoot"/>
        <child link="RightToe"/>
        <dynamics damping="0.1" friction="0.0"/>
        <limit effort="30" velocity="1.0" lower="-0.174533" upper="1.5708" />
        <axis xyz="0 1 0" />
    </joint>
	<!--Chain from (20) to (23)-->
	<joint name="jLeftHip_rotx" type="revolute">
        <origin xyz="4.4e-05    0.081879    0.000436" rpy="0 0 0"/>
        <parent link="Pelvis"/>
        <child link="LeftUpperLeg_f1"/>
        <dynamics damping="0.1" friction="0.0"/>
        <limit effort="30" velocity="1.0" lower="-0.523599" upper="0.785398" />
        <axis xyz="1 0 0" />
    </joint>
	<joint name="jLeftHip_roty" type="revolute">
        <origin xyz="0 0 0" rpy="0 0 0"/>
        <parent link="LeftUpperLeg_f1"/>
        <child link="LeftUpperLeg_f2"/>
        <dynamics damping="0.1" friction="0.0"/>
        <limit effort="30" velocity="1.0" lower="-0.261799" upper="2.0944" />
        <axis xyz="0 1 0" />
    </joint>
    <joint name="jLeftHip_rotz" type="revolute">
        <origin xyz="0 0 0" rpy="0 0 0"/>
        <parent link="LeftUpperLeg_f2"/>
        <child link="LeftUpperLeg"/>
        <dynamics damping="0.1" friction="0.0"/>
        <limit effort="30" velocity="1.0" lower="-0.785398" upper="0.785398" />
        <axis xyz="0 0 1" />
    </joint>
	<joint name="jLeftKnee_roty" type="revolute">
        <origin xyz="6.7e-05           0    -0.45113" rpy="0 0 0"/>
        <parent link="LeftUpperLeg"/>
        <child link="LeftLowerLeg_f1"/>
        <dynamics damping="0.1" friction="0.0"/>
        <limit effort="30" velocity="1.0" lower="0" upper="2.35619" />
        <axis xyz="0 1 0" />
    </joint>
    <joint name="jLeftKnee_rotz" type="revolute">
        <origin xyz="0 0 0" rpy="0 0 0"/>
        <parent link="LeftLowerLeg_f1"/>
        <child link="LeftLowerLeg"/>
        <dynamics damping="0.1" friction="0.0"/>
        <limit effort="30" velocity="1.0" lower="-0.523599" upper="0.698132" />
        <axis xyz="0 0 1" />
    </joint>
	<joint name="jLeftAnkle_rotx" type="revolute">
        <origin xyz="0.000289           0    -0.40628" rpy="0 0 0"/>
        <parent link="LeftLowerLeg"/>
        <child link="LeftFoot_f1"/>
        <dynamics damping="0.1" friction="0.0"/>
        <limit effort="30" velocity="1.0" lower="-0.610865" upper="0.785398" />
        <axis xyz="1 0 0" />
    </joint>
	<joint name="jLeftAnkle_roty" type="revolute">
        <origin xyz="0 0 0" rpy="0 0 0"/>
        <parent link="LeftFoot_f1"/>
        <child link="LeftFoot_f2"/>
        <dynamics damping="0.1" friction="0.0"/>
        <limit effort="30" velocity="1.0" lower="-0.523599" upper="0.872665" />
        <axis xyz="0 1 0" />
    </joint>
    <joint name="jLeftAnkle_rotz" type="revolute">
        <origin xyz="0 0 0" rpy="0 0 0"/>
        <parent link="LeftFoot_f2"/>
        <child link="LeftFoot"/>
        <dynamics damping="0.1" friction="0.0"/>
        <limit effort="30" velocity="1.0" lower="-0.872665" upper="0.436332" />
        <axis xyz="0 0 1" />
    </joint>
	<joint name="jLeftBallFoot_roty" type="revolute">
        <origin xyz="0.14109           0    -0.10944" rpy="0 0 0"/>
        <parent link="LeftFoot"/>
        <child link="LeftToe"/>
        <dynamics damping="0.1" friction="0.0"/>
        <limit effort="30" velocity="1.0" lower="-0.174533" upper="1.5708" />
        <axis xyz="0 1 0" />
    </joint>

	<!--Insert sensors here, if any.-->

</robot>


</robot>
