<robot name="ICUB_2-5_BB_SIM_MODEL">
  <link name="root_link">
    <inertial>
      <origin xyz="0.0248821 0.000103947 -0.0440806" rpy="1.57079632679 0 -1.57079632679"/>
      <mass value="5.09143"/>
      <inertia ixx="0.0139679" ixy="-5.93488e-06" ixz="-1.55458e-05" iyy="0.0202112" iyz="-0.00170968" izz="0.0249124"/>
    </inertial>
    <visual>
      <origin xyz="-0.0364 0 0.032" rpy="1.57079632679 0 -1.57079632679"/>
      <geometry>
        <mesh filename="package://testbot_description/meshes/dae/sim_sea_2-5_root_link_prt-binary.stl" scale="0.001 0.001 0.001"/>
      </geometry>
      <material name="purple">
        <color rgba="0.568 0.372 0.941 1"/>
      </material>
    </visual>
    <collision>
      <origin xyz="-0.0364 0 0.032" rpy="1.57079632679 0 -1.57079632679"/>
      <geometry>
        <mesh filename="package://testbot_description/meshes/dae/sim_sea_2-5_root_link_prt-binary.stl" scale="0.001 0.001 0.001"/>
      </geometry>
    </collision>
  </link>
  <link name="root_link_ems_acc_eb5"/>
  <joint name="root_link_ems_acc_eb5_fixed_joint" type="fixed">
    <origin xyz="0.0493308 -0.0125771 -0.115691" rpy="3.14159265359 1.29154404503 3.14159265359"/>
    <parent link="root_link"/>
    <child link="root_link_ems_acc_eb5"/>
    <dynamics damping="0.1"/>
  </joint>
  <link name="root_link_ems_gyro_eb5"/>
  <joint name="root_link_ems_gyro_eb5_fixed_joint" type="fixed">
    <origin xyz="0.0493308 -0.0125771 -0.115691" rpy="3.14159265359 1.29154404503 3.14159265359"/>
    <parent link="root_link"/>
    <child link="root_link_ems_gyro_eb5"/>
    <dynamics damping="0.1"/>
  </joint>
  <link name="r_hip_1">
    <inertial>
      <origin xyz="-0.040711 -5.9e-05 -0.0005234" rpy="0 0 0"/>
      <mass value="0.920101"/>
      <inertia ixx="0.000411114" ixy="-3.6672e-06" ixz="3.58037e-07" iyy="0.000576521" iyz="-2.19976e-06" izz="0.000587325"/>
    </inertial>
    <visual>
      <origin xyz="0.0233655 0.151913 0.0428515000001" rpy="0 0 0"/>
      <geometry>
        <mesh filename="package://testbot_description/meshes/dae/sim_sea_2-5_r_hip_1_prt-binary.stl" scale="0.001 0.001 0.001"/>
      </geometry>
      <material name="metal">
        <color rgba="0.486 0.651 0.8 1"/>
      </material>
    </visual>
    <collision>
      <origin xyz="0.0233655 0.151913 0.0428515000001" rpy="0 0 0"/>
      <geometry>
        <mesh filename="package://testbot_description/meshes/dae/sim_sea_2-5_r_hip_1_prt-binary.stl" scale="0.001 0.001 0.001"/>
      </geometry>
    </collision>
  </link>
  <joint name="r_hip_pitch" type="revolute">
    <origin xyz="0.0064515 0.0233655 -0.119913" rpy="1.57079632679 0 -1.57079632679"/>
    <axis xyz="-1.0 0.0 0.0"/>
    <parent link="root_link"/>
    <child link="r_hip_1"/>
    <limit effort="50000" lower="-0.523598775598" upper="1.4835298642" velocity="50000"/>
    <dynamics damping="0.223"/>
  </joint>
  <link name="r_hip_2">
    <inertial>
      <origin xyz="3.49999999999e-06 -0.044233 0.0248982" rpy="0 0 0"/>
      <mass value="0.4194"/>
      <inertia ixx="0.00048916" ixy="-2.70159e-07" ixz="1.85233e-07" iyy="0.00028697" iyz="1.28773e-05" izz="0.000315599"/>
    </inertial>
    <visual>
      <origin xyz="0.0701 0.151913 0.0691961998094" rpy="0 0 0"/>
      <geometry>
        <mesh filename="package://testbot_description/meshes/dae/sim_sea_2-5_r_hip_2_prt-binary.stl" scale="0.001 0.001 0.001"/>
      </geometry>
      <material name="metal" />
    </visual>
    <collision>
      <origin xyz="0.0701 0.151913 0.0691961998094" rpy="0 0 0"/>
      <geometry>
        <mesh filename="package://testbot_description/meshes/dae/sim_sea_2-5_r_hip_2_prt-binary.stl" scale="0.001 0.001 0.001"/>
      </geometry>
    </collision>
  </link>
  <joint name="r_hip_roll" type="revolute">
    <origin xyz="-0.0467345 0 -0.0263447" rpy="0 0 0"/>
    <axis xyz="0.0 0.0 -1.0"/>
    <parent link="r_hip_1"/>
    <child link="r_hip_2"/>
    <limit effort="50000" lower="0.0" upper="1.57079632679" velocity="50000"/>
    <dynamics damping="0.223"/>
  </joint>
  <link name="r_hip_3">
    <inertial>
      <origin xyz="-0.000123 -0.0002823 0.008718" rpy="-1.57079632679 0 -1.57079632679"/>
      <mass value="0.126212"/>
      <inertia ixx="3.27938e-05" ixy="2.67901e-07" ixz="-4.41463e-09" iyy="5.69957e-05" iyz="3.32338e-08" izz="3.26449e-05"/>
    </inertial>
    <visual>
      <origin xyz="0.0437089998094 -0.0701 -0.226213" rpy="-1.57079632679 0 -1.57079632679"/>
      <geometry>
        <mesh filename="package://testbot_description/meshes/dae/sim_sea_2-5_r_upper_thigh_prt-binary.stl" scale="0.001 0.001 0.001"/>
      </geometry>
      <material name="metal" />
    </visual>
    <collision>
      <origin xyz="0.0437089998094 -0.0701 -0.226213" rpy="-1.57079632679 0 -1.57079632679"/>
      <geometry>
        <mesh filename="package://testbot_description/meshes/dae/sim_sea_2-5_r_upper_thigh_prt-binary.stl" scale="0.001 0.001 0.001"/>
      </geometry>
    </collision>
  </link>
  <joint name="r_leg_ft_sensor" type="fixed">
    <origin xyz="0 -0.0743 0.0254872" rpy="1.57079632679 -1.57079632679 0"/>
    <parent link="r_hip_2"/>
    <child link="r_hip_3"/>
    <dynamics damping="0.1"/>
  </joint>
  <link name="r_upper_leg">
    <inertial>
      <origin xyz="-7.67e-05 -0.078866 0.0033612" rpy="0 0 0"/>
      <mass value="1.8035"/>
      <inertia ixx="0.00646378343182" ixy="0.000122685853522" ixz="4.94531545868e-06" iyy="0.00144539832219" iyz="-0.000137533175718" izz="0.00645582688618"/>
    </inertial>
    <visual>
      <origin xyz="0.0701 0.241013 0.0437089998094" rpy="0 0 0"/>
      <geometry>
        <mesh filename="package://testbot_description/meshes/dae/sim_sea_2-5_r_thigh_prt-binary.stl" scale="0.001 0.001 0.001"/>
      </geometry>
      <material name="purple" />
    </visual>
    <collision>
      <origin xyz="0.0701 0.241013 0.0437089998094" rpy="0 0 0"/>
      <geometry>
        <mesh filename="package://testbot_description/meshes/dae/sim_sea_2-5_r_thigh_prt-binary.stl" scale="0.001 0.001 0.001"/>
      </geometry>
    </collision>
  </link>
  <joint name="r_hip_yaw" type="revolute">
    <origin xyz="0 0 0.0146" rpy="-1.57079632679 0 -1.57079632679"/>
    <axis xyz="0.0 -1.0 0.0"/>
    <parent link="r_hip_3"/>
    <child link="r_upper_leg"/>
    <limit effort="50000" lower="-1.2217304764" upper="1.2217304764" velocity="50000"/>
    <dynamics damping="0.223"/>
  </joint>
  <link name="r_upper_leg_ems_acc_eb8"/>
  <joint name="r_upper_leg_ems_acc_eb8_fixed_joint" type="fixed">
    <origin xyz="0.0404072 -0.040027 -0.0125751" rpy="1.57079632679 0 -1.57079632679"/>
    <parent link="r_upper_leg"/>
    <child link="r_upper_leg_ems_acc_eb8"/>
    <dynamics damping="0.1"/>
  </joint>
  <link name="r_upper_leg_ems_acc_eb11"/>
  <joint name="r_upper_leg_ems_acc_eb11_fixed_joint" type="fixed">
    <origin xyz="-0.040407 -0.083207 -0.0125771" rpy="1.57079632679 0 -1.57079632679"/>
    <parent link="r_upper_leg"/>
    <child link="r_upper_leg_ems_acc_eb11"/>
    <dynamics damping="0.1"/>
  </joint>
  <link name="r_upper_leg_ems_gyro_eb8"/>
  <joint name="r_upper_leg_ems_gyro_eb8_fixed_joint" type="fixed">
    <origin xyz="0.0404072 -0.035455 -0.013079" rpy="1.57079632679 0 -1.57079632679"/>
    <parent link="r_upper_leg"/>
    <child link="r_upper_leg_ems_gyro_eb8"/>
    <dynamics damping="0.1"/>
  </joint>
  <link name="r_upper_leg_ems_gyro_eb11"/>
  <joint name="r_upper_leg_ems_gyro_eb11_fixed_joint" type="fixed">
    <origin xyz="-0.040407 -0.087779 -0.013081" rpy="1.57079632679 0 -1.57079632679"/>
    <parent link="r_upper_leg"/>
    <child link="r_upper_leg_ems_gyro_eb11"/>
    <dynamics damping="0.1"/>
  </joint>
  <link name="r_upper_leg_mtb_acc_11b1"/>
  <joint name="r_upper_leg_mtb_acc_11b1_fixed_joint" type="fixed">
    <origin xyz="-0.030195 0.04914 0.043588612" rpy="-0.837758053858 -0.000342790749344 1.57087401652"/>
    <parent link="r_upper_leg"/>
    <child link="r_upper_leg_mtb_acc_11b1"/>
    <dynamics damping="0.1"/>
  </joint>
  <link name="r_upper_leg_mtb_acc_11b2"/>
  <joint name="r_upper_leg_mtb_acc_11b2_fixed_joint" type="fixed">
    <origin xyz="-0.0064065 0.039256 0.0539467" rpy="-0.261799341927 -0.000399050135154 1.57090848318"/>
    <parent link="r_upper_leg"/>
    <child link="r_upper_leg_mtb_acc_11b2"/>
    <dynamics damping="0.1"/>
  </joint>
  <link name="r_upper_leg_mtb_acc_11b3"/>
  <joint name="r_upper_leg_mtb_acc_11b3_fixed_joint" type="fixed">
    <origin xyz="-0.0130214 0.004186 0.0538313" rpy="0 -0.000429089990594 1.57091244355"/>
    <parent link="r_upper_leg"/>
    <child link="r_upper_leg_mtb_acc_11b3"/>
    <dynamics damping="0.1"/>
  </joint>
  <link name="r_upper_leg_mtb_acc_11b4"/>
  <joint name="r_upper_leg_mtb_acc_11b4_fixed_joint" type="fixed">
    <origin xyz="0.0422675 -0.004845 0.0322719" rpy="1.18682375086 -0.000536853726193 1.57083983106"/>
    <parent link="r_upper_leg"/>
    <child link="r_upper_leg_mtb_acc_11b4"/>
    <dynamics damping="0.1"/>
  </joint>
  <link name="r_upper_leg_mtb_acc_11b5"/>
  <joint name="r_upper_leg_mtb_acc_11b5_fixed_joint" type="fixed">
    <origin xyz="0.0164786 0.004186 0.0538313" rpy="0 -0.000429089990594 1.57091244355"/>
    <parent link="r_upper_leg"/>
    <child link="r_upper_leg_mtb_acc_11b5"/>
    <dynamics damping="0.1"/>
  </joint>
  <link name="r_upper_leg_mtb_acc_11b6"/>
  <joint name="r_upper_leg_mtb_acc_11b6_fixed_joint" type="fixed">
    <origin xyz="-0.0157594 -0.026365 -0.0437518" rpy="3.14159265359 0.000429089993416 -1.57079632679"/>
    <parent link="r_upper_leg"/>
    <child link="r_upper_leg_mtb_acc_11b6"/>
    <dynamics damping="0.1"/>
  </joint>
  <link name="r_upper_leg_mtb_acc_11b7"/>
  <joint name="r_upper_leg_mtb_acc_11b7_fixed_joint" type="fixed">
    <origin xyz="0.0162386 -0.026366 -0.0437518" rpy="3.14159260377 0.000429089990404 -1.57091243007"/>
    <parent link="r_upper_leg"/>
    <child link="r_upper_leg_mtb_acc_11b7"/>
    <dynamics damping="0.1"/>
  </joint>
  <link name="r_lower_leg">
    <inertial>
      <origin xyz="0.0060664 -0.088843 0.0011052" rpy="0 0 0"/>
      <mass value="1.472"/>
      <inertia ixx="0.00424220933661" ixy="0.000229531990172" ixz="-5.53606289926e-05" iyy="0.00151220835381" iyz="-0.000260873906634" izz="0.00457765110565"/>
    </inertial>
    <visual>
      <origin xyz="0.0797675001907 0.386638 0.0437089998093" rpy="0 0 0"/>
      <geometry>
        <mesh filename="package://testbot_description/meshes/dae/sim_sea_2-5_r_shank_prt-binary.stl" scale="0.001 0.001 0.001"/>
      </geometry>
      <material name="purple" />
    </visual>
    <collision>
      <origin xyz="0.0797675001907 0.386638 0.0437089998093" rpy="0 0 0"/>
      <geometry>
        <mesh filename="package://testbot_description/meshes/dae/sim_sea_2-5_r_shank_prt-binary.stl" scale="0.001 0.001 0.001"/>
      </geometry>
    </collision>
  </link>
  <joint name="r_knee" type="revolute">
    <origin xyz="-0.0096675 -0.145625 0" rpy="0 0 0"/>
    <axis xyz="-1.0 0.0 0.0"/>
    <parent link="r_upper_leg"/>
    <child link="r_lower_leg"/>
    <limit effort="50000" lower="-1.74532925199" upper="0.0" velocity="50000"/>
    <dynamics damping="0.223"/>
  </joint>
  <link name="r_lower_leg_ems_acc_eb9"/>
  <joint name="r_lower_leg_ems_acc_eb9_fixed_joint" type="fixed">
    <origin xyz="0.0235071 -0.092765 0.04351373" rpy="0 -0.218166543341 1.57079632679"/>
    <parent link="r_lower_leg"/>
    <child link="r_lower_leg_ems_acc_eb9"/>
    <dynamics damping="0.1"/>
  </joint>
  <link name="r_lower_leg_ems_gyro_eb9"/>
  <joint name="r_lower_leg_ems_gyro_eb9_fixed_joint" type="fixed">
    <origin xyz="0.024011 -0.088301 0.044503292" rpy="0 -0.218166543341 1.57079632679"/>
    <parent link="r_lower_leg"/>
    <child link="r_lower_leg_ems_gyro_eb9"/>
    <dynamics damping="0.1"/>
  </joint>
  <link name="r_lower_leg_mtb_acc_11b8"/>
  <joint name="r_lower_leg_mtb_acc_11b8_fixed_joint" type="fixed">
    <origin xyz="-0.0055283 -0.004318 0.05362922" rpy="-0.244346164565 2.80911040962e-05 1.57090899435"/>
    <parent link="r_lower_leg"/>
    <child link="r_lower_leg_mtb_acc_11b8"/>
    <dynamics damping="0.1"/>
  </joint>
  <link name="r_lower_leg_mtb_acc_11b9"/>
  <joint name="r_lower_leg_mtb_acc_11b9_fixed_joint" type="fixed">
    <origin xyz="0.0253904 -0.004318 0.0537517" rpy="0.349065638045 -3.97141037841e-05 1.57090544048"/>
    <parent link="r_lower_leg"/>
    <child link="r_lower_leg_mtb_acc_11b9"/>
    <dynamics damping="0.1"/>
  </joint>
  <link name="r_lower_leg_mtb_acc_11b10"/>
  <joint name="r_lower_leg_mtb_acc_11b10_fixed_joint" type="fixed">
    <origin xyz="-0.0325465 -0.043468 0.0278945" rpy="-1.30899714732 0 1.57079632679"/>
    <parent link="r_lower_leg"/>
    <child link="r_lower_leg_mtb_acc_11b10"/>
    <dynamics damping="0.1"/>
  </joint>
  <link name="r_lower_leg_mtb_acc_11b11"/>
  <joint name="r_lower_leg_mtb_acc_11b11_fixed_joint" type="fixed">
    <origin xyz="0.0519165 -0.092958 0.0164801" rpy="1.30899714594 -0.000112159802878 1.57082638021"/>
    <parent link="r_lower_leg"/>
    <child link="r_lower_leg_mtb_acc_11b11"/>
    <dynamics damping="0.1"/>
  </joint>
  <link name="r_ankle_1">
    <inertial>
      <origin xyz="0.0276282 6.29999999999e-05 0.0152507" rpy="0 0 0"/>
      <mass value="0.6803"/>
      <inertia ixx="0.000405201087095" ixy="7.4060158032e-07" ixz="-3.03314661581e-05" iyy="0.000449108136626" iyz="2.88975725979e-06" izz="0.000310063350592"/>
    </inertial>
    <visual>
      <origin xyz="0.0986000001907 0.587138 0.0437089998093" rpy="0 0 0"/>
      <geometry>
        <mesh filename="package://testbot_description/meshes/dae/sim_sea_2-5_r_ankle_prt-binary.stl" scale="0.001 0.001 0.001"/>
      </geometry>
      <material name="metal" />
    </visual>
    <collision>
      <origin xyz="0.0986000001907 0.587138 0.0437089998093" rpy="0 0 0"/>
      <geometry>
        <mesh filename="package://testbot_description/meshes/dae/sim_sea_2-5_r_ankle_prt-binary.stl" scale="0.001 0.001 0.001"/>
      </geometry>
    </collision>
  </link>
  <joint name="r_ankle_pitch" type="revolute">
    <origin xyz="-0.0188325 -0.2005 0" rpy="0 0 0"/>
    <axis xyz="1.0 0.0 0.0"/>
    <parent link="r_lower_leg"/>
    <child link="r_ankle_1"/>
    <limit effort="50000" lower="-0.349065850399" upper="0.523598775598" velocity="50000"/>
    <dynamics damping="0.223"/>
  </joint>
  <link name="r_ankle_2">
    <inertial>
      <origin xyz="-8.2e-06 -0.038202 0.0192673" rpy="0 0 0"/>
      <mass value="0.267485"/>
      <inertia ixx="0.000335682" ixy="-7.53335e-08" ixz="2.93681e-08" iyy="0.00025387" iyz="-4.26218e-07" izz="0.000154833"/>
    </inertial>
    <visual>
      <origin xyz="0.0701000001907 0.587138 0.0622089996185" rpy="0 0 0"/>
      <geometry>
        <mesh filename="package://testbot_description/meshes/dae/sim_sea_2-5_r_foot_prt-binary.stl" scale="0.001 0.001 0.001"/>
      </geometry>
      <material name="metal" />
    </visual>
    <collision>
      <origin xyz="0.0701000001907 0.587138 0.0622089996185" rpy="0 0 0"/>
      <geometry>
        <mesh filename="package://testbot_description/meshes/dae/sim_sea_2-5_r_foot_prt-binary.stl" scale="0.001 0.001 0.001"/>
      </geometry>
    </collision>
  </link>
  <joint name="r_ankle_roll" type="revolute">
    <origin xyz="0.0285 0 -0.0185" rpy="0 0 0"/>
    <axis xyz="0.0 0.0 -1.0"/>
    <parent link="r_ankle_1"/>
    <child link="r_ankle_2"/>
    <limit effort="50000" lower="-0.349065850399" upper="0.349065850399" velocity="50000"/>
    <dynamics damping="0.223"/>
  </joint>
  <link name="r_foot">
    <inertial>
      <origin xyz="0.0336237 0.0053646 -0.001138" rpy="-1.57079632679 0 -1.57079632679"/>
      <mass value="0.38227"/>
      <inertia ixx="0.00120765" ixy="3.70545e-07" ixz="-5.78137e-05" iyy="0.00141242" iyz="-7.82502e-06" izz="0.000273419"/>
    </inertial>
    <visual>
      <origin xyz="0.0472089996185 -0.0701000001907 -0.647438" rpy="-1.57079632679 0 -1.57079632679"/>
      <geometry>
        <mesh filename="package://testbot_description/meshes/dae/sim_sea_2-5_r_sole_prt-binary.stl" scale="0.001 0.001 0.001"/>
      </geometry>
      <material name="black">
        <color rgba="0.235 0 0.411 1"/>
      </material>
    </visual>
    <collision>
      <origin xyz="0.0472089996185 -0.0701000001907 -0.647438" rpy="-1.57079632679 0 -1.57079632679"/>
      <geometry>
        <mesh filename="package://testbot_description/meshes/dae/sim_sea_2-5_r_sole_prt-binary.stl" scale="0.001 0.001 0.001"/>
      </geometry>
    </collision>
  </link>
  <joint name="r_foot_ft_sensor" type="fixed">
    <origin xyz="0 -0.0603 0.015" rpy="1.57079632679 -1.57079632679 0"/>
    <parent link="r_ankle_2"/>
    <child link="r_foot"/>
    <dynamics damping="0.1"/>
  </joint>
  <link name="r_foot_mtb_acc_11b12"/>
  <joint name="r_foot_mtb_acc_11b12_fixed_joint" type="fixed">
    <origin xyz="0.1034744 -0.000807 -0.001215" rpy="0 0 -1.57079632679"/>
    <parent link="r_foot"/>
    <child link="r_foot_mtb_acc_11b12"/>
    <dynamics damping="0.1"/>
  </joint>
  <link name="r_foot_mtb_acc_11b13"/>
  <joint name="r_foot_mtb_acc_11b13_fixed_joint" type="fixed">
    <origin xyz="0.0784744 -0.0118072 -0.001215" rpy="0 0 -1.57079632679"/>
    <parent link="r_foot"/>
    <child link="r_foot_mtb_acc_11b13"/>
    <dynamics damping="0.1"/>
  </joint>
  <link name="r_sole"/>
  <joint name="r_sole_fixed_joint" type="fixed">
    <origin xyz="0.0035 0 0.004" rpy="-3.14159265359 0 0"/>
    <parent link="r_foot"/>
    <child link="r_sole"/>
    <dynamics damping="0.1"/>
  </joint>
  <link name="l_hip_1">
    <inertial>
      <origin xyz="0.041678 -6.3e-05 -0.0004013" rpy="0 0 0"/>
      <mass value="0.915608"/>
      <inertia ixx="0.000402555" ixy="1.07708e-06" ixz="-1.569e-06" iyy="0.000570806" iyz="-6.5378e-07" izz="0.00057937"/>
    </inertial>
    <visual>
      <origin xyz="-0.0223861 0.151913 0.0428515000001" rpy="0 0 0"/>
      <geometry>
        <mesh filename="package://testbot_description/meshes/dae/sim_sea_2-5_l_hip_1_prt-binary.stl" scale="0.001 0.001 0.001"/>
      </geometry>
      <material name="metal" />
    </visual>
    <collision>
      <origin xyz="-0.0223861 0.151913 0.0428515000001" rpy="0 0 0"/>
      <geometry>
        <mesh filename="package://testbot_description/meshes/dae/sim_sea_2-5_l_hip_1_prt-binary.stl" scale="0.001 0.001 0.001"/>
      </geometry>
    </collision>
  </link>
  <joint name="l_hip_pitch" type="revolute">
    <origin xyz="0.0064515 -0.0223861 -0.119913" rpy="1.57079632679 0 -1.57079632679"/>
    <axis xyz="-1.0 0.0 0.0"/>
    <parent link="root_link"/>
    <child link="l_hip_1"/>
    <limit effort="50000" lower="-0.523598775598" upper="1.4835298642" velocity="50000"/>
    <dynamics damping="0.223"/>
  </joint>
  <link name="l_hip_2">
    <inertial>
      <origin xyz="-1.94e-05 -0.044047 0.0239587" rpy="0 0 0"/>
      <mass value="0.421161"/>
      <inertia ixx="0.000494475" ixy="1.54783e-07" ixz="-1.86267e-07" iyy="0.000288821" iyz="1.53903e-05" izz="0.000319114"/>
    </inertial>
    <visual>
      <origin xyz="-0.0701 0.151913 0.0683914998093" rpy="0 0 0"/>
      <geometry>
        <mesh filename="package://testbot_description/meshes/dae/sim_sea_2-5_l_hip_2_prt-binary.stl" scale="0.001 0.001 0.001"/>
      </geometry>
      <material name="metal" />
    </visual>
    <collision>
      <origin xyz="-0.0701 0.151913 0.0683914998093" rpy="0 0 0"/>
      <geometry>
        <mesh filename="package://testbot_description/meshes/dae/sim_sea_2-5_l_hip_2_prt-binary.stl" scale="0.001 0.001 0.001"/>
      </geometry>
    </collision>
  </link>
  <joint name="l_hip_roll" type="revolute">
    <origin xyz="0.0477139 0 -0.02554" rpy="0 0 0"/>
    <axis xyz="0.0 0.0 1.0"/>
    <parent link="l_hip_1"/>
    <child link="l_hip_2"/>
    <limit effort="50000" lower="0.0" upper="1.57079632679" velocity="50000"/>
    <dynamics damping="0.223"/>
  </joint>
  <link name="l_hip_3">
    <inertial>
      <origin xyz="0.0002823 -0.0001229 0.008718" rpy="-1.57079632679 0 0"/>
      <mass value="0.126212"/>
      <inertia ixx="3.27938e-05" ixy="2.67901e-07" ixz="-4.41463e-09" iyy="5.69957e-05" iyz="3.32338e-08" izz="3.26449e-05"/>
    </inertial>
    <visual>
      <origin xyz="-0.0701 0.043709 -0.226213" rpy="-1.57079632679 0 0"/>
      <geometry>
        <mesh filename="package://testbot_description/meshes/dae/sim_sea_2-5_l_upper_thigh_prt-binary.stl" scale="0.001 0.001 0.001"/>
      </geometry>
      <material name="metal" />
    </visual>
    <collision>
      <origin xyz="-0.0701 0.043709 -0.226213" rpy="-1.57079632679 0 0"/>
      <geometry>
        <mesh filename="package://testbot_description/meshes/dae/sim_sea_2-5_l_upper_thigh_prt-binary.stl" scale="0.001 0.001 0.001"/>
      </geometry>
    </collision>
  </link>
  <joint name="l_leg_ft_sensor" type="fixed">
    <origin xyz="0 -0.0743 0.0246825" rpy="1.57079632679 -1.57079632679 0"/>
    <parent link="l_hip_2"/>
    <child link="l_hip_3"/>
    <dynamics damping="0.1"/>
  </joint>
  <link name="l_upper_leg">
    <inertial>
      <origin xyz="0.0001504 -0.078827 0.0033485" rpy="0 0 0"/>
      <mass value="1.8084"/>
      <inertia ixx="0.00647124065718" ixy="-0.000117510769467" ixz="-3.57294757981e-06" iyy="0.00144843621276" iyz="-0.000137708519804" izz="0.00646464360719"/>
    </inertial>
    <visual>
      <origin xyz="-0.0701 0.241013 0.0437089998093" rpy="0 0 0"/>
      <geometry>
        <mesh filename="package://testbot_description/meshes/dae/sim_sea_2-5_l_thigh_prt-binary.stl" scale="0.001 0.001 0.001"/>
      </geometry>
      <material name="purple" />
    </visual>
    <collision>
      <origin xyz="-0.0701 0.241013 0.0437089998093" rpy="0 0 0"/>
      <geometry>
        <mesh filename="package://testbot_description/meshes/dae/sim_sea_2-5_l_thigh_prt-binary.stl" scale="0.001 0.001 0.001"/>
      </geometry>
    </collision>
  </link>
  <joint name="l_hip_yaw" type="revolute">
    <origin xyz="0 0 0.0146" rpy="-1.57079632679 0 -1.57079632679"/>
    <axis xyz="0.0 1.0 0.0"/>
    <parent link="l_hip_3"/>
    <child link="l_upper_leg"/>
    <limit effort="50000" lower="-1.2217304764" upper="1.2217304764" velocity="50000"/>
    <dynamics damping="0.223"/>
  </joint>
  <link name="l_upper_leg_ems_acc_eb6"/>
  <joint name="l_upper_leg_ems_acc_eb6_fixed_joint" type="fixed">
    <origin xyz="-0.0404072 -0.083207 -0.0125771" rpy="1.57079632679 0 -1.57079632679"/>
    <parent link="l_upper_leg"/>
    <child link="l_upper_leg_ems_acc_eb6"/>
    <dynamics damping="0.1"/>
  </joint>
  <link name="l_upper_leg_ems_acc_eb10"/>
  <joint name="l_upper_leg_ems_acc_eb10_fixed_joint" type="fixed">
    <origin xyz="0.040407 -0.040027 -0.0125751" rpy="1.57079632679 0 1.57079632679"/>
    <parent link="l_upper_leg"/>
    <child link="l_upper_leg_ems_acc_eb10"/>
    <dynamics damping="0.1"/>
  </joint>
  <link name="l_upper_leg_ems_gyro_eb6"/>
  <joint name="l_upper_leg_ems_gyro_eb6_fixed_joint" type="fixed">
    <origin xyz="-0.0404072 -0.087779 -0.013081" rpy="1.57079632679 0 -1.57079632679"/>
    <parent link="l_upper_leg"/>
    <child link="l_upper_leg_ems_gyro_eb6"/>
    <dynamics damping="0.1"/>
  </joint>
  <link name="l_upper_leg_ems_gyro_eb10"/>
  <joint name="l_upper_leg_ems_gyro_eb10_fixed_joint" type="fixed">
    <origin xyz="0.040407 -0.035455 -0.013079" rpy="1.57079632679 0 1.57079632679"/>
    <parent link="l_upper_leg"/>
    <child link="l_upper_leg_ems_gyro_eb10"/>
    <dynamics damping="0.1"/>
  </joint>
  <link name="l_upper_leg_mtb_acc_10b1"/>
  <joint name="l_upper_leg_mtb_acc_10b1_fixed_joint" type="fixed">
    <origin xyz="0.031565 0.049332 0.04200163" rpy="0.837758036961 -8.62912829653e-05 1.57087402394"/>
    <parent link="l_upper_leg"/>
    <child link="l_upper_leg_mtb_acc_10b1"/>
    <dynamics damping="0.1"/>
  </joint>
  <link name="l_upper_leg_mtb_acc_10b2"/>
  <joint name="l_upper_leg_mtb_acc_10b2_fixed_joint" type="fixed">
    <origin xyz="0.0083839 0.039452 0.05335544" rpy="0.261799318135 -3.00531353284e-05 1.57090848663"/>
    <parent link="l_upper_leg"/>
    <child link="l_upper_leg_mtb_acc_10b2"/>
    <dynamics damping="0.1"/>
  </joint>
  <link name="l_upper_leg_mtb_acc_10b3"/>
  <joint name="l_upper_leg_mtb_acc_10b3_fixed_joint" type="fixed">
    <origin xyz="0.0150706 0.004382 0.053785" rpy="0 0 1.57079632679"/>
    <parent link="l_upper_leg"/>
    <child link="l_upper_leg_mtb_acc_10b3"/>
    <dynamics damping="0.1"/>
  </joint>
  <link name="l_upper_leg_mtb_acc_10b4"/>
  <joint name="l_upper_leg_mtb_acc_10b4_fixed_joint" type="fixed">
    <origin xyz="-0.0144294 0.004382 0.053785" rpy="0 0 1.57079632679"/>
    <parent link="l_upper_leg"/>
    <child link="l_upper_leg_mtb_acc_10b4"/>
    <dynamics damping="0.1"/>
  </joint>
  <link name="l_upper_leg_mtb_acc_10b5"/>
  <joint name="l_upper_leg_mtb_acc_10b5_fixed_joint" type="fixed">
    <origin xyz="-0.0414999 -0.004658 0.03412949" rpy="-1.18682376254 0 1.57079632679"/>
    <parent link="l_upper_leg"/>
    <child link="l_upper_leg_mtb_acc_10b5"/>
    <dynamics damping="0.1"/>
  </joint>
  <link name="l_upper_leg_mtb_acc_10b6"/>
  <joint name="l_upper_leg_mtb_acc_10b6_fixed_joint" type="fixed">
    <origin xyz="0.0178086 -0.026212 -0.043785" rpy="3.14159265359 0 -1.57091243005"/>
    <parent link="l_upper_leg"/>
    <child link="l_upper_leg_mtb_acc_10b6"/>
    <dynamics damping="0.1"/>
  </joint>
  <link name="l_upper_leg_mtb_acc_10b7"/>
  <joint name="l_upper_leg_mtb_acc_10b7_fixed_joint" type="fixed">
    <origin xyz="-0.0141918 -0.026211 -0.043785" rpy="3.14159265359 0 -1.5709453147"/>
    <parent link="l_upper_leg"/>
    <child link="l_upper_leg_mtb_acc_10b7"/>
    <dynamics damping="0.1"/>
  </joint>
  <link name="l_lower_leg">
    <inertial>
      <origin xyz="0.0171669 -0.088615 0.000868" rpy="0 0 0"/>
      <mass value="1.4724"/>
      <inertia ixx="0.00423934701934" ixy="-0.000240090908858" ixz="6.75754833624e-05" iyy="0.00151341335811" iyz="-0.000229787246191" izz="0.00457420033003"/>
    </inertial>
    <visual>
      <origin xyz="-0.0565145001907 0.386638 0.0437089998093" rpy="0 0 0"/>
      <geometry>
        <mesh filename="package://testbot_description/meshes/dae/sim_sea_2-5_l_shank_prt-binary.stl" scale="0.001 0.001 0.001"/>
      </geometry>
      <material name="purple" />
    </visual>
    <collision>
      <origin xyz="-0.0565145001907 0.386638 0.0437089998093" rpy="0 0 0"/>
      <geometry>
        <mesh filename="package://testbot_description/meshes/dae/sim_sea_2-5_l_shank_prt-binary.stl" scale="0.001 0.001 0.001"/>
      </geometry>
    </collision>
  </link>
  <joint name="l_knee" type="revolute">
    <origin xyz="-0.0135855 -0.145625 0" rpy="0 0 0"/>
    <axis xyz="-1.0 0.0 0.0"/>
    <parent link="l_upper_leg"/>
    <child link="l_lower_leg"/>
    <limit effort="50000" lower="-1.74532925199" upper="0.0" velocity="50000"/>
    <dynamics damping="0.223"/>
  </joint>
  <link name="l_lower_leg_ems_acc_eb7"/>
  <joint name="l_lower_leg_ems_acc_eb7_fixed_joint" type="fixed">
    <origin xyz="0.0249001 -0.092765 0.04351373" rpy="0 -0.218166543341 1.57079632679"/>
    <parent link="l_lower_leg"/>
    <child link="l_lower_leg_ems_acc_eb7"/>
    <dynamics damping="0.1"/>
  </joint>
  <link name="l_lower_leg_ems_gyro_eb7"/>
  <joint name="l_lower_leg_ems_gyro_eb7_fixed_joint" type="fixed">
    <origin xyz="0.025404 -0.088301 0.044503292" rpy="0 -0.218166543341 1.57079632679"/>
    <parent link="l_lower_leg"/>
    <child link="l_lower_leg_ems_gyro_eb7"/>
    <dynamics damping="0.1"/>
  </joint>
  <link name="l_lower_leg_mtb_acc_10b8"/>
  <joint name="l_lower_leg_mtb_acc_10b8_fixed_joint" type="fixed">
    <origin xyz="0.0307696 -0.004318 0.05313347" rpy="0.24434616607 0 1.57079632679"/>
    <parent link="l_lower_leg"/>
    <child link="l_lower_leg_mtb_acc_10b8"/>
    <dynamics damping="0.1"/>
  </joint>
  <link name="l_lower_leg_mtb_acc_10b9"/>
  <joint name="l_lower_leg_mtb_acc_10b9_fixed_joint" type="fixed">
    <origin xyz="-0.0002136 -0.004318 0.0544518" rpy="-0.349065638045 3.97141037841e-05 1.57090544048"/>
    <parent link="l_lower_leg"/>
    <child link="l_lower_leg_mtb_acc_10b9"/>
    <dynamics damping="0.1"/>
  </joint>
  <link name="l_lower_leg_mtb_acc_10b10"/>
  <joint name="l_lower_leg_mtb_acc_10b10_fixed_joint" type="fixed">
    <origin xyz="0.0563295 -0.043468 0.0259151" rpy="1.30899714594 -0.000112159802878 1.57082638021"/>
    <parent link="l_lower_leg"/>
    <child link="l_lower_leg_mtb_acc_10b10"/>
    <dynamics damping="0.1"/>
  </joint>
  <link name="l_lower_leg_mtb_acc_10b11"/>
  <joint name="l_lower_leg_mtb_acc_10b11_fixed_joint" type="fixed">
    <origin xyz="-0.0281332 -0.092958 0.0184593" rpy="-1.3089971472 -2.54317885716e-05 1.57078951235"/>
    <parent link="l_lower_leg"/>
    <child link="l_lower_leg_mtb_acc_10b11"/>
    <dynamics damping="0.1"/>
  </joint>
  <link name="l_ankle_1">
    <inertial>
      <origin xyz="-0.0261116 6.29999999999e-05 0.0152606" rpy="0 0 0"/>
      <mass value="0.6798"/>
      <inertia ixx="0.000405061299357" ixy="-1.12515439246e-06" ixz="3.06763770037e-05" iyy="0.00044834556253" iyz="2.88992928055e-06" izz="0.000309415719323"/>
    </inertial>
    <visual>
      <origin xyz="-0.0971179001907 0.587138 0.043409" rpy="0 0 0"/>
      <geometry>
        <mesh filename="package://testbot_description/meshes/dae/sim_sea_2-5_l_ankle_prt-binary.stl" scale="0.001 0.001 0.001"/>
      </geometry>
      <material name="metal" />
    </visual>
    <collision>
      <origin xyz="-0.0971179001907 0.587138 0.043409" rpy="0 0 0"/>
      <geometry>
        <mesh filename="package://testbot_description/meshes/dae/sim_sea_2-5_l_ankle_prt-binary.stl" scale="0.001 0.001 0.001"/>
      </geometry>
    </collision>
  </link>
  <joint name="l_ankle_pitch" type="revolute">
    <origin xyz="0.0406034 -0.2005 0" rpy="0 0 0"/>
    <axis xyz="1.0 0.0 0.0"/>
    <parent link="l_lower_leg"/>
    <child link="l_ankle_1"/>
    <limit effort="50000" lower="-0.349065850399" upper="0.523598775598" velocity="50000"/>
    <dynamics damping="0.223"/>
  </joint>
  <link name="l_ankle_2">
    <inertial>
      <origin xyz="-8.19999999999e-06 -0.038202 -0.04732025" rpy="0 0 0"/>
      <mass value="0.267485"/>
      <inertia ixx="0.000335682" ixy="-7.53335e-08" ixz="2.93681e-08" iyy="0.00025387" iyz="-4.26218e-07" izz="0.000154833"/>
    </inertial>
    <visual>
      <origin xyz="-0.0701000001907 0.587138 -0.00467855" rpy="0 0 0"/>
      <geometry>
        <mesh filename="package://testbot_description/meshes/dae/sim_sea_2-5_l_foot_prt-binary.stl" scale="0.001 0.001 0.001"/>
      </geometry>
      <material name="metal" />
    </visual>
    <collision>
      <origin xyz="-0.0701000001907 0.587138 -0.00467855" rpy="0 0 0"/>
      <geometry>
        <mesh filename="package://testbot_description/meshes/dae/sim_sea_2-5_l_foot_prt-binary.stl" scale="0.001 0.001 0.001"/>
      </geometry>
    </collision>
  </link>
  <joint name="l_ankle_roll" type="revolute">
    <origin xyz="-0.0270179 0 0.04808755" rpy="0 0 0"/>
    <axis xyz="0.0 0.0 1.0"/>
    <parent link="l_ankle_1"/>
    <child link="l_ankle_2"/>
    <limit effort="50000" lower="-0.349065850399" upper="0.349065850399" velocity="50000"/>
    <dynamics damping="0.223"/>
  </joint>
  <link name="l_foot">
    <inertial>
      <origin xyz="0.0336906 -0.0053662 -0.001154" rpy="-1.57079632679 0 -1.57079632679"/>
      <mass value="0.382372"/>
      <inertia ixx="0.00121061" ixy="-3.65345e-07" ixz="5.78649e-05" iyy="0.00141515" iyz="-7.67241e-06" izz="0.000273665"/>
    </inertial>
    <visual>
      <origin xyz="0.0472089996187 0.0701000001907 -0.647438" rpy="-1.57079632679 0 -1.57079632679"/>
      <geometry>
        <mesh filename="package://testbot_description/meshes/dae/sim_sea_2-5_l_sole_prt-binary.stl" scale="0.001 0.001 0.001"/>
      </geometry>
      <material name="black" />
    </visual>
    <collision>
      <origin xyz="0.0472089996187 0.0701000001907 -0.647438" rpy="-1.57079632679 0 -1.57079632679"/>
      <geometry>
        <mesh filename="package://testbot_description/meshes/dae/sim_sea_2-5_l_sole_prt-binary.stl" scale="0.001 0.001 0.001"/>
      </geometry>
    </collision>
  </link>
  <joint name="l_foot_ft_sensor" type="fixed">
    <origin xyz="0 -0.0603 -0.05158755" rpy="1.57079632679 -1.57079632679 0"/>
    <parent link="l_ankle_2"/>
    <child link="l_foot"/>
    <dynamics damping="0.1"/>
  </joint>
  <link name="l_foot_mtb_acc_10b12"/>
  <joint name="l_foot_mtb_acc_10b12_fixed_joint" type="fixed">
    <origin xyz="0.1055224 0.0008072 -0.001215" rpy="0 0 1.57079632679"/>
    <parent link="l_foot"/>
    <child link="l_foot_mtb_acc_10b12"/>
    <dynamics damping="0.1"/>
  </joint>
  <link name="l_foot_mtb_acc_10b13"/>
  <joint name="l_foot_mtb_acc_10b13_fixed_joint" type="fixed">
    <origin xyz="0.0805224 0.0118072 -0.001215" rpy="0 0 1.57079632679"/>
    <parent link="l_foot"/>
    <child link="l_foot_mtb_acc_10b13"/>
    <dynamics damping="0.1"/>
  </joint>
  <link name="l_sole"/>
  <joint name="l_sole_fixed_joint" type="fixed">
    <origin xyz="0.0035 0 0.004" rpy="-3.14159265359 0 0"/>
    <parent link="l_foot"/>
    <child link="l_sole"/>
    <dynamics damping="0.1"/>
  </joint>
  <link name="torso_1">
    <inertial>
      <origin xyz="0.0270921359 0.02914798 -0.0004398" rpy="0 0 0"/>
      <mass value="0.67144"/>
      <inertia ixx="0.00040911" ixy="-1.04522e-06" ixz="-1.02516e-06" iyy="0.000384141" iyz="6.50708e-06" izz="0.000299445"/>
    </inertial>
    <visual>
      <origin xyz="0.0270462998093 0.032 0.0364" rpy="0 0 0"/>
      <geometry>
        <mesh filename="package://testbot_description/meshes/dae/sim_sea_2-5_lap_belt_1_prt-binary.stl" scale="0.001 0.001 0.001"/>
      </geometry>
      <material name="metal" />
    </visual>
    <collision>
      <origin xyz="0.0270462998093 0.032 0.0364" rpy="0 0 0"/>
      <geometry>
        <mesh filename="package://testbot_description/meshes/dae/sim_sea_2-5_lap_belt_1_prt-binary.stl" scale="0.001 0.001 0.001"/>
      </geometry>
    </collision>
  </link>
  <joint name="torso_pitch" type="revolute">
    <origin xyz="0 0.0270463 0" rpy="1.57079632679 0 -1.57079632679"/>
    <axis xyz="1.0 0.0 0.0"/>
    <parent link="root_link"/>
    <child link="torso_1"/>
    <limit effort="50000" lower="-0.349065850399" upper="1.2217304764" velocity="50000"/>
    <dynamics damping="0.06"/>
  </joint>
  <link name="torso_2">
    <inertial>
      <origin xyz="-0.000113507809265 0.0361525 0.0570963" rpy="0 0 0"/>
      <mass value="0.425685"/>
      <inertia ixx="0.000829234" ixy="2.37006e-08" ixz="9.25231e-08" iyy="0.000436517" iyz="-1.74814e-07" izz="0.000604802"/>
    </inertial>
    <visual>
      <origin xyz="0 0.1433 0.0386531" rpy="0 0 0"/>
      <geometry>
        <mesh filename="package://testbot_description/meshes/dae/sim_sea_2-5_lap_belt_2_prt-binary.stl" scale="0.001 0.001 0.001"/>
      </geometry>
      <material name="metal" />
    </visual>
    <collision>
      <origin xyz="0 0.1433 0.0386531" rpy="0 0 0"/>
      <geometry>
        <mesh filename="package://testbot_description/meshes/dae/sim_sea_2-5_lap_belt_2_prt-binary.stl" scale="0.001 0.001 0.001"/>
      </geometry>
    </collision>
  </link>
  <joint name="torso_roll" type="revolute">
    <origin xyz="0.0270462998093 0.032 -0.0573446" rpy="0 0 0"/>
    <axis xyz="0.0 0.0 -1.0"/>
    <parent link="torso_1"/>
    <child link="torso_2"/>
    <limit effort="50000" lower="-0.523598775598" upper="0.523598775598" velocity="50000"/>
    <dynamics damping="0.06"/>
  </joint>
  <link name="chest">
    <inertial>
      <origin xyz="0.000188619190735 0.023091 -0.013238" rpy="0 0 0"/>
      <mass value="5.638"/>
      <inertia ixx="0.0317644889454" ixy="2.14857690767e-05" ixz="0.000134332642897" iyy="0.0325403485289" iyz="-0.000316745474542" izz="0.0192335114297"/>
    </inertial>
    <visual>
      <origin xyz="0 0.0928 -0.024189" rpy="0 0 0"/>
      <geometry>
        <mesh filename="package://testbot_description/meshes/dae/sim_sea_2-5_chest_bb_prt-binary.stl" scale="0.001 0.001 0.001"/>
      </geometry>
      <material name="purple" />
    </visual>
    <collision>
      <origin xyz="0 0.0928 -0.024189" rpy="0 0 0"/>
      <geometry>
        <mesh filename="package://testbot_description/meshes/dae/sim_sea_2-5_chest_bb_prt-binary.stl" scale="0.001 0.001 0.001"/>
      </geometry>
    </collision>
  </link>
  <joint name="torso_yaw" type="revolute">
    <origin xyz="0 0.05 0.0628421" rpy="0 0 0"/>
    <axis xyz="0.0 -1.0 0.0"/>
    <parent link="torso_2"/>
    <child link="chest"/>
    <limit effort="50000" lower="-0.872664625997" upper="0.872664625997" velocity="50000"/>
    <dynamics damping="0.06"/>
  </joint>
  <link name="chest_ems_acc_eb1"/>
  <joint name="chest_ems_acc_eb1_fixed_joint" type="fixed">
    <origin xyz="0.0647855001907 0.064043 -0.0647091" rpy="3.1415169123 -0.261799309122 0.000292641880255"/>
    <parent link="chest"/>
    <child link="chest_ems_acc_eb1"/>
    <dynamics damping="0.1"/>
  </joint>
  <link name="chest_ems_gyro_eb1"/>
  <joint name="chest_ems_gyro_eb1_fixed_joint" type="fixed">
    <origin xyz="0.0692016001907 0.064548 -0.0635258" rpy="3.1415169123 -0.261799309122 0.000292641880255"/>
    <parent link="chest"/>
    <child link="chest_ems_gyro_eb1"/>
    <dynamics damping="0.1"/>
  </joint>
  <link name="chest_ems_acc_eb2"/>
  <joint name="chest_ems_acc_eb2_fixed_joint" type="fixed">
    <origin xyz="0.0204533001907 0.088063 -0.0641645" rpy="3.14159050104 0.261799319819 3.14158433678"/>
    <parent link="chest"/>
    <child link="chest_ems_acc_eb2"/>
    <dynamics damping="0.1"/>
  </joint>
  <link name="chest_ems_gyro_eb2"/>
  <joint name="chest_ems_gyro_eb2_fixed_joint" type="fixed">
    <origin xyz="0.0160371001907 0.087559 -0.0653479" rpy="3.14159050104 0.261799319819 3.14158433678"/>
    <parent link="chest"/>
    <child link="chest_ems_gyro_eb2"/>
    <dynamics damping="0.1"/>
  </joint>
  <link name="chest_ems_acc_eb3"/>
  <joint name="chest_ems_acc_eb3_fixed_joint" type="fixed">
    <origin xyz="-0.0230587998093 0.064019 -0.0758985" rpy="3.14110916203 0.261100516471 -0.000309071462555"/>
    <parent link="chest"/>
    <child link="chest_ems_acc_eb3"/>
    <dynamics damping="0.1"/>
  </joint>
  <link name="chest_ems_gyro_eb3"/>
  <joint name="chest_ems_gyro_eb3_fixed_joint" type="fixed">
    <origin xyz="-0.0186416998093 0.064521 -0.0770785" rpy="3.14110916203 0.261100516471 -0.000309071462555"/>
    <parent link="chest"/>
    <child link="chest_ems_gyro_eb3"/>
    <dynamics damping="0.1"/>
  </joint>
  <link name="chest_ems_acc_eb4"/>
  <joint name="chest_ems_acc_eb4_fixed_joint" type="fixed">
    <origin xyz="-0.0621620998093 0.088063 -0.0529887" rpy="-3.14159050476 -0.261799319819 3.14158433987"/>
    <parent link="chest"/>
    <child link="chest_ems_acc_eb4"/>
    <dynamics damping="0.1"/>
  </joint>
  <link name="chest_ems_gyro_eb4"/>
  <joint name="chest_ems_gyro_eb4_fixed_joint" type="fixed">
    <origin xyz="-0.0665783998093 0.087559 -0.0518054" rpy="-3.14159050476 -0.261799319819 3.14158433987"/>
    <parent link="chest"/>
    <child link="chest_ems_gyro_eb4"/>
    <dynamics damping="0.1"/>
  </joint>
  <link name="chest_mtb_acc_0b7"/>
  <joint name="chest_mtb_acc_0b7_fixed_joint" type="fixed">
    <origin xyz="-0.0607539998093 -0.0017836 0.0442341" rpy="0.875167771492 0.116363734392 -1.48597350247"/>
    <parent link="chest"/>
    <child link="chest_mtb_acc_0b7"/>
    <dynamics damping="0.1"/>
  </joint>
  <link name="chest_mtb_acc_0b8"/>
  <joint name="chest_mtb_acc_0b8_fixed_joint" type="fixed">
    <origin xyz="-0.0457046998093 -0.001846 0.0567427" rpy="0.500960084689 0.107313688983 -1.4778325291"/>
    <parent link="chest"/>
    <child link="chest_mtb_acc_0b8"/>
    <dynamics damping="0.1"/>
  </joint>
  <link name="chest_mtb_acc_0b9"/>
  <joint name="chest_mtb_acc_0b9_fixed_joint" type="fixed">
    <origin xyz="0.0439036001907 -0.0017841 0.0577221" rpy="-0.500959928973 0.107315404248 -1.66376017469"/>
    <parent link="chest"/>
    <child link="chest_mtb_acc_0b9"/>
    <dynamics damping="0.1"/>
  </joint>
  <link name="chest_mtb_acc_0b10"/>
  <joint name="chest_mtb_acc_0b10_fixed_joint" type="fixed">
    <origin xyz="0.0594286001907 -0.0018543 0.0457981" rpy="-0.875168153475 0.116362025479 -1.65561807505"/>
    <parent link="chest"/>
    <child link="chest_mtb_acc_0b10"/>
    <dynamics damping="0.1"/>
  </joint>
  <link name="r_shoulder_1">
    <inertial>
      <origin xyz="-0.0122656014133 3.2e-05 -0.00321064290449" rpy="0 0 0"/>
      <mass value="0.114862"/>
      <inertia ixx="2.24541e-05" ixy="-1.65173e-08" ixz="-3.55626e-06" iyy="2.29582e-05" iyz="-6.13337e-08" izz="1.00116e-05"/>
    </inertial>
    <visual>
      <origin xyz="0.0990079253076 0 -0.0265292487558" rpy="0 0 0"/>
      <geometry>
        <mesh filename="package://testbot_description/meshes/dae/sim_sea_2-5_r_shoulder_1_prt-binary.stl" scale="0.001 0.001 0.001"/>
      </geometry>
      <material name="metal" />
    </visual>
    <collision>
      <origin xyz="0.0990079253076 0 -0.0265292487558" rpy="0 0 0"/>
      <geometry>
        <mesh filename="package://testbot_description/meshes/dae/sim_sea_2-5_r_shoulder_1_prt-binary.stl" scale="0.001 0.001 0.001"/>
      </geometry>
    </collision>
  </link>
  <joint name="r_shoulder_pitch" type="revolute">
    <origin xyz="-0.120015999809 0.0928 0.0079693" rpy="0 -0.523598883792 3.14159265359"/>
    <axis xyz="-0.965925926173 0.0 0.258819275525"/>
    <parent link="chest"/>
    <child link="r_shoulder_1"/>
    <limit effort="50000" lower="-1.66678943565" upper="0.174532925199" velocity="50000"/>
    <dynamics damping="0.06"/>
  </joint>
  <link name="r_shoulder_2">
    <inertial>
      <origin xyz="-0.0214141709438 0.000271725272551 -0.0194402344535" rpy="0 0 0"/>
      <mass value="0.238162"/>
      <inertia ixx="0.000158626" ixy="-1.12091e-07" ixz="1.02574e-05" iyy="0.000206526" iyz="1.19785e-06" izz="0.000104956"/>
    </inertial>
    <visual>
      <origin xyz="0.106587808568 2.31914715418e-07 -0.0407392121175" rpy="0 0 0"/>
      <geometry>
        <mesh filename="package://testbot_description/meshes/dae/sim_sea_2-5_r_shoulder_2_prt-binary.stl" scale="0.001 0.001 0.001"/>
      </geometry>
      <material name="metal" />
    </visual>
    <collision>
      <origin xyz="0.106587808568 2.31914715418e-07 -0.0407392121175" rpy="0 0 0"/>
      <geometry>
        <mesh filename="package://testbot_description/meshes/dae/sim_sea_2-5_r_shoulder_2_prt-binary.stl" scale="0.001 0.001 0.001"/>
      </geometry>
    </collision>
  </link>
  <joint name="r_shoulder_roll" type="revolute">
    <origin xyz="-0.00758046573227 0 0.0142102463639" rpy="-0.270597611583 -0.252680154648 -1.50155680035"/>
    <axis xyz="-0.258819 -2.77555756156e-17 -0.965926"/>
    <parent link="r_shoulder_1"/>
    <child link="r_shoulder_2"/>
    <limit effort="50000" lower="0.0" upper="2.80648943721" velocity="50000"/>
    <dynamics damping="0.06"/>
  </joint>
  <link name="r_shoulder_3">
    <inertial>
      <origin xyz="-0.0267620766871 -6.99999999998e-06 0.0146999207713" rpy="0 0 0"/>
      <mass value="0.35913"/>
      <inertia ixx="0.000142333" ixy="3.60361e-07" ixz="4.94445e-05" iyy="0.000197746" iyz="2.65919e-07" izz="0.000151821"/>
    </inertial>
    <visual>
      <origin xyz="0.131933879164 0 -0.0353515667647" rpy="0 0 0"/>
      <geometry>
        <mesh filename="package://testbot_description/meshes/dae/sim_sea_2-5_r_upper_arm_prt-binary.stl" scale="0.001 0.001 0.001"/>
      </geometry>
      <material name="metal" />
    </visual>
    <collision>
      <origin xyz="0.131933879164 0 -0.0353515667647" rpy="0 0 0"/>
      <geometry>
        <mesh filename="package://testbot_description/meshes/dae/sim_sea_2-5_r_upper_arm_prt-binary.stl" scale="0.001 0.001 0.001"/>
      </geometry>
    </collision>
  </link>
  <joint name="r_shoulder_yaw" type="revolute">
    <origin xyz="-0.0253460713232 2.32750427306e-07 -0.00538764806457" rpy="-0.252689546175 0.0085186183214 0.067039889142"/>
    <axis xyz="0.965925843882 -2.22044604925e-16 -0.258818979447"/>
    <parent link="r_shoulder_2"/>
    <child link="r_shoulder_3"/>
    <limit effort="50000" lower="-0.645771823238" upper="1.3962634016" velocity="50000"/>
    <dynamics damping="0.06"/>
  </joint>
  <link name="r_upper_arm">
    <inertial>
      <origin xyz="-0.006087 0.000126 0.0293121" rpy="0 1.30899700697 0"/>
      <mass value="0.745104"/>
      <inertia ixx="0.000509527" ixy="1.19292e-06" ixz="-1.17426e-05" iyy="0.000668487" iyz="1.13363e-06" izz="0.000599254"/>
    </inertial>
    <visual>
      <origin xyz="-0.015 0 -0.1933" rpy="0 1.30899700697 0"/>
      <geometry>
        <mesh filename="package://testbot_description/meshes/dae/sim_sea_2-5_r_elbow_prt-binary.stl" scale="0.001 0.001 0.001"/>
      </geometry>
      <material name="purple" />
    </visual>
    <collision>
      <origin xyz="-0.015 0 -0.1933" rpy="0 1.30899700697 0"/>
      <geometry>
        <mesh filename="package://testbot_description/meshes/dae/sim_sea_2-5_r_elbow_prt-binary.stl" scale="0.001 0.001 0.001"/>
      </geometry>
    </collision>
  </link>
  <joint name="r_arm_ft_sensor" type="fixed">
    <origin xyz="-0.0508973017665 0 0.0291670296206" rpy="0 -1.30899700697 0"/>
    <parent link="r_shoulder_3"/>
    <child link="r_upper_arm"/>
    <dynamics damping="0.1"/>
  </joint>
  <link name="r_upper_arm_mtb_acc_2b10"/>
  <joint name="r_upper_arm_mtb_acc_2b10_fixed_joint" type="fixed">
    <origin xyz="-0.0412194 0.029588 0.0295279" rpy="1.57079546365 1.57078381225 -2.68257161164"/>
    <parent link="r_upper_arm"/>
    <child link="r_upper_arm_mtb_acc_2b10"/>
    <dynamics damping="0.1"/>
  </joint>
  <link name="r_upper_arm_mtb_acc_2b11"/>
  <joint name="r_upper_arm_mtb_acc_2b11_fixed_joint" type="fixed">
    <origin xyz="-0.0430568 0.02868 0.0760604" rpy="-1.57079614696 -1.57050350741 0.459021725219"/>
    <parent link="r_upper_arm"/>
    <child link="r_upper_arm_mtb_acc_2b11"/>
    <dynamics damping="0.1"/>
  </joint>
  <link name="r_upper_arm_mtb_acc_2b12"/>
  <joint name="r_upper_arm_mtb_acc_2b12_fixed_joint" type="fixed">
    <origin xyz="-0.0430554 0.028681 0.0049922" rpy="-1.11177442168 -1.57079632679 0"/>
    <parent link="r_upper_arm"/>
    <child link="r_upper_arm_mtb_acc_2b12"/>
    <dynamics damping="0.1"/>
  </joint>
  <link name="r_upper_arm_mtb_acc_2b13"/>
  <joint name="r_upper_arm_mtb_acc_2b13_fixed_joint" type="fixed">
    <origin xyz="0.010593237 0.02835 -0.010738" rpy="1.57079632702 -0.000214520362041 2.47803674451"/>
    <parent link="r_upper_arm"/>
    <child link="r_upper_arm_mtb_acc_2b13"/>
    <dynamics damping="0.1"/>
  </joint>
  <link name="r_elbow_1">
    <inertial>
      <origin xyz="-0.00673912932843 0.0188019 -0.00465769236154" rpy="0 0 0"/>
      <mass value="0.267903"/>
      <inertia ixx="8.13344e-05" ixy="7.36974e-06" ixz="-1.04536e-05" iyy="5.86947e-05" iyz="3.92498e-06" izz="9.68353e-05"/>
    </inertial>
    <visual>
      <origin xyz="0.259390463317 0.0224999 -0.0850325886962" rpy="0 0 0"/>
      <geometry>
        <mesh filename="package://testbot_description/meshes/dae/sim_sea_2-5_r_elbow_prosup_prt-binary.stl" scale="0.001 0.001 0.001"/>
      </geometry>
      <material name="purple" />
    </visual>
    <collision>
      <origin xyz="0.259390463317 0.0224999 -0.0850325886962" rpy="0 0 0"/>
      <geometry>
        <mesh filename="package://testbot_description/meshes/dae/sim_sea_2-5_r_elbow_prosup_prt-binary.stl" scale="0.001 0.001 0.001"/>
      </geometry>
    </collision>
  </link>
  <joint name="r_elbow" type="revolute">
    <origin xyz="0 -0.0224999 0.07926" rpy="0 1.30899700697 0"/>
    <axis xyz="2.22044604925e-16 1.0 0.0"/>
    <parent link="r_upper_arm"/>
    <child link="r_elbow_1"/>
    <limit effort="50000" lower="0.261799387799" upper="1.85004900711" velocity="50000"/>
    <dynamics damping="0.06"/>
  </joint>
  <link name="r_forearm">
    <inertial>
      <origin xyz="-0.0404391133886 -0.000328 0.00532733448387" rpy="0 0 0"/>
      <mass value="0.6347"/>
      <inertia ixx="0.000370044" ixy="-1.65419e-06" ixz="0.00010538" iyy="0.000672279" iyz="1.1456e-06" izz="0.000553637"/>
    </inertial>
    <visual>
      <origin xyz="0.296886967375 0 -0.0795506015227" rpy="0 0 0"/>
      <geometry>
        <mesh filename="package://testbot_description/meshes/dae/sim_sea_2-5_r_forearm_prt-binary.stl" scale="0.001 0.001 0.001"/>
      </geometry>
      <material name="purple" />
    </visual>
    <collision>
      <origin xyz="0.296886967375 0 -0.0795506015227" rpy="0 0 0"/>
      <geometry>
        <mesh filename="package://testbot_description/meshes/dae/sim_sea_2-5_r_forearm_prt-binary.stl" scale="0.001 0.001 0.001"/>
      </geometry>
    </collision>
  </link>
  <joint name="r_wrist_prosup" type="revolute">
    <origin xyz="-0.0384624299027 0.0224999 -0.00522316819403" rpy="0 0 0"/>
    <axis xyz="-0.965925843882 2.22044604925e-16 0.258818979447"/>
    <parent link="r_elbow_1"/>
    <child link="r_forearm"/>
    <limit effort="50000" lower="-1.0471975512" upper="1.0471975512" velocity="50000"/>
    <dynamics damping="0.06"/>
  </joint>
  <link name="r_forearm_mtb_acc_2b7"/>
  <joint name="r_forearm_mtb_acc_2b7_fixed_joint" type="fixed">
    <origin xyz="-0.0768727847342 0.005497 -0.0110479126068" rpy="0.26179949998 0.000370413042328 1.57125816863"/>
    <parent link="r_forearm"/>
    <child link="r_forearm_mtb_acc_2b7"/>
    <dynamics damping="0.1"/>
  </joint>
  <link name="r_forearm_mtb_acc_2b8"/>
  <joint name="r_forearm_mtb_acc_2b8_fixed_joint" type="fixed">
    <origin xyz="-0.0514186150796 0.015786 0.0407521537277" rpy="-0.661143946092 0.147825248461 0.092070114703"/>
    <parent link="r_forearm"/>
    <child link="r_forearm_mtb_acc_2b8"/>
    <dynamics damping="0.1"/>
  </joint>
  <link name="r_forearm_mtb_acc_2b9"/>
  <joint name="r_forearm_mtb_acc_2b9_fixed_joint" type="fixed">
    <origin xyz="-0.0216379956759 0.027924 -0.0132490254018" rpy="-1.76682626732 0.261191225646 0.054048344372"/>
    <parent link="r_forearm"/>
    <child link="r_forearm_mtb_acc_2b9"/>
    <dynamics damping="0.1"/>
  </joint>
  <link name="r_forearm_skin_0"/>
  <joint name="r_forearm_skin_0_fixed_joint" type="fixed">
    <origin xyz="-0.0454493286618 0.030077 -0.00628656037901" rpy="1.69181522292 -0.271026744341 -3.06880438227"/>
    <parent link="r_forearm"/>
    <child link="r_forearm_skin_0"/>
    <dynamics damping="0.1"/>
  </joint>
  <link name="r_forearm_skin_1"/>
  <joint name="r_forearm_skin_1_fixed_joint" type="fixed">
    <origin xyz="-0.0333728935826 0.028826 -0.0198456867711" rpy="1.86694023278 -0.274442533764 -3.09946977984"/>
    <parent link="r_forearm"/>
    <child link="r_forearm_skin_1"/>
    <dynamics damping="0.1"/>
  </joint>
  <link name="r_forearm_skin_2"/>
  <joint name="r_forearm_skin_2_fixed_joint" type="fixed">
    <origin xyz="-0.0146988929852 0.031279 -0.0160117338371" rpy="1.72847287019 -0.264015219116 -3.12733260687"/>
    <parent link="r_forearm"/>
    <child link="r_forearm_skin_2"/>
    <dynamics damping="0.1"/>
  </joint>
  <link name="r_forearm_skin_3"/>
  <joint name="r_forearm_skin_3_fixed_joint" type="fixed">
    <origin xyz="-0.045567293622 -0.030891 -0.00633000929351" rpy="-1.69487280859 -0.269757727104 3.07959743574"/>
    <parent link="r_forearm"/>
    <child link="r_forearm_skin_3"/>
    <dynamics damping="0.1"/>
  </joint>
  <link name="r_forearm_skin_4"/>
  <joint name="r_forearm_skin_4_fixed_joint" type="fixed">
    <origin xyz="-0.0635326332996 -0.0281163 -0.00899784258066" rpy="-1.80734960194 -0.0393131796327 2.97997643632"/>
    <parent link="r_forearm"/>
    <child link="r_forearm_skin_4"/>
    <dynamics damping="0.1"/>
  </joint>
  <link name="r_forearm_skin_5"/>
  <joint name="r_forearm_skin_5_fixed_joint" type="fixed">
    <origin xyz="-0.0688211941968 -0.0179483 -0.0231133361791" rpy="-2.5410475806 -0.385627260642 3.05486989667"/>
    <parent link="r_forearm"/>
    <child link="r_forearm_skin_5"/>
    <dynamics damping="0.1"/>
  </joint>
  <link name="r_forearm_skin_6"/>
  <joint name="r_forearm_skin_6_fixed_joint" type="fixed">
    <origin xyz="-0.0333948436255 -0.0295479 -0.0198325583433" rpy="-1.86628164653 -0.272886336181 3.10448585021"/>
    <parent link="r_forearm"/>
    <child link="r_forearm_skin_6"/>
    <dynamics damping="0.1"/>
  </joint>
  <link name="r_forearm_skin_7"/>
  <joint name="r_forearm_skin_7_fixed_joint" type="fixed">
    <origin xyz="-0.0147224260074 -0.0319422 -0.0159326482703" rpy="-1.72564640857 -0.263992900722 3.12721254266"/>
    <parent link="r_forearm"/>
    <child link="r_forearm_skin_7"/>
    <dynamics damping="0.1"/>
  </joint>
  <link name="r_forearm_skin_8"/>
  <joint name="r_forearm_skin_8_fixed_joint" type="fixed">
    <origin xyz="-0.0228528628554 -0.0097862 -0.041885146375" rpy="-2.94801979137 -0.270605090512 3.13980557285"/>
    <parent link="r_forearm"/>
    <child link="r_forearm_skin_8"/>
    <dynamics damping="0.1"/>
  </joint>
  <link name="r_forearm_skin_9"/>
  <joint name="r_forearm_skin_9_fixed_joint" type="fixed">
    <origin xyz="-0.0376032734683 -0.018955 -0.0340163371186" rpy="-2.58406517708 -0.2933217196 3.12128407396"/>
    <parent link="r_forearm"/>
    <child link="r_forearm_skin_9"/>
    <dynamics damping="0.1"/>
  </joint>
  <link name="r_forearm_skin_10"/>
  <joint name="r_forearm_skin_10_fixed_joint" type="fixed">
    <origin xyz="-0.0542285210888 -0.0097861 -0.0321469082866" rpy="-2.94123313406 -0.328304471922 3.1276263754"/>
    <parent link="r_forearm"/>
    <child link="r_forearm_skin_10"/>
    <dynamics damping="0.1"/>
  </joint>
  <link name="r_forearm_skin_11"/>
  <joint name="r_forearm_skin_11_fixed_joint" type="fixed">
    <origin xyz="-0.0542240912024 0.009043 -0.0321431259452" rpy="2.93929835957 -0.329101389745 -3.12731916446"/>
    <parent link="r_forearm"/>
    <child link="r_forearm_skin_11"/>
    <dynamics damping="0.1"/>
  </joint>
  <link name="r_forearm_skin_12"/>
  <joint name="r_forearm_skin_12_fixed_joint" type="fixed">
    <origin xyz="-0.0375994633868 0.018216 -0.0340191179961" rpy="2.58303505964 -0.29483050207 -3.12026580314"/>
    <parent link="r_forearm"/>
    <child link="r_forearm_skin_12"/>
    <dynamics damping="0.1"/>
  </joint>
  <link name="r_forearm_skin_13"/>
  <joint name="r_forearm_skin_13_fixed_joint" type="fixed">
    <origin xyz="-0.0228550868405 0.009048 -0.0418919009209" rpy="2.94896679198 -0.270583947189 -3.13981880352"/>
    <parent link="r_forearm"/>
    <child link="r_forearm_skin_13"/>
    <dynamics damping="0.1"/>
  </joint>
  <link name="r_forearm_skin_14"/>
  <joint name="r_forearm_skin_14_fixed_joint" type="fixed">
    <origin xyz="-0.0687703276364 0.01716 -0.0230239558511" rpy="2.48044991868 -0.295542566281 -2.91877349139"/>
    <parent link="r_forearm"/>
    <child link="r_forearm_skin_14"/>
    <dynamics damping="0.1"/>
  </joint>
  <link name="r_forearm_skin_15"/>
  <joint name="r_forearm_skin_15_fixed_joint" type="fixed">
    <origin xyz="-0.0633786419662 0.027145 -0.00879405455544" rpy="1.80492769741 -0.289783281916 -3.02765891428"/>
    <parent link="r_forearm"/>
    <child link="r_forearm_skin_15"/>
    <dynamics damping="0.1"/>
  </joint>
  <link name="r_forearm_skin_16"/>
  <joint name="r_forearm_skin_16_fixed_joint" type="fixed">
    <origin xyz="-0.03792482187 0.030487 0.0206369503605" rpy="1.41280007026 -0.25082462139 -3.06572742343"/>
    <parent link="r_forearm"/>
    <child link="r_forearm_skin_16"/>
    <dynamics damping="0.1"/>
  </joint>
  <link name="r_forearm_skin_17"/>
  <joint name="r_forearm_skin_17_fixed_joint" type="fixed">
    <origin xyz="-0.0543170548821 0.027725 0.0303291240179" rpy="1.27223716205 -0.23059304703 -3.03195542837"/>
    <parent link="r_forearm"/>
    <child link="r_forearm_skin_17"/>
    <dynamics damping="0.1"/>
  </joint>
  <link name="r_forearm_skin_19"/>
  <joint name="r_forearm_skin_19_fixed_joint" type="fixed">
    <origin xyz="-0.0381266107138 -0.0312941 0.020690605393" rpy="-1.41560888703 -0.252569290226 3.07715217889"/>
    <parent link="r_forearm"/>
    <child link="r_forearm_skin_19"/>
    <dynamics damping="0.1"/>
  </joint>
  <link name="r_forearm_skin_22"/>
  <joint name="r_forearm_skin_22_fixed_joint" type="fixed">
    <origin xyz="-0.0544173950421 -0.0287223 0.0306037516609" rpy="-1.2658242728 -0.234328151379 3.04788317971"/>
    <parent link="r_forearm"/>
    <child link="r_forearm_skin_22"/>
    <dynamics damping="0.1"/>
  </joint>
  <link name="r_forearm_skin_24"/>
  <joint name="r_forearm_skin_24_fixed_joint" type="fixed">
    <origin xyz="-0.0700345319564 -0.0097164 0.050069108714" rpy="-0.23489327644 -0.0388172993982 3.08676345459"/>
    <parent link="r_forearm"/>
    <child link="r_forearm_skin_24"/>
    <dynamics damping="0.1"/>
  </joint>
  <link name="r_forearm_skin_25"/>
  <joint name="r_forearm_skin_25_fixed_joint" type="fixed">
    <origin xyz="-0.0535999216295 -0.0182238 0.0454698125045" rpy="-0.564295527715 -0.136980272197 3.05963182792"/>
    <parent link="r_forearm"/>
    <child link="r_forearm_skin_25"/>
    <dynamics damping="0.1"/>
  </joint>
  <link name="r_forearm_skin_28"/>
  <joint name="r_forearm_skin_28_fixed_joint" type="fixed">
    <origin xyz="-0.0535859272148 0.017412 0.045352037397" rpy="0.59077064408 -0.0531607226063 3.10597081167"/>
    <parent link="r_forearm"/>
    <child link="r_forearm_skin_28"/>
    <dynamics damping="0.1"/>
  </joint>
  <link name="r_forearm_skin_29"/>
  <joint name="r_forearm_skin_29_fixed_joint" type="fixed">
    <origin xyz="-0.0700355805031 0.008954 0.0500111036233" rpy="0.248630982209 -0.0383136556786 -3.08328999116"/>
    <parent link="r_forearm"/>
    <child link="r_forearm_skin_29"/>
    <dynamics damping="0.1"/>
  </joint>
  <link name="r_forearm_dh_frame"/>
  <joint name="r_forearm_dh_frame_fixed_joint" type="fixed">
    <origin xyz="-0.102871102373 7.00000000002e-06 0.0275642213111" rpy="-0.261799319827 0 -1.57079632679"/>
    <parent link="r_forearm"/>
    <child link="r_forearm_dh_frame"/>
    <dynamics damping="0.1"/>
  </joint>
  <link name="r_wrist_1">
    <inertial>
      <origin xyz="0.000986101955547 -0.001176 0.00410132736724" rpy="0 0 0"/>
      <mass value="0.0362615"/>
      <inertia ixx="5.57722e-06" ixy="-3.10462e-08" ixz="-9.44554e-07" iyy="5.29845e-06" iyz="-1.59685e-07" izz="1.87724e-06"/>
    </inertial>
    <visual>
      <origin xyz="0.400392176248 -7.00000000009e-06 -0.104748304516" rpy="0 0 0"/>
      <geometry>
        <mesh filename="package://testbot_description/meshes/dae/sim_sea_2-5_r_wrist_pitch_prt-binary.stl" scale="0.001 0.001 0.001"/>
      </geometry>
      <material name="purple" />
    </visual>
    <collision>
      <origin xyz="0.400392176248 -7.00000000009e-06 -0.104748304516" rpy="0 0 0"/>
      <geometry>
        <mesh filename="package://testbot_description/meshes/dae/sim_sea_2-5_r_wrist_pitch_prt-binary.stl" scale="0.001 0.001 0.001"/>
      </geometry>
    </collision>
  </link>
  <joint name="r_wrist_pitch" type="revolute">
    <origin xyz="-0.103505208873 7.00000000002e-06 0.0251977029936" rpy="0 0 0"/>
    <axis xyz="0.258818979447 0.0 0.965925843882"/>
    <parent link="r_forearm"/>
    <child link="r_wrist_1"/>
    <limit effort="50000" lower="-1.3962634016" upper="0.436332312999" velocity="50000"/>
    <dynamics damping="0.06"/>
  </joint>
  <link name="r_hand">
    <inertial>
      <origin xyz="-0.064668163717 0.0056002 0.0226812940918" rpy="0 0 0"/>
      <mass value="0.248289"/>
      <inertia ixx="0.000162381" ixy="-2.3536e-06" ixz="3.61526e-05" iyy="0.00043138" iyz="2.07146e-05" izz="0.00030575"/>
    </inertial>
    <visual>
      <origin xyz="0.399758069749 0.0194929 -0.107114822834" rpy="0 0 0"/>
      <geometry>
        <mesh filename="package://testbot_description/meshes/dae/sim_sea_2-5_r_hand_prt-binary.stl" scale="0.001 0.001 0.001"/>
      </geometry>
      <material name="black" />
    </visual>
    <collision>
      <origin xyz="0.399758069749 0.0194929 -0.107114822834" rpy="0 0 0"/>
      <geometry>
        <mesh filename="package://testbot_description/meshes/dae/sim_sea_2-5_r_hand_prt-binary.stl" scale="0.001 0.001 0.001"/>
      </geometry>
    </collision>
  </link>
  <joint name="r_wrist_yaw" type="revolute">
    <origin xyz="0.000634106499644 -0.0194999 0.00236651831751" rpy="0 0 0"/>
    <axis xyz="2.22044604925e-16 1.0 0.0"/>
    <parent link="r_wrist_1"/>
    <child link="r_hand"/>
    <limit effort="50000" lower="-0.349065850399" upper="0.436332312999" velocity="50000"/>
    <dynamics damping="0.06"/>
  </joint>
  <link name="r_hand_dh_frame"/>
  <joint name="r_hand_dh_frame_fixed_joint" type="fixed">
    <origin xyz="-0.0576542978428 -0.0055568 0.0136938323083" rpy="-1.57079632679 -0.261799319827 3.14159265359"/>
    <parent link="r_hand"/>
    <child link="r_hand_dh_frame"/>
    <dynamics damping="0.1"/>
  </joint>
  <link name="l_shoulder_1">
    <inertial>
      <origin xyz="-0.008985 -3.3e-05 -0.0088998" rpy="0 0 0"/>
      <mass value="0.114882"/>
      <inertia ixx="2.24676e-05" ixy="-1.77064e-08" ixz="3.55951e-06" iyy="2.29712e-05" iyz="6.57597e-08" izz="1.00139e-05"/>
    </inertial>
    <visual>
      <origin xyz="-0.120257482 0 -0.032223" rpy="0 0 0"/>
      <geometry>
        <mesh filename="package://testbot_description/meshes/dae/sim_sea_2-5_l_shoulder_1_prt-binary.stl" scale="0.001 0.001 0.001"/>
      </geometry>
      <material name="metal" />
    </visual>
    <collision>
      <origin xyz="-0.120257482 0 -0.032223" rpy="0 0 0"/>
      <geometry>
        <mesh filename="package://testbot_description/meshes/dae/sim_sea_2-5_l_shoulder_1_prt-binary.stl" scale="0.001 0.001 0.001"/>
      </geometry>
    </collision>
  </link>
  <joint name="l_shoulder_pitch" type="revolute">
    <origin xyz="0.120016000191 0.0928 0.0079693" rpy="0 0 0"/>
    <axis xyz="0.965926 0.0 0.258819"/>
    <parent link="chest"/>
    <child link="l_shoulder_1"/>
    <limit effort="50000" lower="-1.66678943565" upper="0.174532925199" velocity="50000"/>
    <dynamics damping="0.06"/>
  </joint>
  <link name="l_shoulder_2">
    <inertial>
      <origin xyz="0.0214745951272 0.000268957899687 -0.0194107361535" rpy="0 0 0"/>
      <mass value="0.238162"/>
      <inertia ixx="0.000159621" ixy="1.19701e-07" ixz="-1.29687e-05" iyy="0.000222574" iyz="1.20112e-06" izz="0.000120056"/>
    </inertial>
    <visual>
      <origin xyz="-0.106586691581 1.10800934344e-07 -0.040743380771" rpy="0 0 0"/>
      <geometry>
        <mesh filename="package://testbot_description/meshes/dae/sim_sea_2-5_l_shoulder_2_prt-binary.stl" scale="0.001 0.001 0.001"/>
      </geometry>
      <material name="metal" />
    </visual>
    <collision>
      <origin xyz="-0.106586691581 1.10800934344e-07 -0.040743380771" rpy="0 0 0"/>
      <geometry>
        <mesh filename="package://testbot_description/meshes/dae/sim_sea_2-5_l_shoulder_2_prt-binary.stl" scale="0.001 0.001 0.001"/>
      </geometry>
    </collision>
  </link>
  <joint name="l_shoulder_roll" type="revolute">
    <origin xyz="-0.013671 0 0.0085204" rpy="0.270597317916 0.252680177542 -1.50155688559"/>
    <axis xyz="-0.258819 2.77555756156e-17 0.965926"/>
    <parent link="l_shoulder_1"/>
    <child link="l_shoulder_2"/>
    <limit effort="50000" lower="0.0" upper="2.80648943721" velocity="50000"/>
    <dynamics damping="0.06"/>
  </joint>
  <link name="l_shoulder_3">
    <inertial>
      <origin xyz="0.026798412222 -1.6e-05 0.0146956806177" rpy="0 0 0"/>
      <mass value="0.35913"/>
      <inertia ixx="0.00014245" ixy="-2.22441e-07" ixz="-4.95846e-05" iyy="0.000197807" iyz="1.07538e-07" izz="0.000151706"/>
    </inertial>
    <visual>
      <origin xyz="-0.131901037685 0 -0.0353427669194" rpy="0 0 0"/>
      <geometry>
        <mesh filename="package://testbot_description/meshes/dae/sim_sea_2-5_l_upper_arm_prt-binary.stl" scale="0.001 0.001 0.001"/>
      </geometry>
      <material name="metal" />
    </visual>
    <collision>
      <origin xyz="-0.131901037685 0 -0.0353427669194" rpy="0 0 0"/>
      <geometry>
        <mesh filename="package://testbot_description/meshes/dae/sim_sea_2-5_l_upper_arm_prt-binary.stl" scale="0.001 0.001 0.001"/>
      </geometry>
    </collision>
  </link>
  <joint name="l_shoulder_yaw" type="revolute">
    <origin xyz="0.0253143468312 1.11636438205e-07 -0.00540061656265" rpy="-0.252689546175 -0.0085186183214 -0.067039889142"/>
    <axis xyz="0.965925843882 2.22044604925e-16 0.258818979447"/>
    <parent link="l_shoulder_2"/>
    <child link="l_shoulder_3"/>
    <limit effort="50000" lower="-0.645771823238" upper="1.3962634016" velocity="50000"/>
    <dynamics damping="0.06"/>
  </joint>
  <link name="l_upper_arm">
    <inertial>
      <origin xyz="-0.006121 -0.000189 0.0293684" rpy="0 -1.30899700697 -3.14159265359"/>
      <mass value="0.746799"/>
      <inertia ixx="0.000509731" ixy="-6.90767e-07" ixz="1.20048e-05" iyy="0.00067086" iyz="3.11833e-06" izz="0.000601202"/>
    </inertial>
    <visual>
      <origin xyz="-0.015 0 -0.1933" rpy="0 -1.30899700697 -3.14159265359"/>
      <geometry>
        <mesh filename="package://testbot_description/meshes/dae/sim_sea_2-5_l_elbow_prt-binary.stl" scale="0.001 0.001 0.001"/>
      </geometry>
      <material name="purple" />
    </visual>
    <collision>
      <origin xyz="-0.015 0 -0.1933" rpy="0 -1.30899700697 -3.14159265359"/>
      <geometry>
        <mesh filename="package://testbot_description/meshes/dae/sim_sea_2-5_l_elbow_prt-binary.stl" scale="0.001 0.001 0.001"/>
      </geometry>
    </collision>
  </link>
  <joint name="l_arm_ft_sensor" type="fixed">
    <origin xyz="0.0509301432452 0 0.0291758294659" rpy="0 -1.30899700697 3.14159265359"/>
    <parent link="l_shoulder_3"/>
    <child link="l_upper_arm"/>
    <dynamics damping="0.1"/>
  </joint>
  <link name="l_upper_arm_mtb_acc_1b10"/>
  <joint name="l_upper_arm_mtb_acc_1b10_fixed_joint" type="fixed">
    <origin xyz="-0.0430554 -0.028681 0.0295279" rpy="-1.57079650664 -1.57050350741 2.68257092837"/>
    <parent link="l_upper_arm"/>
    <child link="l_upper_arm_mtb_acc_1b10"/>
    <dynamics damping="0.1"/>
  </joint>
  <link name="l_upper_arm_mtb_acc_1b11"/>
  <joint name="l_upper_arm_mtb_acc_1b11_fixed_joint" type="fixed">
    <origin xyz="-0.0412181 -0.029589 0.0760604" rpy="-1.57079650664 -1.57050350741 2.68257092837"/>
    <parent link="l_upper_arm"/>
    <child link="l_upper_arm_mtb_acc_1b11"/>
    <dynamics damping="0.1"/>
  </joint>
  <link name="l_upper_arm_mtb_acc_1b12"/>
  <joint name="l_upper_arm_mtb_acc_1b12_fixed_joint" type="fixed">
    <origin xyz="-0.0412194 -0.029588 0.0049921" rpy="-1.57079718993 -1.57078381225 2.68257161162"/>
    <parent link="l_upper_arm"/>
    <child link="l_upper_arm_mtb_acc_1b12"/>
    <dynamics damping="0.1"/>
  </joint>
  <link name="l_upper_arm_mtb_acc_1b13"/>
  <joint name="l_upper_arm_mtb_acc_1b13_fixed_joint" type="fixed">
    <origin xyz="0.010592709 -0.028351 -0.0086914" rpy="-1.57079632657 0.000214520362042 -2.47803674451"/>
    <parent link="l_upper_arm"/>
    <child link="l_upper_arm_mtb_acc_1b13"/>
    <dynamics damping="0.1"/>
  </joint>
  <link name="l_elbow_1">
    <inertial>
      <origin xyz="0.00673912932843 0.0303019 -0.00465769236154" rpy="0 0 0"/>
      <mass value="0.267903"/>
      <inertia ixx="8.13352e-05" ixy="-7.37159e-06" ixz="1.04505e-05" iyy="5.86823e-05" iyz="3.9319e-06" izz="9.68469e-05"/>
    </inertial>
    <visual>
      <origin xyz="-0.259390463317 0.0339999 -0.0850325886962" rpy="0 0 0"/>
      <geometry>
        <mesh filename="package://testbot_description/meshes/dae/sim_sea_2-5_l_elbow_prosup_prt-binary.stl" scale="0.001 0.001 0.001"/>
      </geometry>
      <material name="purple" />
    </visual>
    <collision>
      <origin xyz="-0.259390463317 0.0339999 -0.0850325886962" rpy="0 0 0"/>
      <geometry>
        <mesh filename="package://testbot_description/meshes/dae/sim_sea_2-5_l_elbow_prosup_prt-binary.stl" scale="0.001 0.001 0.001"/>
      </geometry>
    </collision>
  </link>
  <joint name="l_elbow" type="revolute">
    <origin xyz="0 0.0339999 0.07926" rpy="0 -1.30899700697 -3.14159265359"/>
    <axis xyz="2.22044604925e-16 -1.0 0.0"/>
    <parent link="l_upper_arm"/>
    <child link="l_elbow_1"/>
    <limit effort="50000" lower="0.261799387799" upper="1.85004900711" velocity="50000"/>
    <dynamics damping="0.06"/>
  </joint>
  <link name="l_forearm">
    <inertial>
      <origin xyz="0.0404511828823 -0.000686 0.00532363214379" rpy="0 0 0"/>
      <mass value="0.636185"/>
      <inertia ixx="0.000371447" ixy="4.34562e-06" ixz="-0.000105871" iyy="0.000674229" iyz="4.05222e-06" izz="0.000557115"/>
    </inertial>
    <visual>
      <origin xyz="-0.296886967375 0 -0.0795506015227" rpy="0 0 0"/>
      <geometry>
        <mesh filename="package://testbot_description/meshes/dae/sim_sea_2-5_l_forearm_prt-binary.stl" scale="0.001 0.001 0.001"/>
      </geometry>
      <material name="purple" />
    </visual>
    <collision>
      <origin xyz="-0.296886967375 0 -0.0795506015227" rpy="0 0 0"/>
      <geometry>
        <mesh filename="package://testbot_description/meshes/dae/sim_sea_2-5_l_forearm_prt-binary.stl" scale="0.001 0.001 0.001"/>
      </geometry>
    </collision>
  </link>
  <joint name="l_wrist_prosup" type="revolute">
    <origin xyz="0.0384624299027 0.0339999 -0.00522316819403" rpy="0 0 0"/>
    <axis xyz="0.965925843882 2.22044604925e-16 0.258818979447"/>
    <parent link="l_elbow_1"/>
    <child link="l_forearm"/>
    <limit effort="50000" lower="-1.0471975512" upper="1.0471975512" velocity="50000"/>
    <dynamics damping="0.06"/>
  </joint>
  <link name="l_forearm_mtb_acc_1b7"/>
  <joint name="l_forearm_mtb_acc_1b7_fixed_joint" type="fixed">
    <origin xyz="0.0768727847342 -0.005483 -0.0110479126068" rpy="0.26179949998 0.000370413042328 -1.57033448496"/>
    <parent link="l_forearm"/>
    <child link="l_forearm_mtb_acc_1b7"/>
    <dynamics damping="0.1"/>
  </joint>
  <link name="l_forearm_mtb_acc_1b8"/>
  <joint name="l_forearm_mtb_acc_1b8_fixed_joint" type="fixed">
    <origin xyz="0.0514241740607 -0.0180279 0.0407507258436" rpy="-0.661143946092 0.147825248461 -3.04952253889"/>
    <parent link="l_forearm"/>
    <child link="l_forearm_mtb_acc_1b8"/>
    <dynamics damping="0.1"/>
  </joint>
  <link name="l_forearm_mtb_acc_1b9"/>
  <joint name="l_forearm_mtb_acc_1b9_fixed_joint" type="fixed">
    <origin xyz="0.0220991874996 0.025657 -0.0151174243212" rpy="1.76682134218 0.261099829847 3.08752548202"/>
    <parent link="l_forearm"/>
    <child link="l_forearm_mtb_acc_1b9"/>
    <dynamics damping="0.1"/>
  </joint>
  <link name="l_forearm_skin_0"/>
  <joint name="l_forearm_skin_0_fixed_joint" type="fixed">
    <origin xyz="0.0454493286618 -0.0323169 -0.00628656037901" rpy="1.69181522292 -0.271026744341 0.0727882713185"/>
    <parent link="l_forearm"/>
    <child link="l_forearm_skin_0"/>
    <dynamics damping="0.1"/>
  </joint>
  <link name="l_forearm_skin_1"/>
  <joint name="l_forearm_skin_1_fixed_joint" type="fixed">
    <origin xyz="0.0333728935826 -0.0310662 -0.0198456867711" rpy="1.86694023278 -0.274442533764 0.0421228737473"/>
    <parent link="l_forearm"/>
    <child link="l_forearm_skin_1"/>
    <dynamics damping="0.1"/>
  </joint>
  <link name="l_forearm_skin_2"/>
  <joint name="l_forearm_skin_2_fixed_joint" type="fixed">
    <origin xyz="0.0146988929852 -0.0335184 -0.0160117338371" rpy="1.72847287019 -0.264015219116 0.0142600467197"/>
    <parent link="l_forearm"/>
    <child link="l_forearm_skin_2"/>
    <dynamics damping="0.1"/>
  </joint>
  <link name="l_forearm_skin_3"/>
  <joint name="l_forearm_skin_3_fixed_joint" type="fixed">
    <origin xyz="0.045567293622 0.028651 -0.00633000929351" rpy="-1.69487280859 -0.269757727104 -0.061995217851"/>
    <parent link="l_forearm"/>
    <child link="l_forearm_skin_3"/>
    <dynamics damping="0.1"/>
  </joint>
  <link name="l_forearm_skin_4"/>
  <joint name="l_forearm_skin_4_fixed_joint" type="fixed">
    <origin xyz="0.0635326332996 0.025877 -0.00899784258066" rpy="-1.81747870108 -0.287406884885 -0.0998316152826"/>
    <parent link="l_forearm"/>
    <child link="l_forearm_skin_4"/>
    <dynamics damping="0.1"/>
  </joint>
  <link name="l_forearm_skin_5"/>
  <joint name="l_forearm_skin_5_fixed_joint" type="fixed">
    <origin xyz="0.0688211941968 0.015709 -0.0231133361791" rpy="-2.5410475806 -0.385627260642 -0.0867227569203"/>
    <parent link="l_forearm"/>
    <child link="l_forearm_skin_5"/>
    <dynamics damping="0.1"/>
  </joint>
  <link name="l_forearm_skin_6"/>
  <joint name="l_forearm_skin_6_fixed_joint" type="fixed">
    <origin xyz="0.0333948436255 0.027308 -0.0198325583433" rpy="-1.86628164653 -0.272886336181 -0.0371068033783"/>
    <parent link="l_forearm"/>
    <child link="l_forearm_skin_6"/>
    <dynamics damping="0.1"/>
  </joint>
  <link name="l_forearm_skin_7"/>
  <joint name="l_forearm_skin_7_fixed_joint" type="fixed">
    <origin xyz="0.0147224260074 0.029702 -0.0159326482703" rpy="-1.72564640857 -0.263992900722 -0.0143801109253"/>
    <parent link="l_forearm"/>
    <child link="l_forearm_skin_7"/>
    <dynamics damping="0.1"/>
  </joint>
  <link name="l_forearm_skin_8"/>
  <joint name="l_forearm_skin_8_fixed_joint" type="fixed">
    <origin xyz="0.0228528628554 0.007546 -0.041885146375" rpy="-2.94801979137 -0.270605090512 -0.00178708074348"/>
    <parent link="l_forearm"/>
    <child link="l_forearm_skin_8"/>
    <dynamics damping="0.1"/>
  </joint>
  <link name="l_forearm_skin_9"/>
  <joint name="l_forearm_skin_9_fixed_joint" type="fixed">
    <origin xyz="0.0376032734683 0.016715 -0.0340163371186" rpy="-2.58406517708 -0.2933217196 -0.0203085796276"/>
    <parent link="l_forearm"/>
    <child link="l_forearm_skin_9"/>
    <dynamics damping="0.1"/>
  </joint>
  <link name="l_forearm_skin_10"/>
  <joint name="l_forearm_skin_10_fixed_joint" type="fixed">
    <origin xyz="0.0542285210888 0.007546 -0.0321469082866" rpy="-2.94123313406 -0.328304471922 -0.0139662781936"/>
    <parent link="l_forearm"/>
    <child link="l_forearm_skin_10"/>
    <dynamics damping="0.1"/>
  </joint>
  <link name="l_forearm_skin_11"/>
  <joint name="l_forearm_skin_11_fixed_joint" type="fixed">
    <origin xyz="0.0542240912024 -0.0112832 -0.0321431259452" rpy="2.93929835957 -0.329101389745 0.0142734891292"/>
    <parent link="l_forearm"/>
    <child link="l_forearm_skin_11"/>
    <dynamics damping="0.1"/>
  </joint>
  <link name="l_forearm_skin_12"/>
  <joint name="l_forearm_skin_12_fixed_joint" type="fixed">
    <origin xyz="0.0375994633868 -0.0204556 -0.0340191179961" rpy="2.58303505964 -0.29483050207 0.021326850448"/>
    <parent link="l_forearm"/>
    <child link="l_forearm_skin_12"/>
    <dynamics damping="0.1"/>
  </joint>
  <link name="l_forearm_skin_13"/>
  <joint name="l_forearm_skin_13_fixed_joint" type="fixed">
    <origin xyz="0.0228550868405 -0.0112878 -0.0418919009209" rpy="2.94896679198 -0.270583947189 0.00177385006765"/>
    <parent link="l_forearm"/>
    <child link="l_forearm_skin_13"/>
    <dynamics damping="0.1"/>
  </joint>
  <link name="l_forearm_skin_14"/>
  <joint name="l_forearm_skin_14_fixed_joint" type="fixed">
    <origin xyz="0.0687703276364 -0.0193999 -0.0230239558511" rpy="2.52462250363 -0.387794511771 0.0912924111683"/>
    <parent link="l_forearm"/>
    <child link="l_forearm_skin_14"/>
    <dynamics damping="0.1"/>
  </joint>
  <link name="l_forearm_skin_15"/>
  <joint name="l_forearm_skin_15_fixed_joint" type="fixed">
    <origin xyz="0.0633786419662 -0.0293843 -0.00879405455544" rpy="1.80492769741 -0.289783281916 0.113933739306"/>
    <parent link="l_forearm"/>
    <child link="l_forearm_skin_15"/>
    <dynamics damping="0.1"/>
  </joint>
  <link name="l_forearm_skin_16"/>
  <joint name="l_forearm_skin_16_fixed_joint" type="fixed">
    <origin xyz="0.03792482187 -0.0327268 0.0206369503605" rpy="1.41280007026 -0.25082462139 0.0758652301584"/>
    <parent link="l_forearm"/>
    <child link="l_forearm_skin_16"/>
    <dynamics damping="0.1"/>
  </joint>
  <link name="l_forearm_skin_17"/>
  <joint name="l_forearm_skin_17_fixed_joint" type="fixed">
    <origin xyz="0.0543170548821 -0.0299646 0.0303291240179" rpy="1.27223716205 -0.23059304703 0.109637225219"/>
    <parent link="l_forearm"/>
    <child link="l_forearm_skin_17"/>
    <dynamics damping="0.1"/>
  </joint>
  <link name="l_forearm_skin_19"/>
  <joint name="l_forearm_skin_19_fixed_joint" type="fixed">
    <origin xyz="0.0381266107138 0.029054 0.020690605393" rpy="-1.41560888703 -0.252569290226 -0.0644404747027"/>
    <parent link="l_forearm"/>
    <child link="l_forearm_skin_19"/>
    <dynamics damping="0.1"/>
  </joint>
  <link name="l_forearm_skin_22"/>
  <joint name="l_forearm_skin_22_fixed_joint" type="fixed">
    <origin xyz="0.0544173950421 0.026483 0.0306037516609" rpy="-1.2658242728 -0.234328151379 -0.0937094738802"/>
    <parent link="l_forearm"/>
    <child link="l_forearm_skin_22"/>
    <dynamics damping="0.1"/>
  </joint>
  <link name="l_forearm_skin_24"/>
  <joint name="l_forearm_skin_24_fixed_joint" type="fixed">
    <origin xyz="0.0700345319564 0.007477 0.050069108714" rpy="-0.23489327644 -0.0388172993982 -0.0548291989999"/>
    <parent link="l_forearm"/>
    <child link="l_forearm_skin_24"/>
    <dynamics damping="0.1"/>
  </joint>
  <link name="l_forearm_skin_25"/>
  <joint name="l_forearm_skin_25_fixed_joint" type="fixed">
    <origin xyz="0.0535999216295 0.015984 0.0454698125045" rpy="-0.564295527715 -0.136980272197 -0.0819608256656"/>
    <parent link="l_forearm"/>
    <child link="l_forearm_skin_25"/>
    <dynamics damping="0.1"/>
  </joint>
  <link name="l_forearm_skin_28"/>
  <joint name="l_forearm_skin_28_fixed_joint" type="fixed">
    <origin xyz="0.0535859272148 -0.0196522 0.045352037397" rpy="0.579311106949 -0.133994306778 0.0867597858312"/>
    <parent link="l_forearm"/>
    <child link="l_forearm_skin_28"/>
    <dynamics damping="0.1"/>
  </joint>
  <link name="l_forearm_skin_29"/>
  <joint name="l_forearm_skin_29_fixed_joint" type="fixed">
    <origin xyz="0.0700355805031 -0.0111936 0.0500111036233" rpy="0.248630982209 -0.0383136556786 0.0583026624266"/>
    <parent link="l_forearm"/>
    <child link="l_forearm_skin_29"/>
    <dynamics damping="0.1"/>
  </joint>
  <link name="l_forearm_dh_frame"/>
  <joint name="l_forearm_dh_frame_fixed_joint" type="fixed">
    <origin xyz="0.102871102373 7.00000000002e-06 0.0275642213111" rpy="2.87979333376 0 1.57079632679"/>
    <parent link="l_forearm"/>
    <child link="l_forearm_dh_frame"/>
    <dynamics damping="0.1"/>
  </joint>
  <link name="l_wrist_1">
    <inertial>
      <origin xyz="-0.000981313804428 -0.001178 0.00408345773913" rpy="0 0 0"/>
      <mass value="0.0362152"/>
      <inertia ixx="5.56774e-06" ixy="3.08362e-08" ixz="9.42153e-07" iyy="5.28838e-06" iyz="-1.58924e-07" izz="1.87579e-06"/>
    </inertial>
    <visual>
      <origin xyz="-0.400314530555 -7.00000000009e-06 -0.105038082269" rpy="0 0 0"/>
      <geometry>
        <mesh filename="package://testbot_description/meshes/dae/sim_sea_2-5_l_wrist_pitch_prt-binary.stl" scale="0.001 0.001 0.001"/>
      </geometry>
      <material name="purple" />
    </visual>
    <collision>
      <origin xyz="-0.400314530555 -7.00000000009e-06 -0.105038082269" rpy="0 0 0"/>
      <geometry>
        <mesh filename="package://testbot_description/meshes/dae/sim_sea_2-5_l_wrist_pitch_prt-binary.stl" scale="0.001 0.001 0.001"/>
      </geometry>
    </collision>
  </link>
  <joint name="l_wrist_pitch" type="revolute">
    <origin xyz="0.103427563179 7.00000000002e-06 0.0254874807467" rpy="0 0 0"/>
    <axis xyz="0.258818979447 0.0 -0.965925843882"/>
    <parent link="l_forearm"/>
    <child link="l_wrist_1"/>
    <limit effort="50000" lower="-1.3962634016" upper="0.436332312999" velocity="50000"/>
    <dynamics damping="0.06"/>
  </joint>
  <link name="l_hand">
    <inertial>
      <origin xyz="0.0647680204057 0.0056304 0.0226602208449" rpy="0 0 0"/>
      <mass value="0.247806"/>
      <inertia ixx="0.000162491" ixy="2.96453e-06" ixz="-3.68906e-05" iyy="0.000430657" iyz="2.06885e-05" izz="0.000304729"/>
    </inertial>
    <visual>
      <origin xyz="-0.399680424055 0.0194929 -0.107404600587" rpy="0 0 0"/>
      <geometry>
        <mesh filename="package://testbot_description/meshes/dae/sim_sea_2-5_l_hand_prt-binary.stl" scale="0.001 0.001 0.001"/>
      </geometry>
      <material name="black" />
    </visual>
    <collision>
      <origin xyz="-0.399680424055 0.0194929 -0.107404600587" rpy="0 0 0"/>
      <geometry>
        <mesh filename="package://testbot_description/meshes/dae/sim_sea_2-5_l_hand_prt-binary.stl" scale="0.001 0.001 0.001"/>
      </geometry>
    </collision>
  </link>
  <joint name="l_wrist_yaw" type="revolute">
    <origin xyz="-0.000634106499644 -0.0194999 0.00236651831751" rpy="0 0 0"/>
    <axis xyz="-2.22044604925e-16 1.0 0.0"/>
    <parent link="l_wrist_1"/>
    <child link="l_hand"/>
    <limit effort="50000" lower="-0.349065850399" upper="0.436332312999" velocity="50000"/>
    <dynamics damping="0.06"/>
  </joint>
  <link name="l_hand_dh_frame"/>
  <joint name="l_hand_dh_frame_fixed_joint" type="fixed">
    <origin xyz="0.0576542978428 -0.0055568 0.0136938323083" rpy="-1.57079632679 -0.261799319827 0"/>
    <parent link="l_hand"/>
    <child link="l_hand_dh_frame"/>
    <dynamics damping="0.1"/>
  </joint>
  <link name="neck_1">
    <inertial>
      <origin xyz="0.0143705608 0.006567 -0.0063842" rpy="0 0 0"/>
      <mass value="0.125793"/>
      <inertia ixx="4.0647e-05" ixy="8.09156e-08" ixz="-3.74998e-08" iyy="3.881e-05" iyz="9.39717e-06" izz="4.7535e-05"/>
    </inertial>
    <visual>
      <origin xyz="0.0142999998093 -0.079997 -0.0295008" rpy="0 0 0"/>
      <geometry>
        <mesh filename="package://testbot_description/meshes/dae/sim_sea_2-5_neck_1_prt-binary.stl" scale="0.001 0.001 0.001"/>
      </geometry>
      <material name="metal" />
    </visual>
    <collision>
      <origin xyz="0.0142999998093 -0.079997 -0.0295008" rpy="0 0 0"/>
      <geometry>
        <mesh filename="package://testbot_description/meshes/dae/sim_sea_2-5_neck_1_prt-binary.stl" scale="0.001 0.001 0.001"/>
      </geometry>
    </collision>
  </link>
  <joint name="neck_pitch" type="revolute">
    <origin xyz="-0.0142999998093 0.172797 0.0053118" rpy="0 0 0"/>
    <axis xyz="-1.0 0.0 0.0"/>
    <parent link="chest"/>
    <child link="neck_1"/>
    <limit effort="50000" lower="-0.698131700798" upper="0.383972435439" velocity="50000"/>
    <dynamics damping="0.06"/>
  </joint>
  <link name="neck_2">
    <inertial>
      <origin xyz="-8.8573009265e-05 0.035225 -0.01954527" rpy="0 0 0"/>
      <mass value="0.177087"/>
      <inertia ixx="0.000117943" ixy="-5.25591e-07" ixz="4.68307e-07" iyy="4.04013e-05" iyz="9.81476e-06" izz="0.000105186"/>
    </inertial>
    <visual>
      <origin xyz="0 -0.089497 -0.05030077" rpy="0 0 0"/>
      <geometry>
        <mesh filename="package://testbot_description/meshes/dae/sim_sea_2-5_neck_2_prt-binary.stl" scale="0.001 0.001 0.001"/>
      </geometry>
      <material name="metal" />
    </visual>
    <collision>
      <origin xyz="0 -0.089497 -0.05030077" rpy="0 0 0"/>
      <geometry>
        <mesh filename="package://testbot_description/meshes/dae/sim_sea_2-5_neck_2_prt-binary.stl" scale="0.001 0.001 0.001"/>
      </geometry>
    </collision>
  </link>
  <joint name="neck_roll" type="revolute">
    <origin xyz="0.0142999998093 0.0095 0.02079997" rpy="0 0 0"/>
    <axis xyz="0.0 0.0 1.0"/>
    <parent link="neck_1"/>
    <child link="neck_2"/>
    <limit effort="50000" lower="-0.349065850399" upper="0.349065850399" velocity="50000"/>
    <dynamics damping="0.06"/>
  </joint>
  <link name="head">
    <inertial>
      <origin xyz="-0.000574157809265 0.113511 -0.0075392" rpy="0 0 0"/>
      <mass value="1.50691"/>
      <inertia ixx="0.00680478" ixy="-1.60267e-05" ixz="7.28166e-05" iyy="0.00634736" iyz="0.000292091" izz="0.00478116"/>
    </inertial>
    <visual>
      <origin xyz="0 -0.067153 -0.0295008" rpy="0 0 0"/>
      <geometry>
        <mesh filename="package://testbot_description/meshes/dae/sim_sea_2-5_head_prt-binary.stl" scale="0.001 0.001 0.001"/>
      </geometry>
      <material name="white">
           <texture />
           <color rgba="0.8 0.9 1 1" />
      </material>
    </visual>
    <collision>
      <origin xyz="0 -0.067153 -0.0295008" rpy="0 0 0"/>
      <geometry>
        <mesh filename="package://testbot_description/meshes/dae/sim_sea_2-5_head_prt-binary.stl" scale="0.001 0.001 0.001"/>
      </geometry>
    </collision>
  </link>
  <joint name="neck_yaw" type="revolute">
    <origin xyz="0 -0.022344 -0.02079997" rpy="0 0 0"/>
    <axis xyz="0.0 1.0 0.0"/>
    <parent link="neck_2"/>
    <child link="head"/>
    <limit effort="50000" lower="-0.872664625997" upper="0.872664625997" velocity="50000"/>
    <dynamics damping="0.06"/>
  </joint>
  <link name="imu"/>
  <joint name="imu_fixed_joint" type="fixed">
    <origin xyz="0.00950000019074 0.133444 0.0093" rpy="-1.57079632679 1.57079632679 0"/>
    <parent link="head"/>
    <child link="imu"/>
    <dynamics damping="0.1"/>
  </joint>
  <gazebo reference="l_leg_ft_sensor">
    <sensor name="l_leg_ft_sensor" type="force_torque">
      <always_on>1</always_on>
      <update_rate>100</update_rate>
      <force_torque>
        <frame>child</frame>
        <measure_direction>child_to_parent</measure_direction>
      </force_torque>
    </sensor>
  </gazebo>
  <sensor name="l_leg_ft_sensor" type="force_torque">
    <parent joint="l_leg_ft_sensor"/>
    <force_torque>
      <frame>child</frame>
      <measure_direction>child_to_parent</measure_direction>
    </force_torque>
  </sensor>
  <gazebo reference="r_leg_ft_sensor">
    <sensor name="r_leg_ft_sensor" type="force_torque">
      <always_on>1</always_on>
      <update_rate>100</update_rate>
      <force_torque>
        <frame>child</frame>
        <measure_direction>child_to_parent</measure_direction>
      </force_torque>
    </sensor>
  </gazebo>
  <sensor name="r_leg_ft_sensor" type="force_torque">
    <parent joint="r_leg_ft_sensor"/>
    <force_torque>
      <frame>child</frame>
      <measure_direction>child_to_parent</measure_direction>
    </force_torque>
  </sensor>
  <gazebo reference="l_foot_ft_sensor">
    <sensor name="l_foot_ft_sensor" type="force_torque">
      <always_on>1</always_on>
      <update_rate>100</update_rate>
      <force_torque>
        <frame>child</frame>
        <measure_direction>child_to_parent</measure_direction>
      </force_torque>
    </sensor>
  </gazebo>
  <sensor name="l_foot_ft_sensor" type="force_torque">
    <parent joint="l_foot_ft_sensor"/>
    <force_torque>
      <frame>child</frame>
      <measure_direction>child_to_parent</measure_direction>
    </force_torque>
  </sensor>
  <gazebo reference="r_foot_ft_sensor">
    <sensor name="r_foot_ft_sensor" type="force_torque">
      <always_on>1</always_on>
      <update_rate>100</update_rate>
      <force_torque>
        <frame>child</frame>
        <measure_direction>child_to_parent</measure_direction>
      </force_torque>
    </sensor>
  </gazebo>
  <sensor name="r_foot_ft_sensor" type="force_torque">
    <parent joint="r_foot_ft_sensor"/>
    <force_torque>
      <frame>child</frame>
      <measure_direction>child_to_parent</measure_direction>
    </force_torque>
  </sensor>
  <gazebo reference="l_arm_ft_sensor">
    <sensor name="l_arm_ft_sensor" type="force_torque">
      <always_on>1</always_on>
      <update_rate>100</update_rate>
      <force_torque>
        <frame>child</frame>
        <measure_direction>child_to_parent</measure_direction>
      </force_torque>
    </sensor>
  </gazebo>
  <sensor name="l_arm_ft_sensor" type="force_torque">
    <parent joint="l_arm_ft_sensor"/>
    <force_torque>
      <frame>child</frame>
      <measure_direction>child_to_parent</measure_direction>
    </force_torque>
  </sensor>
  <gazebo reference="r_arm_ft_sensor">
    <sensor name="r_arm_ft_sensor" type="force_torque">
      <always_on>1</always_on>
      <update_rate>100</update_rate>
      <force_torque>
        <frame>child</frame>
        <measure_direction>child_to_parent</measure_direction>
      </force_torque>
    </sensor>
  </gazebo>
  <sensor name="r_arm_ft_sensor" type="force_torque">
    <parent joint="r_arm_ft_sensor"/>
    <force_torque>
      <frame>child</frame>
      <measure_direction>child_to_parent</measure_direction>
    </force_torque>
  </sensor>
  <gazebo reference="head">
    <sensor name="imu" type="imu">
      <always_on>1</always_on>
      <update_rate>100</update_rate>
      <pose>0.00950000019074 0.133444 0.0093 -1.57079632679 1.57079632679 0.0</pose>
    </sensor>
  </gazebo>
  <sensor name="imu" type="imu">
    <parent link="head"/>
    <origin rpy="-1.57079632679 1.57079632679 0.0" xyz="0.00950000019074 0.133444 0.0093"/>
  </sensor>
  <link name="base_link"/>
  <joint name="base_fixed_joint" type="fixed">
  <origin xyz="0 0 0" rpy="0 -0 0"/>
  <axis xyz="0 0 0"/>
  <parent link="base_link"/>
  <child link="root_link"/>
</joint>
  <link name="l_foot_dh_frame"/>
  <joint name="l_foot_dh_frame_fixed_joint" type="fixed">
  <origin xyz="0.0 0 0.004" rpy="0 1.5708 0"/>
  <axis xyz="0 0 0"/>
  <parent link="l_foot"/>
  <child link="l_foot_dh_frame"/>
</joint>
  <link name="r_foot_dh_frame"/>
  <joint name="r_foot_dh_frame_fixed_joint" type="fixed">
  <origin xyz="0.0 0 0.004" rpy="0 1.5708 0"/>
  <axis xyz="0 0 0"/>
  <parent link="r_foot"/>
  <child link="r_foot_dh_frame"/>
</joint>
  <gazebo reference="r_arm_ft_sensor">
  <disableFixedJointLumping>true</disableFixedJointLumping>
</gazebo>
  <gazebo reference="r_arm_ft_sensor">
  <disableFixedJointLumping>true</disableFixedJointLumping>
</gazebo>
  <gazebo reference="l_arm_ft_sensor">
  <disableFixedJointLumping>true</disableFixedJointLumping>
</gazebo>
  <gazebo reference="r_leg_ft_sensor">
  <disableFixedJointLumping>true</disableFixedJointLumping>
</gazebo>
  <gazebo reference="l_leg_ft_sensor">
  <disableFixedJointLumping>true</disableFixedJointLumping>
</gazebo>
  <gazebo reference="r_foot_ft_sensor">
  <disableFixedJointLumping>true</disableFixedJointLumping>
</gazebo>
  <gazebo reference="l_foot_ft_sensor">
  <disableFixedJointLumping>true</disableFixedJointLumping>
</gazebo>
  <gazebo>
<plugin name="controlboard_torso" filename="libgazebo_yarp_controlboard.so">
    <yarpConfigurationFile>package://testbot_description/conf/gazebo_iCubGenova02_torso.ini</yarpConfigurationFile>
</plugin>
<plugin name="controlboard_head" filename="libgazebo_yarp_controlboard.so">
    <yarpConfigurationFile>package://testbot_description/conf/gazebo_iCubGenova02_head.ini</yarpConfigurationFile>
</plugin>
<plugin name="controlboard_left_arm" filename="libgazebo_yarp_controlboard.so">
    <yarpConfigurationFile>package://testbot_description/conf/gazebo_iCubGenova02_left_arm.ini</yarpConfigurationFile>
    <initialConfiguration>-0.52 0.52 0 0.785 0 0 0.698</initialConfiguration>
</plugin>
<plugin name="controlboard_right_arm" filename="libgazebo_yarp_controlboard.so">
    <yarpConfigurationFile>package://testbot_description/conf/gazebo_iCubGenova02_right_arm.ini</yarpConfigurationFile>
    <initialConfiguration>-0.52 0.52 0 0.785 0 0 0.698</initialConfiguration>
</plugin>
<plugin name="controlboard_right_leg" filename="libgazebo_yarp_controlboard.so">
    <yarpConfigurationFile>package://testbot_description/conf/gazebo_iCubGenova02_right_leg.ini</yarpConfigurationFile>
</plugin>
<plugin name="controlboard_left_leg" filename="libgazebo_yarp_controlboard.so">
    <yarpConfigurationFile>package://testbot_description/conf/gazebo_iCubGenova02_left_leg.ini</yarpConfigurationFile>
</plugin>
<plugin name="apply_external_wrench" filename="libgazebo_yarp_externalwrench.so">
     <robotNamefromConfigFile>package://testbot_description/conf/gazebo_iCubGenova02_robotname.ini</robotNamefromConfigFile>
</plugin>
</gazebo>
</robot>
